Workbook

Sheet Summary
A1: AzteckPlinkoFull Workbook
A2: Generated from F:\Gaming\Stakes\math-sdk\games\azteck_plinko_final
A4: Package
A5: Key | B5: Value
A6: Root | B6: F:\Gaming\Stakes\math-sdk\games\azteck_plinko_final
A7: Index | B7: F:\Gaming\Stakes\math-sdk\games\azteck_plinko_final\artifacts\publish_files\index.json
A8: Lookup files | B8: 72
A9: Docs dir exists | B9: TRUE
A10: RTP tolerance | B10: 0.01
A11: Payout scale | B11: 100
A12: Max bet assumption | B12: 500
A14: Mode Metrics
A15: Mode | B15: Cost | C15: Rows Config | D15: Expected Buckets | E15: Rows | F15: Unique Multipliers | G15: Bucket Structure Pass | H15: RTP Target | I15: RTP Actual | J15: Abs Drift | K15: RTP Pass | L15: Hit Rate | M15: Zero Rate | N15: Profit Rate | O15: Weighted Mean | P15: Std | Q15: Max Win | R15: Max Win Probability | S15: Max Exposure
A16: buy100_expert_10 | B16: ='buy100_expert_10'!$B$3 | C16: 10 | D16: =IF(C16="","",C16+1) | E16: ='buy100_expert_10'!B21 | F16: ='buy100_expert_10'!B22 | G16: =IF(C16="","N/A",F16=ROUNDUP((C16+1)/2,0)) | H16: ='buy100_expert_10'!$D$3 | I16: ='buy100_expert_10'!G16 | J16: =ABS(I16-H16) | K16: ='buy100_expert_10'!H16 | L16: =SUMIFS('buy100_expert_10'!E7:E14,'buy100_expert_10'!D7:D14,">0") | M16: =SUMIFS('buy100_expert_10'!E7:E14,'buy100_expert_10'!D7:D14,"=0") | N16: =SUMIFS('buy100_expert_10'!E7:E14,'buy100_expert_10'!D7:D14,">"&B16) | O16: ='buy100_expert_10'!F16 | P16: =SQRT(SUMPRODUCT('buy100_expert_10'!E7:E14,('buy100_expert_10'!D7:D14-O16)^2)) | Q16: ='buy100_expert_10'!B19 | R16: ='buy100_expert_10'!B20 | S16: ='buy100_expert_10'!B23
A17: buy100_expert_11 | B17: ='buy100_expert_11'!$B$3 | C17: 11 | D17: =IF(C17="","",C17+1) | E17: ='buy100_expert_11'!B22 | F17: ='buy100_expert_11'!B23 | G17: =IF(C17="","N/A",F17=ROUNDUP((C17+1)/2,0)) | H17: ='buy100_expert_11'!$D$3 | I17: ='buy100_expert_11'!G17 | J17: =ABS(I17-H17) | K17: ='buy100_expert_11'!H17 | L17: =SUMIFS('buy100_expert_11'!E7:E15,'buy100_expert_11'!D7:D15,">0") | M17: =SUMIFS('buy100_expert_11'!E7:E15,'buy100_expert_11'!D7:D15,"=0") | N17: =SUMIFS('buy100_expert_11'!E7:E15,'buy100_expert_11'!D7:D15,">"&B17) | O17: ='buy100_expert_11'!F17 | P17: =SQRT(SUMPRODUCT('buy100_expert_11'!E7:E15,('buy100_expert_11'!D7:D15-O17)^2)) | Q17: ='buy100_expert_11'!B20 | R17: ='buy100_expert_11'!B21 | S17: ='buy100_expert_11'!B24
A18: buy100_expert_12 | B18: ='buy100_expert_12'!$B$3 | C18: 12 | D18: =IF(C18="","",C18+1) | E18: ='buy100_expert_12'!B23 | F18: ='buy100_expert_12'!B24 | G18: =IF(C18="","N/A",F18=ROUNDUP((C18+1)/2,0)) | H18: ='buy100_expert_12'!$D$3 | I18: ='buy100_expert_12'!G18 | J18: =ABS(I18-H18) | K18: ='buy100_expert_12'!H18 | L18: =SUMIFS('buy100_expert_12'!E7:E16,'buy100_expert_12'!D7:D16,">0") | M18: =SUMIFS('buy100_expert_12'!E7:E16,'buy100_expert_12'!D7:D16,"=0") | N18: =SUMIFS('buy100_expert_12'!E7:E16,'buy100_expert_12'!D7:D16,">"&B18) | O18: ='buy100_expert_12'!F18 | P18: =SQRT(SUMPRODUCT('buy100_expert_12'!E7:E16,('buy100_expert_12'!D7:D16-O18)^2)) | Q18: ='buy100_expert_12'!B21 | R18: ='buy100_expert_12'!B22 | S18: ='buy100_expert_12'!B25
A19: buy100_expert_13 | B19: ='buy100_expert_13'!$B$3 | C19: 13 | D19: =IF(C19="","",C19+1) | E19: ='buy100_expert_13'!B24 | F19: ='buy100_expert_13'!B25 | G19: =IF(C19="","N/A",F19=ROUNDUP((C19+1)/2,0)) | H19: ='buy100_expert_13'!$D$3 | I19: ='buy100_expert_13'!G19 | J19: =ABS(I19-H19) | K19: ='buy100_expert_13'!H19 | L19: =SUMIFS('buy100_expert_13'!E7:E17,'buy100_expert_13'!D7:D17,">0") | M19: =SUMIFS('buy100_expert_13'!E7:E17,'buy100_expert_13'!D7:D17,"=0") | N19: =SUMIFS('buy100_expert_13'!E7:E17,'buy100_expert_13'!D7:D17,">"&B19) | O19: ='buy100_expert_13'!F19 | P19: =SQRT(SUMPRODUCT('buy100_expert_13'!E7:E17,('buy100_expert_13'!D7:D17-O19)^2)) | Q19: ='buy100_expert_13'!B22 | R19: ='buy100_expert_13'!B23 | S19: ='buy100_expert_13'!B26
A20: buy100_expert_14 | B20: ='buy100_expert_14'!$B$3 | C20: 14 | D20: =IF(C20="","",C20+1) | E20: ='buy100_expert_14'!B25 | F20: ='buy100_expert_14'!B26 | G20: =IF(C20="","N/A",F20=ROUNDUP((C20+1)/2,0)) | H20: ='buy100_expert_14'!$D$3 | I20: ='buy100_expert_14'!G20 | J20: =ABS(I20-H20) | K20: ='buy100_expert_14'!H20 | L20: =SUMIFS('buy100_expert_14'!E7:E18,'buy100_expert_14'!D7:D18,">0") | M20: =SUMIFS('buy100_expert_14'!E7:E18,'buy100_expert_14'!D7:D18,"=0") | N20: =SUMIFS('buy100_expert_14'!E7:E18,'buy100_expert_14'!D7:D18,">"&B20) | O20: ='buy100_expert_14'!F20 | P20: =SQRT(SUMPRODUCT('buy100_expert_14'!E7:E18,('buy100_expert_14'!D7:D18-O20)^2)) | Q20: ='buy100_expert_14'!B23 | R20: ='buy100_expert_14'!B24 | S20: ='buy100_expert_14'!B27
A21: buy100_expert_15 | B21: ='buy100_expert_15'!$B$3 | C21: 15 | D21: =IF(C21="","",C21+1) | E21: ='buy100_expert_15'!B24 | F21: ='buy100_expert_15'!B25 | G21: =IF(C21="","N/A",F21=ROUNDUP((C21+1)/2,0)) | H21: ='buy100_expert_15'!$D$3 | I21: ='buy100_expert_15'!G19 | J21: =ABS(I21-H21) | K21: ='buy100_expert_15'!H19 | L21: =SUMIFS('buy100_expert_15'!E7:E17,'buy100_expert_15'!D7:D17,">0") | M21: =SUMIFS('buy100_expert_15'!E7:E17,'buy100_expert_15'!D7:D17,"=0") | N21: =SUMIFS('buy100_expert_15'!E7:E17,'buy100_expert_15'!D7:D17,">"&B21) | O21: ='buy100_expert_15'!F19 | P21: =SQRT(SUMPRODUCT('buy100_expert_15'!E7:E17,('buy100_expert_15'!D7:D17-O21)^2)) | Q21: ='buy100_expert_15'!B22 | R21: ='buy100_expert_15'!B23 | S21: ='buy100_expert_15'!B26
A22: buy100_expert_16 | B22: ='buy100_expert_16'!$B$3 | C22: 16 | D22: =IF(C22="","",C22+1) | E22: ='buy100_expert_16'!B25 | F22: ='buy100_expert_16'!B26 | G22: =IF(C22="","N/A",F22=ROUNDUP((C22+1)/2,0)) | H22: ='buy100_expert_16'!$D$3 | I22: ='buy100_expert_16'!G20 | J22: =ABS(I22-H22) | K22: ='buy100_expert_16'!H20 | L22: =SUMIFS('buy100_expert_16'!E7:E18,'buy100_expert_16'!D7:D18,">0") | M22: =SUMIFS('buy100_expert_16'!E7:E18,'buy100_expert_16'!D7:D18,"=0") | N22: =SUMIFS('buy100_expert_16'!E7:E18,'buy100_expert_16'!D7:D18,">"&B22) | O22: ='buy100_expert_16'!F20 | P22: =SQRT(SUMPRODUCT('buy100_expert_16'!E7:E18,('buy100_expert_16'!D7:D18-O22)^2)) | Q22: ='buy100_expert_16'!B23 | R22: ='buy100_expert_16'!B24 | S22: ='buy100_expert_16'!B27
A23: buy100_expert_8 | B23: ='buy100_expert_8'!$B$3 | C23: 8 | D23: =IF(C23="","",C23+1) | E23: ='buy100_expert_8'!B21 | F23: ='buy100_expert_8'!B22 | G23: =IF(C23="","N/A",F23=ROUNDUP((C23+1)/2,0)) | H23: ='buy100_expert_8'!$D$3 | I23: ='buy100_expert_8'!G16 | J23: =ABS(I23-H23) | K23: ='buy100_expert_8'!H16 | L23: =SUMIFS('buy100_expert_8'!E7:E14,'buy100_expert_8'!D7:D14,">0") | M23: =SUMIFS('buy100_expert_8'!E7:E14,'buy100_expert_8'!D7:D14,"=0") | N23: =SUMIFS('buy100_expert_8'!E7:E14,'buy100_expert_8'!D7:D14,">"&B23) | O23: ='buy100_expert_8'!F16 | P23: =SQRT(SUMPRODUCT('buy100_expert_8'!E7:E14,('buy100_expert_8'!D7:D14-O23)^2)) | Q23: ='buy100_expert_8'!B19 | R23: ='buy100_expert_8'!B20 | S23: ='buy100_expert_8'!B23
A24: buy100_expert_9 | B24: ='buy100_expert_9'!$B$3 | C24: 9 | D24: =IF(C24="","",C24+1) | E24: ='buy100_expert_9'!B22 | F24: ='buy100_expert_9'!B23 | G24: =IF(C24="","N/A",F24=ROUNDUP((C24+1)/2,0)) | H24: ='buy100_expert_9'!$D$3 | I24: ='buy100_expert_9'!G17 | J24: =ABS(I24-H24) | K24: ='buy100_expert_9'!H17 | L24: =SUMIFS('buy100_expert_9'!E7:E15,'buy100_expert_9'!D7:D15,">0") | M24: =SUMIFS('buy100_expert_9'!E7:E15,'buy100_expert_9'!D7:D15,"=0") | N24: =SUMIFS('buy100_expert_9'!E7:E15,'buy100_expert_9'!D7:D15,">"&B24) | O24: ='buy100_expert_9'!F17 | P24: =SQRT(SUMPRODUCT('buy100_expert_9'!E7:E15,('buy100_expert_9'!D7:D15-O24)^2)) | Q24: ='buy100_expert_9'!B20 | R24: ='buy100_expert_9'!B21 | S24: ='buy100_expert_9'!B24
A25: buy100_high_10 | B25: ='buy100_high_10'!$B$3 | C25: 10 | D25: =IF(C25="","",C25+1) | E25: ='buy100_high_10'!B23 | F25: ='buy100_high_10'!B24 | G25: =IF(C25="","N/A",F25=ROUNDUP((C25+1)/2,0)) | H25: ='buy100_high_10'!$D$3 | I25: ='buy100_high_10'!G18 | J25: =ABS(I25-H25) | K25: ='buy100_high_10'!H18 | L25: =SUMIFS('buy100_high_10'!E7:E16,'buy100_high_10'!D7:D16,">0") | M25: =SUMIFS('buy100_high_10'!E7:E16,'buy100_high_10'!D7:D16,"=0") | N25: =SUMIFS('buy100_high_10'!E7:E16,'buy100_high_10'!D7:D16,">"&B25) | O25: ='buy100_high_10'!F18 | P25: =SQRT(SUMPRODUCT('buy100_high_10'!E7:E16,('buy100_high_10'!D7:D16-O25)^2)) | Q25: ='buy100_high_10'!B21 | R25: ='buy100_high_10'!B22 | S25: ='buy100_high_10'!B25
A26: buy100_high_11 | B26: ='buy100_high_11'!$B$3 | C26: 11 | D26: =IF(C26="","",C26+1) | E26: ='buy100_high_11'!B24 | F26: ='buy100_high_11'!B25 | G26: =IF(C26="","N/A",F26=ROUNDUP((C26+1)/2,0)) | H26: ='buy100_high_11'!$D$3 | I26: ='buy100_high_11'!G19 | J26: =ABS(I26-H26) | K26: ='buy100_high_11'!H19 | L26: =SUMIFS('buy100_high_11'!E7:E17,'buy100_high_11'!D7:D17,">0") | M26: =SUMIFS('buy100_high_11'!E7:E17,'buy100_high_11'!D7:D17,"=0") | N26: =SUMIFS('buy100_high_11'!E7:E17,'buy100_high_11'!D7:D17,">"&B26) | O26: ='buy100_high_11'!F19 | P26: =SQRT(SUMPRODUCT('buy100_high_11'!E7:E17,('buy100_high_11'!D7:D17-O26)^2)) | Q26: ='buy100_high_11'!B22 | R26: ='buy100_high_11'!B23 | S26: ='buy100_high_11'!B26
A27: buy100_high_12 | B27: ='buy100_high_12'!$B$3 | C27: 12 | D27: =IF(C27="","",C27+1) | E27: ='buy100_high_12'!B25 | F27: ='buy100_high_12'!B26 | G27: =IF(C27="","N/A",F27=ROUNDUP((C27+1)/2,0)) | H27: ='buy100_high_12'!$D$3 | I27: ='buy100_high_12'!G20 | J27: =ABS(I27-H27) | K27: ='buy100_high_12'!H20 | L27: =SUMIFS('buy100_high_12'!E7:E18,'buy100_high_12'!D7:D18,">0") | M27: =SUMIFS('buy100_high_12'!E7:E18,'buy100_high_12'!D7:D18,"=0") | N27: =SUMIFS('buy100_high_12'!E7:E18,'buy100_high_12'!D7:D18,">"&B27) | O27: ='buy100_high_12'!F20 | P27: =SQRT(SUMPRODUCT('buy100_high_12'!E7:E18,('buy100_high_12'!D7:D18-O27)^2)) | Q27: ='buy100_high_12'!B23 | R27: ='buy100_high_12'!B24 | S27: ='buy100_high_12'!B27
A28: buy100_high_13 | B28: ='buy100_high_13'!$B$3 | C28: 13 | D28: =IF(C28="","",C28+1) | E28: ='buy100_high_13'!B26 | F28: ='buy100_high_13'!B27 | G28: =IF(C28="","N/A",F28=ROUNDUP((C28+1)/2,0)) | H28: ='buy100_high_13'!$D$3 | I28: ='buy100_high_13'!G21 | J28: =ABS(I28-H28) | K28: ='buy100_high_13'!H21 | L28: =SUMIFS('buy100_high_13'!E7:E19,'buy100_high_13'!D7:D19,">0") | M28: =SUMIFS('buy100_high_13'!E7:E19,'buy100_high_13'!D7:D19,"=0") | N28: =SUMIFS('buy100_high_13'!E7:E19,'buy100_high_13'!D7:D19,">"&B28) | O28: ='buy100_high_13'!F21 | P28: =SQRT(SUMPRODUCT('buy100_high_13'!E7:E19,('buy100_high_13'!D7:D19-O28)^2)) | Q28: ='buy100_high_13'!B24 | R28: ='buy100_high_13'!B25 | S28: ='buy100_high_13'!B28
A29: buy100_high_14 | B29: ='buy100_high_14'!$B$3 | C29: 14 | D29: =IF(C29="","",C29+1) | E29: ='buy100_high_14'!B25 | F29: ='buy100_high_14'!B26 | G29: =IF(C29="","N/A",F29=ROUNDUP((C29+1)/2,0)) | H29: ='buy100_high_14'!$D$3 | I29: ='buy100_high_14'!G20 | J29: =ABS(I29-H29) | K29: ='buy100_high_14'!H20 | L29: =SUMIFS('buy100_high_14'!E7:E18,'buy100_high_14'!D7:D18,">0") | M29: =SUMIFS('buy100_high_14'!E7:E18,'buy100_high_14'!D7:D18,"=0") | N29: =SUMIFS('buy100_high_14'!E7:E18,'buy100_high_14'!D7:D18,">"&B29) | O29: ='buy100_high_14'!F20 | P29: =SQRT(SUMPRODUCT('buy100_high_14'!E7:E18,('buy100_high_14'!D7:D18-O29)^2)) | Q29: ='buy100_high_14'!B23 | R29: ='buy100_high_14'!B24 | S29: ='buy100_high_14'!B27
A30: buy100_high_15 | B30: ='buy100_high_15'!$B$3 | C30: 15 | D30: =IF(C30="","",C30+1) | E30: ='buy100_high_15'!B26 | F30: ='buy100_high_15'!B27 | G30: =IF(C30="","N/A",F30=ROUNDUP((C30+1)/2,0)) | H30: ='buy100_high_15'!$D$3 | I30: ='buy100_high_15'!G21 | J30: =ABS(I30-H30) | K30: ='buy100_high_15'!H21 | L30: =SUMIFS('buy100_high_15'!E7:E19,'buy100_high_15'!D7:D19,">0") | M30: =SUMIFS('buy100_high_15'!E7:E19,'buy100_high_15'!D7:D19,"=0") | N30: =SUMIFS('buy100_high_15'!E7:E19,'buy100_high_15'!D7:D19,">"&B30) | O30: ='buy100_high_15'!F21 | P30: =SQRT(SUMPRODUCT('buy100_high_15'!E7:E19,('buy100_high_15'!D7:D19-O30)^2)) | Q30: ='buy100_high_15'!B24 | R30: ='buy100_high_15'!B25 | S30: ='buy100_high_15'!B28
A31: buy100_high_16 | B31: ='buy100_high_16'!$B$3 | C31: 16 | D31: =IF(C31="","",C31+1) | E31: ='buy100_high_16'!B27 | F31: ='buy100_high_16'!B28 | G31: =IF(C31="","N/A",F31=ROUNDUP((C31+1)/2,0)) | H31: ='buy100_high_16'!$D$3 | I31: ='buy100_high_16'!G22 | J31: =ABS(I31-H31) | K31: ='buy100_high_16'!H22 | L31: =SUMIFS('buy100_high_16'!E7:E20,'buy100_high_16'!D7:D20,">0") | M31: =SUMIFS('buy100_high_16'!E7:E20,'buy100_high_16'!D7:D20,"=0") | N31: =SUMIFS('buy100_high_16'!E7:E20,'buy100_high_16'!D7:D20,">"&B31) | O31: ='buy100_high_16'!F22 | P31: =SQRT(SUMPRODUCT('buy100_high_16'!E7:E20,('buy100_high_16'!D7:D20-O31)^2)) | Q31: ='buy100_high_16'!B25 | R31: ='buy100_high_16'!B26 | S31: ='buy100_high_16'!B29
A32: buy100_high_8 | B32: ='buy100_high_8'!$B$3 | C32: 8 | D32: =IF(C32="","",C32+1) | E32: ='buy100_high_8'!B22 | F32: ='buy100_high_8'!B23 | G32: =IF(C32="","N/A",F32=ROUNDUP((C32+1)/2,0)) | H32: ='buy100_high_8'!$D$3 | I32: ='buy100_high_8'!G17 | J32: =ABS(I32-H32) | K32: ='buy100_high_8'!H17 | L32: =SUMIFS('buy100_high_8'!E7:E15,'buy100_high_8'!D7:D15,">0") | M32: =SUMIFS('buy100_high_8'!E7:E15,'buy100_high_8'!D7:D15,"=0") | N32: =SUMIFS('buy100_high_8'!E7:E15,'buy100_high_8'!D7:D15,">"&B32) | O32: ='buy100_high_8'!F17 | P32: =SQRT(SUMPRODUCT('buy100_high_8'!E7:E15,('buy100_high_8'!D7:D15-O32)^2)) | Q32: ='buy100_high_8'!B20 | R32: ='buy100_high_8'!B21 | S32: ='buy100_high_8'!B24
A33: buy100_high_9 | B33: ='buy100_high_9'!$B$3 | C33: 9 | D33: =IF(C33="","",C33+1) | E33: ='buy100_high_9'!B22 | F33: ='buy100_high_9'!B23 | G33: =IF(C33="","N/A",F33=ROUNDUP((C33+1)/2,0)) | H33: ='buy100_high_9'!$D$3 | I33: ='buy100_high_9'!G17 | J33: =ABS(I33-H33) | K33: ='buy100_high_9'!H17 | L33: =SUMIFS('buy100_high_9'!E7:E15,'buy100_high_9'!D7:D15,">0") | M33: =SUMIFS('buy100_high_9'!E7:E15,'buy100_high_9'!D7:D15,"=0") | N33: =SUMIFS('buy100_high_9'!E7:E15,'buy100_high_9'!D7:D15,">"&B33) | O33: ='buy100_high_9'!F17 | P33: =SQRT(SUMPRODUCT('buy100_high_9'!E7:E15,('buy100_high_9'!D7:D15-O33)^2)) | Q33: ='buy100_high_9'!B20 | R33: ='buy100_high_9'!B21 | S33: ='buy100_high_9'!B24
A34: buy100_low_10 | B34: ='buy100_low_10'!$B$3 | C34: 10 | D34: =IF(C34="","",C34+1) | E34: ='buy100_low_10'!B24 | F34: ='buy100_low_10'!B25 | G34: =IF(C34="","N/A",F34=ROUNDUP((C34+1)/2,0)) | H34: ='buy100_low_10'!$D$3 | I34: ='buy100_low_10'!G19 | J34: =ABS(I34-H34) | K34: ='buy100_low_10'!H19 | L34: =SUMIFS('buy100_low_10'!E7:E17,'buy100_low_10'!D7:D17,">0") | M34: =SUMIFS('buy100_low_10'!E7:E17,'buy100_low_10'!D7:D17,"=0") | N34: =SUMIFS('buy100_low_10'!E7:E17,'buy100_low_10'!D7:D17,">"&B34) | O34: ='buy100_low_10'!F19 | P34: =SQRT(SUMPRODUCT('buy100_low_10'!E7:E17,('buy100_low_10'!D7:D17-O34)^2)) | Q34: ='buy100_low_10'!B22 | R34: ='buy100_low_10'!B23 | S34: ='buy100_low_10'!B26
A35: buy100_low_11 | B35: ='buy100_low_11'!$B$3 | C35: 11 | D35: =IF(C35="","",C35+1) | E35: ='buy100_low_11'!B24 | F35: ='buy100_low_11'!B25 | G35: =IF(C35="","N/A",F35=ROUNDUP((C35+1)/2,0)) | H35: ='buy100_low_11'!$D$3 | I35: ='buy100_low_11'!G19 | J35: =ABS(I35-H35) | K35: ='buy100_low_11'!H19 | L35: =SUMIFS('buy100_low_11'!E7:E17,'buy100_low_11'!D7:D17,">0") | M35: =SUMIFS('buy100_low_11'!E7:E17,'buy100_low_11'!D7:D17,"=0") | N35: =SUMIFS('buy100_low_11'!E7:E17,'buy100_low_11'!D7:D17,">"&B35) | O35: ='buy100_low_11'!F19 | P35: =SQRT(SUMPRODUCT('buy100_low_11'!E7:E17,('buy100_low_11'!D7:D17-O35)^2)) | Q35: ='buy100_low_11'!B22 | R35: ='buy100_low_11'!B23 | S35: ='buy100_low_11'!B26
A36: buy100_low_12 | B36: ='buy100_low_12'!$B$3 | C36: 12 | D36: =IF(C36="","",C36+1) | E36: ='buy100_low_12'!B25 | F36: ='buy100_low_12'!B26 | G36: =IF(C36="","N/A",F36=ROUNDUP((C36+1)/2,0)) | H36: ='buy100_low_12'!$D$3 | I36: ='buy100_low_12'!G20 | J36: =ABS(I36-H36) | K36: ='buy100_low_12'!H20 | L36: =SUMIFS('buy100_low_12'!E7:E18,'buy100_low_12'!D7:D18,">0") | M36: =SUMIFS('buy100_low_12'!E7:E18,'buy100_low_12'!D7:D18,"=0") | N36: =SUMIFS('buy100_low_12'!E7:E18,'buy100_low_12'!D7:D18,">"&B36) | O36: ='buy100_low_12'!F20 | P36: =SQRT(SUMPRODUCT('buy100_low_12'!E7:E18,('buy100_low_12'!D7:D18-O36)^2)) | Q36: ='buy100_low_12'!B23 | R36: ='buy100_low_12'!B24 | S36: ='buy100_low_12'!B27
A37: buy100_low_13 | B37: ='buy100_low_13'!$B$3 | C37: 13 | D37: =IF(C37="","",C37+1) | E37: ='buy100_low_13'!B27 | F37: ='buy100_low_13'!B28 | G37: =IF(C37="","N/A",F37=ROUNDUP((C37+1)/2,0)) | H37: ='buy100_low_13'!$D$3 | I37: ='buy100_low_13'!G22 | J37: =ABS(I37-H37) | K37: ='buy100_low_13'!H22 | L37: =SUMIFS('buy100_low_13'!E7:E20,'buy100_low_13'!D7:D20,">0") | M37: =SUMIFS('buy100_low_13'!E7:E20,'buy100_low_13'!D7:D20,"=0") | N37: =SUMIFS('buy100_low_13'!E7:E20,'buy100_low_13'!D7:D20,">"&B37) | O37: ='buy100_low_13'!F22 | P37: =SQRT(SUMPRODUCT('buy100_low_13'!E7:E20,('buy100_low_13'!D7:D20-O37)^2)) | Q37: ='buy100_low_13'!B25 | R37: ='buy100_low_13'!B26 | S37: ='buy100_low_13'!B29
A38: buy100_low_14 | B38: ='buy100_low_14'!$B$3 | C38: 14 | D38: =IF(C38="","",C38+1) | E38: ='buy100_low_14'!B27 | F38: ='buy100_low_14'!B28 | G38: =IF(C38="","N/A",F38=ROUNDUP((C38+1)/2,0)) | H38: ='buy100_low_14'!$D$3 | I38: ='buy100_low_14'!G22 | J38: =ABS(I38-H38) | K38: ='buy100_low_14'!H22 | L38: =SUMIFS('buy100_low_14'!E7:E20,'buy100_low_14'!D7:D20,">0") | M38: =SUMIFS('buy100_low_14'!E7:E20,'buy100_low_14'!D7:D20,"=0") | N38: =SUMIFS('buy100_low_14'!E7:E20,'buy100_low_14'!D7:D20,">"&B38) | O38: ='buy100_low_14'!F22 | P38: =SQRT(SUMPRODUCT('buy100_low_14'!E7:E20,('buy100_low_14'!D7:D20-O38)^2)) | Q38: ='buy100_low_14'!B25 | R38: ='buy100_low_14'!B26 | S38: ='buy100_low_14'!B29
A39: buy100_low_15 | B39: ='buy100_low_15'!$B$3 | C39: 15 | D39: =IF(C39="","",C39+1) | E39: ='buy100_low_15'!B26 | F39: ='buy100_low_15'!B27 | G39: =IF(C39="","N/A",F39=ROUNDUP((C39+1)/2,0)) | H39: ='buy100_low_15'!$D$3 | I39: ='buy100_low_15'!G21 | J39: =ABS(I39-H39) | K39: ='buy100_low_15'!H21 | L39: =SUMIFS('buy100_low_15'!E7:E19,'buy100_low_15'!D7:D19,">0") | M39: =SUMIFS('buy100_low_15'!E7:E19,'buy100_low_15'!D7:D19,"=0") | N39: =SUMIFS('buy100_low_15'!E7:E19,'buy100_low_15'!D7:D19,">"&B39) | O39: ='buy100_low_15'!F21 | P39: =SQRT(SUMPRODUCT('buy100_low_15'!E7:E19,('buy100_low_15'!D7:D19-O39)^2)) | Q39: ='buy100_low_15'!B24 | R39: ='buy100_low_15'!B25 | S39: ='buy100_low_15'!B28
A40: buy100_low_16 | B40: ='buy100_low_16'!$B$3 | C40: 16 | D40: =IF(C40="","",C40+1) | E40: ='buy100_low_16'!B27 | F40: ='buy100_low_16'!B28 | G40: =IF(C40="","N/A",F40=ROUNDUP((C40+1)/2,0)) | H40: ='buy100_low_16'!$D$3 | I40: ='buy100_low_16'!G22 | J40: =ABS(I40-H40) | K40: ='buy100_low_16'!H22 | L40: =SUMIFS('buy100_low_16'!E7:E20,'buy100_low_16'!D7:D20,">0") | M40: =SUMIFS('buy100_low_16'!E7:E20,'buy100_low_16'!D7:D20,"=0") | N40: =SUMIFS('buy100_low_16'!E7:E20,'buy100_low_16'!D7:D20,">"&B40) | O40: ='buy100_low_16'!F22 | P40: =SQRT(SUMPRODUCT('buy100_low_16'!E7:E20,('buy100_low_16'!D7:D20-O40)^2)) | Q40: ='buy100_low_16'!B25 | R40: ='buy100_low_16'!B26 | S40: ='buy100_low_16'!B29
A41: buy100_low_8 | B41: ='buy100_low_8'!$B$3 | C41: 8 | D41: =IF(C41="","",C41+1) | E41: ='buy100_low_8'!B22 | F41: ='buy100_low_8'!B23 | G41: =IF(C41="","N/A",F41=ROUNDUP((C41+1)/2,0)) | H41: ='buy100_low_8'!$D$3 | I41: ='buy100_low_8'!G17 | J41: =ABS(I41-H41) | K41: ='buy100_low_8'!H17 | L41: =SUMIFS('buy100_low_8'!E7:E15,'buy100_low_8'!D7:D15,">0") | M41: =SUMIFS('buy100_low_8'!E7:E15,'buy100_low_8'!D7:D15,"=0") | N41: =SUMIFS('buy100_low_8'!E7:E15,'buy100_low_8'!D7:D15,">"&B41) | O41: ='buy100_low_8'!F17 | P41: =SQRT(SUMPRODUCT('buy100_low_8'!E7:E15,('buy100_low_8'!D7:D15-O41)^2)) | Q41: ='buy100_low_8'!B20 | R41: ='buy100_low_8'!B21 | S41: ='buy100_low_8'!B24
A42: buy100_low_9 | B42: ='buy100_low_9'!$B$3 | C42: 9 | D42: =IF(C42="","",C42+1) | E42: ='buy100_low_9'!B23 | F42: ='buy100_low_9'!B24 | G42: =IF(C42="","N/A",F42=ROUNDUP((C42+1)/2,0)) | H42: ='buy100_low_9'!$D$3 | I42: ='buy100_low_9'!G18 | J42: =ABS(I42-H42) | K42: ='buy100_low_9'!H18 | L42: =SUMIFS('buy100_low_9'!E7:E16,'buy100_low_9'!D7:D16,">0") | M42: =SUMIFS('buy100_low_9'!E7:E16,'buy100_low_9'!D7:D16,"=0") | N42: =SUMIFS('buy100_low_9'!E7:E16,'buy100_low_9'!D7:D16,">"&B42) | O42: ='buy100_low_9'!F18 | P42: =SQRT(SUMPRODUCT('buy100_low_9'!E7:E16,('buy100_low_9'!D7:D16-O42)^2)) | Q42: ='buy100_low_9'!B21 | R42: ='buy100_low_9'!B22 | S42: ='buy100_low_9'!B25
...

Sheet buy100_expert_10
A1: buy100_expert_10 Lookup Detail
A2: Derived from lookup rows
A3: Cost | B3: 99 | C3: Target RTP | D3: 0.9605 | E3: RTP Tol | F3: 0.01 | G3: Payout Scale | H3: 100
A5: Rows
A6: sim_id | B6: weight | C6: payout_raw | D6: payout_scaled | E6: probability | F6: weighted_payout | G6: cumulative_probability
A7: 3 | B7: 16918 | C7: 198000 | D7: =C7/$H$3 | E7: =IF($B$16>0,B7/$B$16,0) | F7: =D7*E7 | G7: =E7
A8: 4 | B8: 186113 | C8: 5940 | D8: =C8/$H$3 | E8: =IF($B$16>0,B8/$B$16,0) | F8: =D8*E8 | G8: =G7+E8
A9: 5 | B9: 197979 | C9: 990 | D9: =C9/$H$3 | E9: =IF($B$16>0,B9/$B$16,0) | F9: =D9*E9 | G9: =G8+E9
A10: 6 | B10: 197979 | C10: 990 | D10: =C10/$H$3 | E10: =IF($B$16>0,B10/$B$16,0) | F10: =D10*E10 | G10: =G9+E10
A11: 7 | B11: 197979 | C11: 990 | D11: =C11/$H$3 | E11: =IF($B$16>0,B11/$B$16,0) | F11: =D11*E11 | G11: =G10+E11
A12: 8 | B12: 186113 | C12: 5940 | D12: =C12/$H$3 | E12: =IF($B$16>0,B12/$B$16,0) | F12: =D12*E12 | G12: =G11+E12
A13: 9 | B13: 16918 | C13: 198000 | D13: =C13/$H$3 | E13: =IF($B$16>0,B13/$B$16,0) | F13: =D13*E13 | G13: =G12+E13
A14: 11 | B14: 1 | C14: 10000000 | D14: =C14/$H$3 | E14: =IF($B$16>0,B14/$B$16,0) | F14: =D14*E14 | G14: =G13+E14
A16: CHECK_SUMS | B16: =SUM(B7:B14) | C16: payout_raw_sum | D16: =SUM(D7:D14) | E16: =SUM(E7:E14) | F16: =SUM(F7:F14) | G16: =IF($B$3>0,F16/$B$3,0) | H16: =IF($D$3="","N/A",ABS(G16-$D$3)<=$F$3)
A17: rtp_drift | B17: =IF($D$3="","",G16-$D$3)
A18: prob_sum_check | B18: =ABS(E16-1)<=1E-9
A19: max_win_value | B19: =MAX(D7:D14)
A20: max_win_probability | B20: =SUMIFS(E7:E14,D7:D14,B19)
A21: outcome_rows | B21: =ROWS(A7:A14)
A22: unique_multipliers | B22: =SUMPRODUCT(1/COUNTIF(D7:D14,D7:D14))
A23: max_exposure_with_max_bet | B23: =B19*500.0

Sheet buy100_expert_11
A1: buy100_expert_11 Lookup Detail
A2: Derived from lookup rows
A3: Cost | B3: 99 | C3: Target RTP | D3: 0.9605 | E3: RTP Tol | F3: 0.01 | G3: Payout Scale | H3: 100
A5: Rows
A6: sim_id | B6: weight | C6: payout_raw | D6: payout_scaled | E6: probability | F6: weighted_payout | G6: cumulative_probability
A7: 3 | B7: 6436 | C7: 396000 | D7: =C7/$H$3 | E7: =IF($B$17>0,B7/$B$17,0) | F7: =D7*E7 | G7: =E7
A8: 4 | B8: 156093 | C8: 10890 | D8: =C8/$H$3 | E8: =IF($B$17>0,B8/$B$17,0) | F8: =D8*E8 | G8: =G7+E8
A9: 5 | B9: 168044 | C9: 1980 | D9: =C9/$H$3 | E9: =IF($B$17>0,B9/$B$17,0) | F9: =D9*E9 | G9: =G8+E9
A10: 6 | B10: 169427 | C10: 990 | D10: =C10/$H$3 | E10: =IF($B$17>0,B10/$B$17,0) | F10: =D10*E10 | G10: =G9+E10
A11: 7 | B11: 169427 | C11: 990 | D11: =C11/$H$3 | E11: =IF($B$17>0,B11/$B$17,0) | F11: =D11*E11 | G11: =G10+E11
A12: 8 | B12: 168043 | C12: 1980 | D12: =C12/$H$3 | E12: =IF($B$17>0,B12/$B$17,0) | F12: =D12*E12 | G12: =G11+E12
A13: 9 | B13: 156093 | C13: 10890 | D13: =C13/$H$3 | E13: =IF($B$17>0,B13/$B$17,0) | F13: =D13*E13 | G13: =G12+E13
A14: 10 | B14: 6436 | C14: 396000 | D14: =C14/$H$3 | E14: =IF($B$17>0,B14/$B$17,0) | F14: =D14*E14 | G14: =G13+E14
A15: 12 | B15: 1 | C15: 10000000 | D15: =C15/$H$3 | E15: =IF($B$17>0,B15/$B$17,0) | F15: =D15*E15 | G15: =G14+E15
A17: CHECK_SUMS | B17: =SUM(B7:B15) | C17: payout_raw_sum | D17: =SUM(D7:D15) | E17: =SUM(E7:E15) | F17: =SUM(F7:F15) | G17: =IF($B$3>0,F17/$B$3,0) | H17: =IF($D$3="","N/A",ABS(G17-$D$3)<=$F$3)
A18: rtp_drift | B18: =IF($D$3="","",G17-$D$3)
A19: prob_sum_check | B19: =ABS(E17-1)<=1E-9
A20: max_win_value | B20: =MAX(D7:D15)
A21: max_win_probability | B21: =SUMIFS(E7:E15,D7:D15,B20)
A22: outcome_rows | B22: =ROWS(A7:A15)
A23: unique_multipliers | B23: =SUMPRODUCT(1/COUNTIF(D7:D15,D7:D15))
A24: max_exposure_with_max_bet | B24: =B20*500.0

Sheet buy100_expert_12
A1: buy100_expert_12 Lookup Detail
A2: Derived from lookup rows
A3: Cost | B3: 99 | C3: Target RTP | D3: 0.9605 | E3: RTP Tol | F3: 0.01 | G3: Payout Scale | H3: 100
A5: Rows
A6: sim_id | B6: weight | C6: payout_raw | D6: payout_scaled | E6: probability | F6: weighted_payout | G6: cumulative_probability
A7: 3 | B7: 3327 | C7: 594000 | D7: =C7/$H$3 | E7: =IF($B$18>0,B7/$B$18,0) | F7: =D7*E7 | G7: =E7
A8: 4 | B8: 133852 | C8: 14850 | D8: =C8/$H$3 | E8: =IF($B$18>0,B8/$B$18,0) | F8: =D8*E8 | G8: =G7+E8
A9: 5 | B9: 143482 | C9: 3960 | D9: =C9/$H$3 | E9: =IF($B$18>0,B9/$B$18,0) | F9: =D9*E9 | G9: =G8+E9
A10: 6 | B10: 146226 | C10: 990 | D10: =C10/$H$3 | E10: =IF($B$18>0,B10/$B$18,0) | F10: =D10*E10 | G10: =G9+E10
A11: 7 | B11: 146226 | C11: 990 | D11: =C11/$H$3 | E11: =IF($B$18>0,B11/$B$18,0) | F11: =D11*E11 | G11: =G10+E11
A12: 8 | B12: 146226 | C12: 990 | D12: =C12/$H$3 | E12: =IF($B$18>0,B12/$B$18,0) | F12: =D12*E12 | G12: =G11+E12
A13: 9 | B13: 143481 | C13: 3960 | D13: =C13/$H$3 | E13: =IF($B$18>0,B13/$B$18,0) | F13: =D13*E13 | G13: =G12+E13
A14: 10 | B14: 133852 | C14: 14850 | D14: =C14/$H$3 | E14: =IF($B$18>0,B14/$B$18,0) | F14: =D14*E14 | G14: =G13+E14
A15: 11 | B15: 3327 | C15: 594000 | D15: =C15/$H$3 | E15: =IF($B$18>0,B15/$B$18,0) | F15: =D15*E15 | G15: =G14+E15
A16: 13 | B16: 1 | C16: 10000000 | D16: =C16/$H$3 | E16: =IF($B$18>0,B16/$B$18,0) | F16: =D16*E16 | G16: =G15+E16
A18: CHECK_SUMS | B18: =SUM(B7:B16) | C18: payout_raw_sum | D18: =SUM(D7:D16) | E18: =SUM(E7:E16) | F18: =SUM(F7:F16) | G18: =IF($B$3>0,F18/$B$3,0) | H18: =IF($D$3="","N/A",ABS(G18-$D$3)<=$F$3)
A19: rtp_drift | B19: =IF($D$3="","",G18-$D$3)
A20: prob_sum_check | B20: =ABS(E18-1)<=1E-9
A21: max_win_value | B21: =MAX(D7:D16)
A22: max_win_probability | B22: =SUMIFS(E7:E16,D7:D16,B21)
A23: outcome_rows | B23: =ROWS(A7:A16)
A24: unique_multipliers | B24: =SUMPRODUCT(1/COUNTIF(D7:D16,D7:D16))
A25: max_exposure_with_max_bet | B25: =B21*500.0

Sheet buy100_expert_13
A1: buy100_expert_13 Lookup Detail
A2: Derived from lookup rows
A3: Cost | B3: 99 | C3: Target RTP | D3: 0.9605 | E3: RTP Tol | F3: 0.01 | G3: Payout Scale | H3: 100
A5: Rows
A6: sim_id | B6: weight | C6: payout_raw | D6: payout_scaled | E6: probability | F6: weighted_payout | G6: cumulative_probability
A7: 3 | B7: 447 | C7: 990000 | D7: =C7/$H$3 | E7: =IF($B$19>0,B7/$B$19,0) | F7: =D7*E7 | G7: =E7
A8: 4 | B8: 110896 | C8: 29700 | D8: =C8/$H$3 | E8: =IF($B$19>0,B8/$B$19,0) | F8: =D8*E8 | G8: =G7+E8
A9: 5 | B9: 127109 | C9: 5940 | D9: =C9/$H$3 | E9: =IF($B$19>0,B9/$B$19,0) | F9: =D9*E9 | G9: =G8+E9
A10: 6 | B10: 130774 | C10: 990 | D10: =C10/$H$3 | E10: =IF($B$19>0,B10/$B$19,0) | F10: =D10*E10 | G10: =G9+E10
A11: 7 | B11: 130774 | C11: 990 | D11: =C11/$H$3 | E11: =IF($B$19>0,B11/$B$19,0) | F11: =D11*E11 | G11: =G10+E11
A12: 8 | B12: 130774 | C12: 990 | D12: =C12/$H$3 | E12: =IF($B$19>0,B12/$B$19,0) | F12: =D12*E12 | G12: =G11+E12
A13: 9 | B13: 130774 | C13: 990 | D13: =C13/$H$3 | E13: =IF($B$19>0,B13/$B$19,0) | F13: =D13*E13 | G13: =G12+E13
A14: 10 | B14: 127109 | C14: 5940 | D14: =C14/$H$3 | E14: =IF($B$19>0,B14/$B$19,0) | F14: =D14*E14 | G14: =G13+E14
A15: 11 | B15: 110895 | C15: 29700 | D15: =C15/$H$3 | E15: =IF($B$19>0,B15/$B$19,0) | F15: =D15*E15 | G15: =G14+E15
A16: 12 | B16: 447 | C16: 990000 | D16: =C16/$H$3 | E16: =IF($B$19>0,B16/$B$19,0) | F16: =D16*E16 | G16: =G15+E16
A17: 14 | B17: 1 | C17: 10000000 | D17: =C17/$H$3 | E17: =IF($B$19>0,B17/$B$19,0) | F17: =D17*E17 | G17: =G16+E17
A19: CHECK_SUMS | B19: =SUM(B7:B17) | C19: payout_raw_sum | D19: =SUM(D7:D17) | E19: =SUM(E7:E17) | F19: =SUM(F7:F17) | G19: =IF($B$3>0,F19/$B$3,0) | H19: =IF($D$3="","N/A",ABS(G19-$D$3)<=$F$3)
A20: rtp_drift | B20: =IF($D$3="","",G19-$D$3)
A21: prob_sum_check | B21: =ABS(E19-1)<=1E-9
A22: max_win_value | B22: =MAX(D7:D17)
A23: max_win_probability | B23: =SUMIFS(E7:E17,D7:D17,B22)
A24: outcome_rows | B24: =ROWS(A7:A17)
A25: unique_multipliers | B25: =SUMPRODUCT(1/COUNTIF(D7:D17,D7:D17))
A26: max_exposure_with_max_bet | B26: =B22*500.0

Sheet buy100_expert_14
A1: buy100_expert_14 Lookup Detail
A2: Derived from lookup rows
A3: Cost | B3: 99 | C3: Target RTP | D3: 0.9605 | E3: RTP Tol | F3: 0.01 | G3: Payout Scale | H3: 100
A5: Rows
A6: sim_id | B6: weight | C6: payout_raw | D6: payout_scaled | E6: probability | F6: weighted_payout | G6: cumulative_probability
A7: 3 | B7: 39 | C7: 1584000 | D7: =C7/$H$3 | E7: =IF($B$20>0,B7/$B$20,0) | F7: =D7*E7 | G7: =E7
A8: 4 | B8: 100403 | C8: 29700 | D8: =C8/$H$3 | E8: =IF($B$20>0,B8/$B$20,0) | F8: =D8*E8 | G8: =G7+E8
A9: 5 | B9: 109878 | C9: 11880 | D9: =C9/$H$3 | E9: =IF($B$20>0,B9/$B$20,0) | F9: =D9*E9 | G9: =G8+E9
A10: 6 | B10: 115524 | C10: 1980 | D10: =C10/$H$3 | E10: =IF($B$20>0,B10/$B$20,0) | F10: =D10*E10 | G10: =G9+E10
A11: 7 | B11: 116104 | C11: 990 | D11: =C11/$H$3 | E11: =IF($B$20>0,B11/$B$20,0) | F11: =D11*E11 | G11: =G10+E11
A12: 8 | B12: 116104 | C12: 990 | D12: =C12/$H$3 | E12: =IF($B$20>0,B12/$B$20,0) | F12: =D12*E12 | G12: =G11+E12
A13: 9 | B13: 116104 | C13: 990 | D13: =C13/$H$3 | E13: =IF($B$20>0,B13/$B$20,0) | F13: =D13*E13 | G13: =G12+E13
A14: 10 | B14: 115524 | C14: 1980 | D14: =C14/$H$3 | E14: =IF($B$20>0,B14/$B$20,0) | F14: =D14*E14 | G14: =G13+E14
A15: 11 | B15: 109878 | C15: 11880 | D15: =C15/$H$3 | E15: =IF($B$20>0,B15/$B$20,0) | F15: =D15*E15 | G15: =G14+E15
A16: 12 | B16: 100403 | C16: 29700 | D16: =C16/$H$3 | E16: =IF($B$20>0,B16/$B$20,0) | F16: =D16*E16 | G16: =G15+E16
A17: 13 | B17: 38 | C17: 1584000 | D17: =C17/$H$3 | E17: =IF($B$20>0,B17/$B$20,0) | F17: =D17*E17 | G17: =G16+E17
A18: 15 | B18: 1 | C18: 10000000 | D18: =C18/$H$3 | E18: =IF($B$20>0,B18/$B$20,0) | F18: =D18*E18 | G18: =G17+E18
A20: CHECK_SUMS | B20: =SUM(B7:B18) | C20: payout_raw_sum | D20: =SUM(D7:D18) | E20: =SUM(E7:E18) | F20: =SUM(F7:F18) | G20: =IF($B$3>0,F20/$B$3,0) | H20: =IF($D$3="","N/A",ABS(G20-$D$3)<=$F$3)
A21: rtp_drift | B21: =IF($D$3="","",G20-$D$3)
A22: prob_sum_check | B22: =ABS(E20-1)<=1E-9
A23: max_win_value | B23: =MAX(D7:D18)
A24: max_win_probability | B24: =SUMIFS(E7:E18,D7:D18,B23)
A25: outcome_rows | B25: =ROWS(A7:A18)
A26: unique_multipliers | B26: =SUMPRODUCT(1/COUNTIF(D7:D18,D7:D18))
A27: max_exposure_with_max_bet | B27: =B23*500.0

Sheet buy100_expert_15
A1: buy100_expert_15 Lookup Detail
A2: Derived from lookup rows
A3: Cost | B3: 99 | C3: Target RTP | D3: 0.9605 | E3: RTP Tol | F3: 0.01 | G3: Payout Scale | H3: 100
A5: Rows
A6: sim_id | B6: weight | C6: payout_raw | D6: payout_scaled | E6: probability | F6: weighted_payout | G6: cumulative_probability
A7: 4 | B7: 44501 | C7: 59400 | D7: =C7/$H$3 | E7: =IF($B$19>0,B7/$B$19,0) | F7: =D7*E7 | G7: =E7
A8: 5 | B8: 91285 | C8: 17820 | D8: =C8/$H$3 | E8: =IF($B$19>0,B8/$B$19,0) | F8: =D8*E8 | G8: =G7+E8
A9: 6 | B9: 120024 | C9: 1980 | D9: =C9/$H$3 | E9: =IF($B$19>0,B9/$B$19,0) | F9: =D9*E9 | G9: =G8+E9
A10: 7 | B10: 122095 | C10: 990 | D10: =C10/$H$3 | E10: =IF($B$19>0,B10/$B$19,0) | F10: =D10*E10 | G10: =G9+E10
A11: 8 | B11: 122095 | C11: 990 | D11: =C11/$H$3 | E11: =IF($B$19>0,B11/$B$19,0) | F11: =D11*E11 | G11: =G10+E11
A12: 9 | B12: 122095 | C12: 990 | D12: =C12/$H$3 | E12: =IF($B$19>0,B12/$B$19,0) | F12: =D12*E12 | G12: =G11+E12
A13: 10 | B13: 122094 | C13: 990 | D13: =C13/$H$3 | E13: =IF($B$19>0,B13/$B$19,0) | F13: =D13*E13 | G13: =G12+E13
A14: 11 | B14: 120024 | C14: 1980 | D14: =C14/$H$3 | E14: =IF($B$19>0,B14/$B$19,0) | F14: =D14*E14 | G14: =G13+E14
A15: 12 | B15: 91285 | C15: 17820 | D15: =C15/$H$3 | E15: =IF($B$19>0,B15/$B$19,0) | F15: =D15*E15 | G15: =G14+E15
A16: 13 | B16: 44501 | C16: 59400 | D16: =C16/$H$3 | E16: =IF($B$19>0,B16/$B$19,0) | F16: =D16*E16 | G16: =G15+E16
A17: 16 | B17: 1 | C17: 10000000 | D17: =C17/$H$3 | E17: =IF($B$19>0,B17/$B$19,0) | F17: =D17*E17 | G17: =G16+E17
A19: CHECK_SUMS | B19: =SUM(B7:B17) | C19: payout_raw_sum | D19: =SUM(D7:D17) | E19: =SUM(E7:E17) | F19: =SUM(F7:F17) | G19: =IF($B$3>0,F19/$B$3,0) | H19: =IF($D$3="","N/A",ABS(G19-$D$3)<=$F$3)
A20: rtp_drift | B20: =IF($D$3="","",G19-$D$3)
A21: prob_sum_check | B21: =ABS(E19-1)<=1E-9
A22: max_win_value | B22: =MAX(D7:D17)
A23: max_win_probability | B23: =SUMIFS(E7:E17,D7:D17,B22)
A24: outcome_rows | B24: =ROWS(A7:A17)
A25: unique_multipliers | B25: =SUMPRODUCT(1/COUNTIF(D7:D17,D7:D17))
A26: max_exposure_with_max_bet | B26: =B22*500.0

Sheet buy100_expert_16
A1: buy100_expert_16 Lookup Detail
A2: Derived from lookup rows
A3: Cost | B3: 99 | C3: Target RTP | D3: 0.9605 | E3: RTP Tol | F3: 0.01 | G3: Payout Scale | H3: 100
A5: Rows
A6: sim_id | B6: weight | C6: payout_raw | D6: payout_scaled | E6: probability | F6: weighted_payout | G6: cumulative_probability
A7: 4 | B7: 23897 | C7: 69300 | D7: =C7/$H$3 | E7: =IF($B$20>0,B7/$B$20,0) | F7: =D7*E7 | G7: =E7
A8: 5 | B8: 69779 | C8: 24750 | D8: =C8/$H$3 | E8: =IF($B$20>0,B8/$B$20,0) | F8: =D8*E8 | G8: =G7+E8
A9: 6 | B9: 97389 | C9: 10890 | D9: =C9/$H$3 | E9: =IF($B$20>0,B9/$B$20,0) | F9: =D9*E9 | G9: =G8+E9
A10: 7 | B10: 123574 | C10: 990 | D10: =C10/$H$3 | E10: =IF($B$20>0,B10/$B$20,0) | F10: =D10*E10 | G10: =G9+E10
A11: 8 | B11: 123574 | C11: 990 | D11: =C11/$H$3 | E11: =IF($B$20>0,B11/$B$20,0) | F11: =D11*E11 | G11: =G10+E11
A12: 9 | B12: 123574 | C12: 990 | D12: =C12/$H$3 | E12: =IF($B$20>0,B12/$B$20,0) | F12: =D12*E12 | G12: =G11+E12
A13: 10 | B13: 123574 | C13: 990 | D13: =C13/$H$3 | E13: =IF($B$20>0,B13/$B$20,0) | F13: =D13*E13 | G13: =G12+E13
A14: 11 | B14: 123574 | C14: 990 | D14: =C14/$H$3 | E14: =IF($B$20>0,B14/$B$20,0) | F14: =D14*E14 | G14: =G13+E14
A15: 12 | B15: 97389 | C15: 10890 | D15: =C15/$H$3 | E15: =IF($B$20>0,B15/$B$20,0) | F15: =D15*E15 | G15: =G14+E15
A16: 13 | B16: 69778 | C16: 24750 | D16: =C16/$H$3 | E16: =IF($B$20>0,B16/$B$20,0) | F16: =D16*E16 | G16: =G15+E16
A17: 14 | B17: 23897 | C17: 69300 | D17: =C17/$H$3 | E17: =IF($B$20>0,B17/$B$20,0) | F17: =D17*E17 | G17: =G16+E17
A18: 17 | B18: 1 | C18: 10000000 | D18: =C18/$H$3 | E18: =IF($B$20>0,B18/$B$20,0) | F18: =D18*E18 | G18: =G17+E18
A20: CHECK_SUMS | B20: =SUM(B7:B18) | C20: payout_raw_sum | D20: =SUM(D7:D18) | E20: =SUM(E7:E18) | F20: =SUM(F7:F18) | G20: =IF($B$3>0,F20/$B$3,0) | H20: =IF($D$3="","N/A",ABS(G20-$D$3)<=$F$3)
A21: rtp_drift | B21: =IF($D$3="","",G20-$D$3)
A22: prob_sum_check | B22: =ABS(E20-1)<=1E-9
A23: max_win_value | B23: =MAX(D7:D18)
A24: max_win_probability | B24: =SUMIFS(E7:E18,D7:D18,B23)
A25: outcome_rows | B25: =ROWS(A7:A18)
A26: unique_multipliers | B26: =SUMPRODUCT(1/COUNTIF(D7:D18,D7:D18))
A27: max_exposure_with_max_bet | B27: =B23*500.0

Sheet buy100_expert_8
A1: buy100_expert_8 Lookup Detail
A2: Derived from lookup rows
A3: Cost | B3: 99 | C3: Target RTP | D3: 0.9605 | E3: RTP Tol | F3: 0.01 | G3: Payout Scale | H3: 100
A5: Rows
A6: sim_id | B6: weight | C6: payout_raw | D6: payout_scaled | E6: probability | F6: weighted_payout | G6: cumulative_probability
A7: 2 | B7: 53 | C7: 455400 | D7: =C7/$H$3 | E7: =IF($B$16>0,B7/$B$16,0) | F7: =D7*E7 | G7: =E7
A8: 3 | B8: 39227 | C8: 108900 | D8: =C8/$H$3 | E8: =IF($B$16>0,B8/$B$16,0) | F8: =D8*E8 | G8: =G7+E8
A9: 4 | B9: 307147 | C9: 990 | D9: =C9/$H$3 | E9: =IF($B$16>0,B9/$B$16,0) | F9: =D9*E9 | G9: =G8+E9
A10: 5 | B10: 307146 | C10: 990 | D10: =C10/$H$3 | E10: =IF($B$16>0,B10/$B$16,0) | F10: =D10*E10 | G10: =G9+E10
A11: 6 | B11: 307146 | C11: 990 | D11: =C11/$H$3 | E11: =IF($B$16>0,B11/$B$16,0) | F11: =D11*E11 | G11: =G10+E11
A12: 7 | B12: 39227 | C12: 108900 | D12: =C12/$H$3 | E12: =IF($B$16>0,B12/$B$16,0) | F12: =D12*E12 | G12: =G11+E12
A13: 8 | B13: 53 | C13: 455400 | D13: =C13/$H$3 | E13: =IF($B$16>0,B13/$B$16,0) | F13: =D13*E13 | G13: =G12+E13
A14: 9 | B14: 1 | C14: 4950000 | D14: =C14/$H$3 | E14: =IF($B$16>0,B14/$B$16,0) | F14: =D14*E14 | G14: =G13+E14
A16: CHECK_SUMS | B16: =SUM(B7:B14) | C16: payout_raw_sum | D16: =SUM(D7:D14) | E16: =SUM(E7:E14) | F16: =SUM(F7:F14) | G16: =IF($B$3>0,F16/$B$3,0) | H16: =IF($D$3="","N/A",ABS(G16-$D$3)<=$F$3)
A17: rtp_drift | B17: =IF($D$3="","",G16-$D$3)
A18: prob_sum_check | B18: =ABS(E16-1)<=1E-9
A19: max_win_value | B19: =MAX(D7:D14)
A20: max_win_probability | B20: =SUMIFS(E7:E14,D7:D14,B19)
A21: outcome_rows | B21: =ROWS(A7:A14)
A22: unique_multipliers | B22: =SUMPRODUCT(1/COUNTIF(D7:D14,D7:D14))
A23: max_exposure_with_max_bet | B23: =B19*500.0

Sheet buy100_expert_9
A1: buy100_expert_9 Lookup Detail
A2: Derived from lookup rows
A3: Cost | B3: 99 | C3: Target RTP | D3: 0.9605 | E3: RTP Tol | F3: 0.01 | G3: Payout Scale | H3: 100
A5: Rows
A6: sim_id | B6: weight | C6: payout_raw | D6: payout_scaled | E6: probability | F6: weighted_payout | G6: cumulative_probability
A7: 2 | B7: 3 | C7: 772200 | D7: =C7/$H$3 | E7: =IF($B$17>0,B7/$B$17,0) | F7: =D7*E7 | G7: =E7
A8: 3 | B8: 27253 | C8: 148500 | D8: =C8/$H$3 | E8: =IF($B$17>0,B8/$B$17,0) | F8: =D8*E8 | G8: =G7+E8
A9: 4 | B9: 234653 | C9: 1980 | D9: =C9/$H$3 | E9: =IF($B$17>0,B9/$B$17,0) | F9: =D9*E9 | G9: =G8+E9
A10: 5 | B10: 238091 | C10: 990 | D10: =C10/$H$3 | E10: =IF($B$17>0,B10/$B$17,0) | F10: =D10*E10 | G10: =G9+E10
A11: 6 | B11: 238091 | C11: 990 | D11: =C11/$H$3 | E11: =IF($B$17>0,B11/$B$17,0) | F11: =D11*E11 | G11: =G10+E11
A12: 7 | B12: 234653 | C12: 1980 | D12: =C12/$H$3 | E12: =IF($B$17>0,B12/$B$17,0) | F12: =D12*E12 | G12: =G11+E12
A13: 8 | B13: 27252 | C13: 148500 | D13: =C13/$H$3 | E13: =IF($B$17>0,B13/$B$17,0) | F13: =D13*E13 | G13: =G12+E13
A14: 9 | B14: 3 | C14: 772200 | D14: =C14/$H$3 | E14: =IF($B$17>0,B14/$B$17,0) | F14: =D14*E14 | G14: =G13+E14
A15: 10 | B15: 1 | C15: 9900000 | D15: =C15/$H$3 | E15: =IF($B$17>0,B15/$B$17,0) | F15: =D15*E15 | G15: =G14+E15
A17: CHECK_SUMS | B17: =SUM(B7:B15) | C17: payout_raw_sum | D17: =SUM(D7:D15) | E17: =SUM(E7:E15) | F17: =SUM(F7:F15) | G17: =IF($B$3>0,F17/$B$3,0) | H17: =IF($D$3="","N/A",ABS(G17-$D$3)<=$F$3)
A18: rtp_drift | B18: =IF($D$3="","",G17-$D$3)
A19: prob_sum_check | B19: =ABS(E17-1)<=1E-9
A20: max_win_value | B20: =MAX(D7:D15)
A21: max_win_probability | B21: =SUMIFS(E7:E15,D7:D15,B20)
A22: outcome_rows | B22: =ROWS(A7:A15)
A23: unique_multipliers | B23: =SUMPRODUCT(1/COUNTIF(D7:D15,D7:D15))
A24: max_exposure_with_max_bet | B24: =B20*500.0

Sheet buy100_high_10
A1: buy100_high_10 Lookup Detail
A2: Derived from lookup rows
A3: Cost | B3: 99 | C3: Target RTP | D3: 0.9605 | E3: RTP Tol | F3: 0.01 | G3: Payout Scale | H3: 100
A5: Rows
A6: sim_id | B6: weight | C6: payout_raw | D6: payout_scaled | E6: probability | F6: weighted_payout | G6: cumulative_probability
A7: 2 | B7: 6175 | C7: 99000 | D7: =C7/$H$3 | E7: =IF($B$18>0,B7/$B$18,0) | F7: =D7*E7 | G7: =E7
A8: 3 | B8: 70857 | C8: 29700 | D8: =C8/$H$3 | E8: =IF($B$18>0,B8/$B$18,0) | F8: =D8*E8 | G8: =G7+E8
A9: 4 | B9: 147334 | C9: 8910 | D9: =C9/$H$3 | E9: =IF($B$18>0,B9/$B$18,0) | F9: =D9*E9 | G9: =G8+E9
A10: 5 | B10: 181608 | C10: 2970 | D10: =C10/$H$3 | E10: =IF($B$18>0,B10/$B$18,0) | F10: =D10*E10 | G10: =G9+E10
A11: 6 | B11: 188051 | C11: 1980 | D11: =C11/$H$3 | E11: =IF($B$18>0,B11/$B$18,0) | F11: =D11*E11 | G11: =G10+E11
A12: 7 | B12: 181608 | C12: 2970 | D12: =C12/$H$3 | E12: =IF($B$18>0,B12/$B$18,0) | F12: =D12*E12 | G12: =G11+E12
A13: 8 | B13: 147334 | C13: 8910 | D13: =C13/$H$3 | E13: =IF($B$18>0,B13/$B$18,0) | F13: =D13*E13 | G13: =G12+E13
A14: 9 | B14: 70857 | C14: 29700 | D14: =C14/$H$3 | E14: =IF($B$18>0,B14/$B$18,0) | F14: =D14*E14 | G14: =G13+E14
A15: 10 | B15: 6175 | C15: 99000 | D15: =C15/$H$3 | E15: =IF($B$18>0,B15/$B$18,0) | F15: =D15*E15 | G15: =G14+E15
A16: 11 | B16: 1 | C16: 752400 | D16: =C16/$H$3 | E16: =IF($B$18>0,B16/$B$18,0) | F16: =D16*E16 | G16: =G15+E16
A18: CHECK_SUMS | B18: =SUM(B7:B16) | C18: payout_raw_sum | D18: =SUM(D7:D16) | E18: =SUM(E7:E16) | F18: =SUM(F7:F16) | G18: =IF($B$3>0,F18/$B$3,0) | H18: =IF($D$3="","N/A",ABS(G18-$D$3)<=$F$3)
A19: rtp_drift | B19: =IF($D$3="","",G18-$D$3)
A20: prob_sum_check | B20: =ABS(E18-1)<=1E-9
A21: max_win_value | B21: =MAX(D7:D16)
A22: max_win_probability | B22: =SUMIFS(E7:E16,D7:D16,B21)
A23: outcome_rows | B23: =ROWS(A7:A16)
A24: unique_multipliers | B24: =SUMPRODUCT(1/COUNTIF(D7:D16,D7:D16))
A25: max_exposure_with_max_bet | B25: =B21*500.0

Sheet buy100_high_11
A1: buy100_high_11 Lookup Detail
A2: Derived from lookup rows
A3: Cost | B3: 99 | C3: Target RTP | D3: 0.9605 | E3: RTP Tol | F3: 0.01 | G3: Payout Scale | H3: 100
A5: Rows
A6: sim_id | B6: weight | C6: payout_raw | D6: payout_scaled | E6: probability | F6: weighted_payout | G6: cumulative_probability
A7: 2 | B7: 2022 | C7: 138600 | D7: =C7/$H$3 | E7: =IF($B$19>0,B7/$B$19,0) | F7: =D7*E7 | G7: =E7
A8: 3 | B8: 35021 | C8: 51480 | D8: =C8/$H$3 | E8: =IF($B$19>0,B8/$B$19,0) | F8: =D8*E8 | G8: =G7+E8
A9: 4 | B9: 119996 | C9: 13860 | D9: =C9/$H$3 | E9: =IF($B$19>0,B9/$B$19,0) | F9: =D9*E9 | G9: =G8+E9
A10: 5 | B10: 165925 | C10: 3960 | D10: =C10/$H$3 | E10: =IF($B$19>0,B10/$B$19,0) | F10: =D10*E10 | G10: =G9+E10
A11: 6 | B11: 177036 | C11: 1980 | D11: =C11/$H$3 | E11: =IF($B$19>0,B11/$B$19,0) | F11: =D11*E11 | G11: =G10+E11
A12: 7 | B12: 177035 | C12: 1980 | D12: =C12/$H$3 | E12: =IF($B$19>0,B12/$B$19,0) | F12: =D12*E12 | G12: =G11+E12
A13: 8 | B13: 165925 | C13: 3960 | D13: =C13/$H$3 | E13: =IF($B$19>0,B13/$B$19,0) | F13: =D13*E13 | G13: =G12+E13
A14: 9 | B14: 119996 | C14: 13860 | D14: =C14/$H$3 | E14: =IF($B$19>0,B14/$B$19,0) | F14: =D14*E14 | G14: =G13+E14
A15: 10 | B15: 35021 | C15: 51480 | D15: =C15/$H$3 | E15: =IF($B$19>0,B15/$B$19,0) | F15: =D15*E15 | G15: =G14+E15
A16: 11 | B16: 2022 | C16: 138600 | D16: =C16/$H$3 | E16: =IF($B$19>0,B16/$B$19,0) | F16: =D16*E16 | G16: =G15+E16
A17: 12 | B17: 1 | C17: 1188000 | D17: =C17/$H$3 | E17: =IF($B$19>0,B17/$B$19,0) | F17: =D17*E17 | G17: =G16+E17
A19: CHECK_SUMS | B19: =SUM(B7:B17) | C19: payout_raw_sum | D19: =SUM(D7:D17) | E19: =SUM(E7:E17) | F19: =SUM(F7:F17) | G19: =IF($B$3>0,F19/$B$3,0) | H19: =IF($D$3="","N/A",ABS(G19-$D$3)<=$F$3)
A20: rtp_drift | B20: =IF($D$3="","",G19-$D$3)
A21: prob_sum_check | B21: =ABS(E19-1)<=1E-9
A22: max_win_value | B22: =MAX(D7:D17)
A23: max_win_probability | B23: =SUMIFS(E7:E17,D7:D17,B22)
A24: outcome_rows | B24: =ROWS(A7:A17)
A25: unique_multipliers | B25: =SUMPRODUCT(1/COUNTIF(D7:D17,D7:D17))
A26: max_exposure_with_max_bet | B26: =B22*500.0

Sheet buy100_high_12
A1: buy100_high_12 Lookup Detail
A2: Derived from lookup rows
A3: Cost | B3: 99 | C3: Target RTP | D3: 0.9605 | E3: RTP Tol | F3: 0.01 | G3: Payout Scale | H3: 100
A5: Rows
A6: sim_id | B6: weight | C6: payout_raw | D6: payout_scaled | E6: probability | F6: weighted_payout | G6: cumulative_probability
A7: 2 | B7: 166 | C7: 237600 | D7: =C7/$H$3 | E7: =IF($B$20>0,B7/$B$20,0) | F7: =D7*E7 | G7: =E7
A8: 3 | B8: 16582 | C8: 80190 | D8: =C8/$H$3 | E8: =IF($B$20>0,B8/$B$20,0) | F8: =D8*E8 | G8: =G7+E8
A9: 4 | B9: 96980 | C9: 19800 | D9: =C9/$H$3 | E9: =IF($B$20>0,B9/$B$20,0) | F9: =D9*E9 | G9: =G8+E9
A10: 5 | B10: 141302 | C10: 6930 | D10: =C10/$H$3 | E10: =IF($B$20>0,B10/$B$20,0) | F10: =D10*E10 | G10: =G9+E10
A11: 6 | B11: 163313 | C11: 1980 | D11: =C11/$H$3 | E11: =IF($B$20>0,B11/$B$20,0) | F11: =D11*E11 | G11: =G10+E11
A12: 7 | B12: 163313 | C12: 1980 | D12: =C12/$H$3 | E12: =IF($B$20>0,B12/$B$20,0) | F12: =D12*E12 | G12: =G11+E12
A13: 8 | B13: 163313 | C13: 1980 | D13: =C13/$H$3 | E13: =IF($B$20>0,B13/$B$20,0) | F13: =D13*E13 | G13: =G12+E13
A14: 9 | B14: 141302 | C14: 6930 | D14: =C14/$H$3 | E14: =IF($B$20>0,B14/$B$20,0) | F14: =D14*E14 | G14: =G13+E14
A15: 10 | B15: 96980 | C15: 19800 | D15: =C15/$H$3 | E15: =IF($B$20>0,B15/$B$20,0) | F15: =D15*E15 | G15: =G14+E15
A16: 11 | B16: 16582 | C16: 80190 | D16: =C16/$H$3 | E16: =IF($B$20>0,B16/$B$20,0) | F16: =D16*E16 | G16: =G15+E16
A17: 12 | B17: 166 | C17: 237600 | D17: =C17/$H$3 | E17: =IF($B$20>0,B17/$B$20,0) | F17: =D17*E17 | G17: =G16+E17
A18: 13 | B18: 1 | C18: 1683000 | D18: =C18/$H$3 | E18: =IF($B$20>0,B18/$B$20,0) | F18: =D18*E18 | G18: =G17+E18
A20: CHECK_SUMS | B20: =SUM(B7:B18) | C20: payout_raw_sum | D20: =SUM(D7:D18) | E20: =SUM(E7:E18) | F20: =SUM(F7:F18) | G20: =IF($B$3>0,F20/$B$3,0) | H20: =IF($D$3="","N/A",ABS(G20-$D$3)<=$F$3)
A21: rtp_drift | B21: =IF($D$3="","",G20-$D$3)
A22: prob_sum_check | B22: =ABS(E20-1)<=1E-9
A23: max_win_value | B23: =MAX(D7:D18)
A24: max_win_probability | B24: =SUMIFS(E7:E18,D7:D18,B23)
A25: outcome_rows | B25: =ROWS(A7:A18)
A26: unique_multipliers | B26: =SUMPRODUCT(1/COUNTIF(D7:D18,D7:D18))
A27: max_exposure_with_max_bet | B27: =B23*500.0

Sheet buy100_high_13
A1: buy100_high_13 Lookup Detail
A2: Derived from lookup rows
A3: Cost | B3: 99 | C3: Target RTP | D3: 0.9605 | E3: RTP Tol | F3: 0.01 | G3: Payout Scale | H3: 100
A5: Rows
A6: sim_id | B6: weight | C6: payout_raw | D6: payout_scaled | E6: probability | F6: weighted_payout | G6: cumulative_probability
A7: 2 | B7: 4 | C7: 366300 | D7: =C7/$H$3 | E7: =IF($B$21>0,B7/$B$21,0) | F7: =D7*E7 | G7: =E7
A8: 3 | B8: 7209 | C8: 108900 | D8: =C8/$H$3 | E8: =IF($B$21>0,B8/$B$21,0) | F8: =D8*E8 | G8: =G7+E8
A9: 4 | B9: 53155 | C9: 39600 | D9: =C9/$H$3 | E9: =IF($B$21>0,B9/$B$21,0) | F9: =D9*E9 | G9: =G8+E9
A10: 5 | B10: 125144 | C10: 9900 | D10: =C10/$H$3 | E10: =IF($B$21>0,B10/$B$21,0) | F10: =D10*E10 | G10: =G9+E10
A11: 6 | B11: 157244 | C11: 1980 | D11: =C11/$H$3 | E11: =IF($B$21>0,B11/$B$21,0) | F11: =D11*E11 | G11: =G10+E11
A12: 7 | B12: 157244 | C12: 1980 | D12: =C12/$H$3 | E12: =IF($B$21>0,B12/$B$21,0) | F12: =D12*E12 | G12: =G11+E12
A13: 8 | B13: 157244 | C13: 1980 | D13: =C13/$H$3 | E13: =IF($B$21>0,B13/$B$21,0) | F13: =D13*E13 | G13: =G12+E13
A14: 9 | B14: 157243 | C14: 1980 | D14: =C14/$H$3 | E14: =IF($B$21>0,B14/$B$21,0) | F14: =D14*E14 | G14: =G13+E14
A15: 10 | B15: 125144 | C15: 9900 | D15: =C15/$H$3 | E15: =IF($B$21>0,B15/$B$21,0) | F15: =D15*E15 | G15: =G14+E15
A16: 11 | B16: 53155 | C16: 39600 | D16: =C16/$H$3 | E16: =IF($B$21>0,B16/$B$21,0) | F16: =D16*E16 | G16: =G15+E16
A17: 12 | B17: 7209 | C17: 108900 | D17: =C17/$H$3 | E17: =IF($B$21>0,B17/$B$21,0) | F17: =D17*E17 | G17: =G16+E17
A18: 13 | B18: 4 | C18: 366300 | D18: =C18/$H$3 | E18: =IF($B$21>0,B18/$B$21,0) | F18: =D18*E18 | G18: =G17+E18
A19: 14 | B19: 1 | C19: 2574000 | D19: =C19/$H$3 | E19: =IF($B$21>0,B19/$B$21,0) | F19: =D19*E19 | G19: =G18+E19
A21: CHECK_SUMS | B21: =SUM(B7:B19) | C21: payout_raw_sum | D21: =SUM(D7:D19) | E21: =SUM(E7:E19) | F21: =SUM(F7:F19) | G21: =IF($B$3>0,F21/$B$3,0) | H21: =IF($D$3="","N/A",ABS(G21-$D$3)<=$F$3)
A22: rtp_drift | B22: =IF($D$3="","",G21-$D$3)
A23: prob_sum_check | B23: =ABS(E21-1)<=1E-9
A24: max_win_value | B24: =MAX(D7:D19)
A25: max_win_probability | B25: =SUMIFS(E7:E19,D7:D19,B24)
A26: outcome_rows | B26: =ROWS(A7:A19)
A27: unique_multipliers | B27: =SUMPRODUCT(1/COUNTIF(D7:D19,D7:D19))
A28: max_exposure_with_max_bet | B28: =B24*500.0

Sheet buy100_high_14
A1: buy100_high_14 Lookup Detail
A2: Derived from lookup rows
A3: Cost | B3: 99 | C3: Target RTP | D3: 0.9605 | E3: RTP Tol | F3: 0.01 | G3: Payout Scale | H3: 100
A5: Rows
A6: sim_id | B6: weight | C6: payout_raw | D6: payout_scaled | E6: probability | F6: weighted_payout | G6: cumulative_probability
A7: 3 | B7: 1079 | C7: 178200 | D7: =C7/$H$3 | E7: =IF($B$20>0,B7/$B$20,0) | F7: =D7*E7 | G7: =E7
A8: 4 | B8: 39331 | C8: 49500 | D8: =C8/$H$3 | E8: =IF($B$20>0,B8/$B$20,0) | F8: =D8*E8 | G8: =G7+E8
A9: 5 | B9: 92711 | C9: 18810 | D9: =C9/$H$3 | E9: =IF($B$20>0,B9/$B$20,0) | F9: =D9*E9 | G9: =G8+E9
A10: 6 | B10: 144323 | C10: 2970 | D10: =C10/$H$3 | E10: =IF($B$20>0,B10/$B$20,0) | F10: =D10*E10 | G10: =G9+E10
A11: 7 | B11: 148371 | C11: 1980 | D11: =C11/$H$3 | E11: =IF($B$20>0,B11/$B$20,0) | F11: =D11*E11 | G11: =G10+E11
A12: 8 | B12: 148370 | C12: 1980 | D12: =C12/$H$3 | E12: =IF($B$20>0,B12/$B$20,0) | F12: =D12*E12 | G12: =G11+E12
A13: 9 | B13: 148370 | C13: 1980 | D13: =C13/$H$3 | E13: =IF($B$20>0,B13/$B$20,0) | F13: =D13*E13 | G13: =G12+E13
A14: 10 | B14: 144323 | C14: 2970 | D14: =C14/$H$3 | E14: =IF($B$20>0,B14/$B$20,0) | F14: =D14*E14 | G14: =G13+E14
A15: 11 | B15: 92711 | C15: 18810 | D15: =C15/$H$3 | E15: =IF($B$20>0,B15/$B$20,0) | F15: =D15*E15 | G15: =G14+E15
A16: 12 | B16: 39331 | C16: 49500 | D16: =C16/$H$3 | E16: =IF($B$20>0,B16/$B$20,0) | F16: =D16*E16 | G16: =G15+E16
A17: 13 | B17: 1079 | C17: 178200 | D17: =C17/$H$3 | E17: =IF($B$20>0,B17/$B$20,0) | F17: =D17*E17 | G17: =G16+E17
A18: 15 | B18: 1 | C18: 4158000 | D18: =C18/$H$3 | E18: =IF($B$20>0,B18/$B$20,0) | F18: =D18*E18 | G18: =G17+E18
A20: CHECK_SUMS | B20: =SUM(B7:B18) | C20: payout_raw_sum | D20: =SUM(D7:D18) | E20: =SUM(E7:E18) | F20: =SUM(F7:F18) | G20: =IF($B$3>0,F20/$B$3,0) | H20: =IF($D$3="","N/A",ABS(G20-$D$3)<=$F$3)
A21: rtp_drift | B21: =IF($D$3="","",G20-$D$3)
A22: prob_sum_check | B22: =ABS(E20-1)<=1E-9
A23: max_win_value | B23: =MAX(D7:D18)
A24: max_win_probability | B24: =SUMIFS(E7:E18,D7:D18,B23)
A25: outcome_rows | B25: =ROWS(A7:A18)
A26: unique_multipliers | B26: =SUMPRODUCT(1/COUNTIF(D7:D18,D7:D18))
A27: max_exposure_with_max_bet | B27: =B23*500.0

Sheet buy100_high_15
A1: buy100_high_15 Lookup Detail
A2: Derived from lookup rows
A3: Cost | B3: 99 | C3: Target RTP | D3: 0.9605 | E3: RTP Tol | F3: 0.01 | G3: Payout Scale | H3: 100
A5: Rows
A6: sim_id | B6: weight | C6: payout_raw | D6: payout_scaled | E6: probability | F6: weighted_payout | G6: cumulative_probability
A7: 3 | B7: 136 | C7: 267300 | D7: =C7/$H$3 | E7: =IF($B$21>0,B7/$B$21,0) | F7: =D7*E7 | G7: =E7
A8: 4 | B8: 18698 | C8: 79200 | D8: =C8/$H$3 | E8: =IF($B$21>0,B8/$B$21,0) | F8: =D8*E8 | G8: =G7+E8
A9: 5 | B9: 68315 | C9: 29700 | D9: =C9/$H$3 | E9: =IF($B$21>0,B9/$B$21,0) | F9: =D9*E9 | G9: =G8+E9
A10: 6 | B10: 130579 | C10: 4950 | D10: =C10/$H$3 | E10: =IF($B$21>0,B10/$B$21,0) | F10: =D10*E10 | G10: =G9+E10
A11: 7 | B11: 141136 | C11: 1980 | D11: =C11/$H$3 | E11: =IF($B$21>0,B11/$B$21,0) | F11: =D11*E11 | G11: =G10+E11
A12: 8 | B12: 141136 | C12: 1980 | D12: =C12/$H$3 | E12: =IF($B$21>0,B12/$B$21,0) | F12: =D12*E12 | G12: =G11+E12
A13: 9 | B13: 141136 | C13: 1980 | D13: =C13/$H$3 | E13: =IF($B$21>0,B13/$B$21,0) | F13: =D13*E13 | G13: =G12+E13
A14: 10 | B14: 141136 | C14: 1980 | D14: =C14/$H$3 | E14: =IF($B$21>0,B14/$B$21,0) | F14: =D14*E14 | G14: =G13+E14
A15: 11 | B15: 130579 | C15: 4950 | D15: =C15/$H$3 | E15: =IF($B$21>0,B15/$B$21,0) | F15: =D15*E15 | G15: =G14+E15
A16: 12 | B16: 68314 | C16: 29700 | D16: =C16/$H$3 | E16: =IF($B$21>0,B16/$B$21,0) | F16: =D16*E16 | G16: =G15+E16
A17: 13 | B17: 18698 | C17: 79200 | D17: =C17/$H$3 | E17: =IF($B$21>0,B17/$B$21,0) | F17: =D17*E17 | G17: =G16+E17
A18: 14 | B18: 136 | C18: 267300 | D18: =C18/$H$3 | E18: =IF($B$21>0,B18/$B$21,0) | F18: =D18*E18 | G18: =G17+E18
A19: 16 | B19: 1 | C19: 6138000 | D19: =C19/$H$3 | E19: =IF($B$21>0,B19/$B$21,0) | F19: =D19*E19 | G19: =G18+E19
A21: CHECK_SUMS | B21: =SUM(B7:B19) | C21: payout_raw_sum | D21: =SUM(D7:D19) | E21: =SUM(E7:E19) | F21: =SUM(F7:F19) | G21: =IF($B$3>0,F21/$B$3,0) | H21: =IF($D$3="","N/A",ABS(G21-$D$3)<=$F$3)
A22: rtp_drift | B22: =IF($D$3="","",G21-$D$3)
A23: prob_sum_check | B23: =ABS(E21-1)<=1E-9
A24: max_win_value | B24: =MAX(D7:D19)
A25: max_win_probability | B25: =SUMIFS(E7:E19,D7:D19,B24)
A26: outcome_rows | B26: =ROWS(A7:A19)
A27: unique_multipliers | B27: =SUMPRODUCT(1/COUNTIF(D7:D19,D7:D19))
A28: max_exposure_with_max_bet | B28: =B24*500.0

Sheet buy100_high_16
A1: buy100_high_16 Lookup Detail
A2: Derived from lookup rows
A3: Cost | B3: 99 | C3: Target RTP | D3: 0.9605 | E3: RTP Tol | F3: 0.01 | G3: Payout Scale | H3: 100
A5: Rows
A6: sim_id | B6: weight | C6: payout_raw | D6: payout_scaled | E6: probability | F6: weighted_payout | G6: cumulative_probability
A7: 3 | B7: 31 | C7: 257400 | D7: =C7/$H$3 | E7: =IF($B$22>0,B7/$B$22,0) | F7: =D7*E7 | G7: =E7
A8: 4 | B8: 8163 | C8: 89100 | D8: =C8/$H$3 | E8: =IF($B$22>0,B8/$B$22,0) | F8: =D8*E8 | G8: =G7+E8
A9: 5 | B9: 42226 | C9: 39600 | D9: =C9/$H$3 | E9: =IF($B$22>0,B9/$B$22,0) | F9: =D9*E9 | G9: =G8+E9
A10: 6 | B10: 81484 | C10: 19800 | D10: =C10/$H$3 | E10: =IF($B$22>0,B10/$B$22,0) | F10: =D10*E10 | G10: =G9+E10
A11: 7 | B11: 147239 | C11: 1980 | D11: =C11/$H$3 | E11: =IF($B$22>0,B11/$B$22,0) | F11: =D11*E11 | G11: =G10+E11
A12: 8 | B12: 147238 | C12: 1980 | D12: =C12/$H$3 | E12: =IF($B$22>0,B12/$B$22,0) | F12: =D12*E12 | G12: =G11+E12
A13: 9 | B13: 147238 | C13: 1980 | D13: =C13/$H$3 | E13: =IF($B$22>0,B13/$B$22,0) | F13: =D13*E13 | G13: =G12+E13
A14: 10 | B14: 147238 | C14: 1980 | D14: =C14/$H$3 | E14: =IF($B$22>0,B14/$B$22,0) | F14: =D14*E14 | G14: =G13+E14
A15: 11 | B15: 147238 | C15: 1980 | D15: =C15/$H$3 | E15: =IF($B$22>0,B15/$B$22,0) | F15: =D15*E15 | G15: =G14+E15
A16: 12 | B16: 81484 | C16: 19800 | D16: =C16/$H$3 | E16: =IF($B$22>0,B16/$B$22,0) | F16: =D16*E16 | G16: =G15+E16
A17: 13 | B17: 42226 | C17: 39600 | D17: =C17/$H$3 | E17: =IF($B$22>0,B17/$B$22,0) | F17: =D17*E17 | G17: =G16+E17
A18: 14 | B18: 8163 | C18: 89100 | D18: =C18/$H$3 | E18: =IF($B$22>0,B18/$B$22,0) | F18: =D18*E18 | G18: =G17+E18
A19: 15 | B19: 31 | C19: 257400 | D19: =C19/$H$3 | E19: =IF($B$22>0,B19/$B$22,0) | F19: =D19*E19 | G19: =G18+E19
A20: 17 | B20: 1 | C20: 9900000 | D20: =C20/$H$3 | E20: =IF($B$22>0,B20/$B$22,0) | F20: =D20*E20 | G20: =G19+E20
A22: CHECK_SUMS | B22: =SUM(B7:B20) | C22: payout_raw_sum | D22: =SUM(D7:D20) | E22: =SUM(E7:E20) | F22: =SUM(F7:F20) | G22: =IF($B$3>0,F22/$B$3,0) | H22: =IF($D$3="","N/A",ABS(G22-$D$3)<=$F$3)
A23: rtp_drift | B23: =IF($D$3="","",G22-$D$3)
A24: prob_sum_check | B24: =ABS(E22-1)<=1E-9
A25: max_win_value | B25: =MAX(D7:D20)
A26: max_win_probability | B26: =SUMIFS(E7:E20,D7:D20,B25)
A27: outcome_rows | B27: =ROWS(A7:A20)
A28: unique_multipliers | B28: =SUMPRODUCT(1/COUNTIF(D7:D20,D7:D20))
A29: max_exposure_with_max_bet | B29: =B25*500.0

Sheet buy100_high_8
A1: buy100_high_8 Lookup Detail
A2: Derived from lookup rows
A3: Cost | B3: 99 | C3: Target RTP | D3: 0.9605 | E3: RTP Tol | F3: 0.01 | G3: Payout Scale | H3: 100
A5: Rows
A6: sim_id | B6: weight | C6: payout_raw | D6: payout_scaled | E6: probability | F6: weighted_payout | G6: cumulative_probability
A7: 1 | B7: 3 | C7: 287100 | D7: =C7/$H$3 | E7: =IF($B$17>0,B7/$B$17,0) | F7: =D7*E7 | G7: =E7
A8: 2 | B8: 49565 | C8: 39600 | D8: =C8/$H$3 | E8: =IF($B$17>0,B8/$B$17,0) | F8: =D8*E8 | G8: =G7+E8
A9: 3 | B9: 131430 | C9: 14850 | D9: =C9/$H$3 | E9: =IF($B$17>0,B9/$B$17,0) | F9: =D9*E9 | G9: =G8+E9
A10: 4 | B10: 209886 | C10: 2970 | D10: =C10/$H$3 | E10: =IF($B$17>0,B10/$B$17,0) | F10: =D10*E10 | G10: =G9+E10
A11: 5 | B11: 218234 | C11: 1980 | D11: =C11/$H$3 | E11: =IF($B$17>0,B11/$B$17,0) | F11: =D11*E11 | G11: =G10+E11
A12: 6 | B12: 209886 | C12: 2970 | D12: =C12/$H$3 | E12: =IF($B$17>0,B12/$B$17,0) | F12: =D12*E12 | G12: =G11+E12
A13: 7 | B13: 131430 | C13: 14850 | D13: =C13/$H$3 | E13: =IF($B$17>0,B13/$B$17,0) | F13: =D13*E13 | G13: =G12+E13
A14: 8 | B14: 49565 | C14: 39600 | D14: =C14/$H$3 | E14: =IF($B$17>0,B14/$B$17,0) | F14: =D14*E14 | G14: =G13+E14
A15: 9 | B15: 1 | C15: 287100 | D15: =C15/$H$3 | E15: =IF($B$17>0,B15/$B$17,0) | F15: =D15*E15 | G15: =G14+E15
A17: CHECK_SUMS | B17: =SUM(B7:B15) | C17: payout_raw_sum | D17: =SUM(D7:D15) | E17: =SUM(E7:E15) | F17: =SUM(F7:F15) | G17: =IF($B$3>0,F17/$B$3,0) | H17: =IF($D$3="","N/A",ABS(G17-$D$3)<=$F$3)
A18: rtp_drift | B18: =IF($D$3="","",G17-$D$3)
A19: prob_sum_check | B19: =ABS(E17-1)<=1E-9
A20: max_win_value | B20: =MAX(D7:D15)
A21: max_win_probability | B21: =SUMIFS(E7:E15,D7:D15,B20)
A22: outcome_rows | B22: =ROWS(A7:A15)
A23: unique_multipliers | B23: =SUMPRODUCT(1/COUNTIF(D7:D15,D7:D15))
A24: max_exposure_with_max_bet | B24: =B20*500.0

Sheet buy100_high_9
A1: buy100_high_9 Lookup Detail
A2: Derived from lookup rows
A3: Cost | B3: 99 | C3: Target RTP | D3: 0.9605 | E3: RTP Tol | F3: 0.01 | G3: Payout Scale | H3: 100
A5: Rows
A6: sim_id | B6: weight | C6: payout_raw | D6: payout_scaled | E6: probability | F6: weighted_payout | G6: cumulative_probability
A7: 2 | B7: 17622 | C7: 69300 | D7: =C7/$H$3 | E7: =IF($B$17>0,B7/$B$17,0) | F7: =D7*E7 | G7: =E7
A8: 3 | B8: 105820 | C8: 19800 | D8: =C8/$H$3 | E8: =IF($B$17>0,B8/$B$17,0) | F8: =D8*E8 | G8: =G7+E8
A9: 4 | B9: 174802 | C9: 5940 | D9: =C9/$H$3 | E9: =IF($B$17>0,B9/$B$17,0) | F9: =D9*E9 | G9: =G8+E9
A10: 5 | B10: 201756 | C10: 1980 | D10: =C10/$H$3 | E10: =IF($B$17>0,B10/$B$17,0) | F10: =D10*E10 | G10: =G9+E10
A11: 6 | B11: 201756 | C11: 1980 | D11: =C11/$H$3 | E11: =IF($B$17>0,B11/$B$17,0) | F11: =D11*E11 | G11: =G10+E11
A12: 7 | B12: 174802 | C12: 5940 | D12: =C12/$H$3 | E12: =IF($B$17>0,B12/$B$17,0) | F12: =D12*E12 | G12: =G11+E12
A13: 8 | B13: 105819 | C13: 19800 | D13: =C13/$H$3 | E13: =IF($B$17>0,B13/$B$17,0) | F13: =D13*E13 | G13: =G12+E13
A14: 9 | B14: 17622 | C14: 69300 | D14: =C14/$H$3 | E14: =IF($B$17>0,B14/$B$17,0) | F14: =D14*E14 | G14: =G13+E14
A15: 10 | B15: 1 | C15: 425700 | D15: =C15/$H$3 | E15: =IF($B$17>0,B15/$B$17,0) | F15: =D15*E15 | G15: =G14+E15
A17: CHECK_SUMS | B17: =SUM(B7:B15) | C17: payout_raw_sum | D17: =SUM(D7:D15) | E17: =SUM(E7:E15) | F17: =SUM(F7:F15) | G17: =IF($B$3>0,F17/$B$3,0) | H17: =IF($D$3="","N/A",ABS(G17-$D$3)<=$F$3)
A18: rtp_drift | B18: =IF($D$3="","",G17-$D$3)
A19: prob_sum_check | B19: =ABS(E17-1)<=1E-9
A20: max_win_value | B20: =MAX(D7:D15)
A21: max_win_probability | B21: =SUMIFS(E7:E15,D7:D15,B20)
A22: outcome_rows | B22: =ROWS(A7:A15)
A23: unique_multipliers | B23: =SUMPRODUCT(1/COUNTIF(D7:D15,D7:D15))
A24: max_exposure_with_max_bet | B24: =B20*500.0

Sheet buy100_low_10
A1: buy100_low_10 Lookup Detail
A2: Derived from lookup rows
A3: Cost | B3: 99 | C3: Target RTP | D3: 0.9605 | E3: RTP Tol | F3: 0.01 | G3: Payout Scale | H3: 100
A5: Rows
A6: sim_id | B6: weight | C6: payout_raw | D6: payout_scaled | E6: probability | F6: weighted_payout | G6: cumulative_probability
A7: 1 | B7: 1 | C7: 88110 | D7: =C7/$H$3 | E7: =IF($B$19>0,B7/$B$19,0) | F7: =D7*E7 | G7: =E7
A8: 2 | B8: 6697 | C8: 29700 | D8: =C8/$H$3 | E8: =IF($B$19>0,B8/$B$19,0) | F8: =D8*E8 | G8: =G7+E8
A9: 3 | B9: 77086 | C9: 13860 | D9: =C9/$H$3 | E9: =IF($B$19>0,B9/$B$19,0) | F9: =D9*E9 | G9: =G8+E9
A10: 4 | B10: 121881 | C10: 10890 | D10: =C10/$H$3 | E10: =IF($B$19>0,B10/$B$19,0) | F10: =D10*E10 | G10: =G9+E10
A11: 5 | B11: 141990 | C11: 9900 | D11: =C11/$H$3 | E11: =IF($B$19>0,B11/$B$19,0) | F11: =D11*E11 | G11: =G10+E11
A12: 6 | B12: 304691 | C12: 4950 | D12: =C12/$H$3 | E12: =IF($B$19>0,B12/$B$19,0) | F12: =D12*E12 | G12: =G11+E12
A13: 7 | B13: 141990 | C13: 9900 | D13: =C13/$H$3 | E13: =IF($B$19>0,B13/$B$19,0) | F13: =D13*E13 | G13: =G12+E13
A14: 8 | B14: 121881 | C14: 10890 | D14: =C14/$H$3 | E14: =IF($B$19>0,B14/$B$19,0) | F14: =D14*E14 | G14: =G13+E14
A15: 9 | B15: 77086 | C15: 13860 | D15: =C15/$H$3 | E15: =IF($B$19>0,B15/$B$19,0) | F15: =D15*E15 | G15: =G14+E15
A16: 10 | B16: 6696 | C16: 29700 | D16: =C16/$H$3 | E16: =IF($B$19>0,B16/$B$19,0) | F16: =D16*E16 | G16: =G15+E16
A17: 11 | B17: 1 | C17: 88110 | D17: =C17/$H$3 | E17: =IF($B$19>0,B17/$B$19,0) | F17: =D17*E17 | G17: =G16+E17
A19: CHECK_SUMS | B19: =SUM(B7:B17) | C19: payout_raw_sum | D19: =SUM(D7:D17) | E19: =SUM(E7:E17) | F19: =SUM(F7:F17) | G19: =IF($B$3>0,F19/$B$3,0) | H19: =IF($D$3="","N/A",ABS(G19-$D$3)<=$F$3)
A20: rtp_drift | B20: =IF($D$3="","",G19-$D$3)
A21: prob_sum_check | B21: =ABS(E19-1)<=1E-9
A22: max_win_value | B22: =MAX(D7:D17)
A23: max_win_probability | B23: =SUMIFS(E7:E17,D7:D17,B22)
A24: outcome_rows | B24: =ROWS(A7:A17)
A25: unique_multipliers | B25: =SUMPRODUCT(1/COUNTIF(D7:D17,D7:D17))
A26: max_exposure_with_max_bet | B26: =B22*500.0

Sheet buy100_low_11
A1: buy100_low_11 Lookup Detail
A2: Derived from lookup rows
A3: Cost | B3: 99 | C3: Target RTP | D3: 0.9605 | E3: RTP Tol | F3: 0.01 | G3: Payout Scale | H3: 100
A5: Rows
A6: sim_id | B6: weight | C6: payout_raw | D6: payout_scaled | E6: probability | F6: weighted_payout | G6: cumulative_probability
A7: 2 | B7: 3366 | C7: 29700 | D7: =C7/$H$3 | E7: =IF($B$19>0,B7/$B$19,0) | F7: =D7*E7 | G7: =E7
A8: 3 | B8: 26312 | C8: 18810 | D8: =C8/$H$3 | E8: =IF($B$19>0,B8/$B$19,0) | F8: =D8*E8 | G8: =G7+E8
A9: 4 | B9: 80781 | C9: 12870 | D9: =C9/$H$3 | E9: =IF($B$19>0,B9/$B$19,0) | F9: =D9*E9 | G9: =G8+E9
A10: 5 | B10: 141540 | C10: 9900 | D10: =C10/$H$3 | E10: =IF($B$19>0,B10/$B$19,0) | F10: =D10*E10 | G10: =G9+E10
A11: 6 | B11: 248001 | C11: 6930 | D11: =C11/$H$3 | E11: =IF($B$19>0,B11/$B$19,0) | F11: =D11*E11 | G11: =G10+E11
