Workbook

Sheet Summary
A1: Treasure Dice Full Audit Workbook
A2: Clean workbook for treasure_dice_final
A3: Workbook Scope
A4: Key | B4: Value
A5: Package | B5: math-sdk/games/treasure_dice_final
A6: Modes | B6: 8
A7: Target RTP | B7: 0.96
A8: Tolerance | B8: 0.01
A9: All RTP Pass | B9: TRUE
A10: All Weight Pass | B10: TRUE
A11: All Lookup Pass | B11: TRUE
A12: All MaxWin Pass | B12: TRUE
A13: All Replay Pass | B13: TRUE
A15: Mode Audit Table
A16: Mode | B16: Cost | C16: RTP | D16: Hit Rate | E16: Std Dev | F16: P95 | G16: P99 | H16: Max Win | I16: Pass | J16: Sheet
A17: safe_shore | B17: =LUT_safe_shore!B6 -> 1 | C17: =LUT_safe_shore!B9 -> 0.96 | D17: =LUT_safe_shore!B10 -> 0.8 | E17: =LUT_safe_shore!B15 -> 0.48 | F17: =LUT_safe_shore!B19 -> 1.2 | G17: =LUT_safe_shore!B20 -> 1.2 | H17: =LUT_safe_shore!B17 -> 1.2 | I17: =IF(ABS(C17-0.96)<=0.01,"Pass","Fail") -> Pass | J17: LUT_safe_shore
A18: hidden_bay | B18: =LUT_hidden_bay!B6 -> 1 | C18: =LUT_hidden_bay!B9 -> 0.96 | D18: =LUT_hidden_bay!B10 -> 0.6 | E18: =LUT_hidden_bay!B15 -> 0.78383672 | F18: =LUT_hidden_bay!B19 -> 0 | G18: =LUT_hidden_bay!B20 -> 0 | H18: =LUT_hidden_bay!B17 -> 1.6 | I18: =IF(ABS(C18-0.96)<=0.01,"Pass","Fail") -> Pass | J18: LUT_hidden_bay
A19: coral_reef | B19: =LUT_coral_reef!B6 -> 1 | C19: =LUT_coral_reef!B9 -> 0.96 | D19: =LUT_coral_reef!B10 -> 0.4 | E19: =LUT_coral_reef!B15 -> 1.1757551 | F19: =LUT_coral_reef!B19 -> 2.4 | G19: =LUT_coral_reef!B20 -> 0 | H19: =LUT_coral_reef!B17 -> 2.4 | I19: =IF(ABS(C19-0.96)<=0.01,"Pass","Fail") -> Pass | J19: LUT_coral_reef
A20: storm_route | B20: =LUT_storm_route!B6 -> 1 | C20: =LUT_storm_route!B9 -> 0.96 | D20: =LUT_storm_route!B10 -> 0.25 | E20: =LUT_storm_route!B15 -> 1.6627688 | F20: =LUT_storm_route!B19 -> 3.84 | G20: =LUT_storm_route!B20 -> 0 | H20: =LUT_storm_route!B17 -> 3.84 | I20: =IF(ABS(C20-0.96)<=0.01,"Pass","Fail") -> Pass | J20: LUT_storm_route
A21: skull_island | B21: =LUT_skull_island!B6 -> 1 | C21: =LUT_skull_island!B9 -> 0.96 | D21: =LUT_skull_island!B10 -> 0.1 | E21: =LUT_skull_island!B15 -> 2.88 | F21: =LUT_skull_island!B19 -> 0 | G21: =LUT_skull_island!B20 -> 0 | H21: =LUT_skull_island!B17 -> 9.6 | I21: =IF(ABS(C21-0.96)<=0.01,"Pass","Fail") -> Pass | J21: LUT_skull_island
A22: kraken_waters | B22: =LUT_kraken_waters!B6 -> 1 | C22: =LUT_kraken_waters!B9 -> 0.96 | D22: =LUT_kraken_waters!B10 -> 0.05 | E22: =LUT_kraken_waters!B15 -> 4.184543 | F22: =LUT_kraken_waters!B19 -> 0 | G22: =LUT_kraken_waters!B20 -> 0 | H22: =LUT_kraken_waters!B17 -> 19.2 | I22: =IF(ABS(C22-0.96)<=0.01,"Pass","Fail") -> Pass | J22: LUT_kraken_waters
A23: lost_treasure | B23: =LUT_lost_treasure!B6 -> 1 | C23: =LUT_lost_treasure!B9 -> 0.96 | D23: =LUT_lost_treasure!B10 -> 0.01 | E23: =LUT_lost_treasure!B15 -> 9.5518794 | F23: =LUT_lost_treasure!B19 -> 0 | G23: =LUT_lost_treasure!B20 -> 0 | H23: =LUT_lost_treasure!B17 -> 96 | I23: =IF(ABS(C23-0.96)<=0.01,"Pass","Fail") -> Pass | J23: LUT_lost_treasure
A24: treasure_hunt_buy | B24: =LUT_treasure_hunt_buy!B6 -> 100 | C24: =LUT_treasure_hunt_buy!B9 -> 0.95995 | D24: =LUT_treasure_hunt_buy!B10 -> 0.8134 | E24: =LUT_treasure_hunt_buy!B15 -> 77.022951 | F24: =LUT_treasure_hunt_buy!B19 -> 50 | G24: =LUT_treasure_hunt_buy!B20 -> 180 | H24: =LUT_treasure_hunt_buy!B17 -> 275 | I24: =IF(ABS(C24-0.96)<=0.01,"Pass","Fail") -> Pass | J24: LUT_treasure_hunt_buy

Sheet Index_JSON
A1: Index JSON Audit
A2: index.json
A3: JSON Overview
A4: Key | B4: Value
A5: Type | B5: dict
A6: Top-Level Keys | B6: modes
A8: Serialized JSON
A9: Line | B9: Content
A10: 1 | B10: {
A11: 2 | B11: "modes": [
A12: 3 | B12: {
A13: 4 | B13: "name": "safe_shore",
A14: 5 | B14: "cost": 1.0,
A15: 6 | B15: "events": "books_safe_shore.jsonl.zst",
A16: 7 | B16: "weights": "lookUpTable_safe_shore_0.csv"
A17: 8 | B17: },
A18: 9 | B18: {
A19: 10 | B19: "name": "hidden_bay",
A20: 11 | B20: "cost": 1.0,
A21: 12 | B21: "events": "books_hidden_bay.jsonl.zst",
... A61: 52 | B61: }

Sheet Config_JSON
A1: Config JSON Audit
A2: config.json
A3: JSON Overview
A4: Key | B4: Value
A5: Type | B5: dict
A6: Top-Level Keys | B6: workingName, frontendConfig, gameID, rtp, betDenomination, minDenomination, providerNumber, standardForceFile, bookShelfConfig
A8: Serialized JSON
A9: Line | B9: Content
A10: 1 | B10: {
A11: 2 | B11: "workingName": "treasure_dice",
A12: 3 | B12: "frontendConfig": {
A13: 4 | B13: "file": "fe_config.json",
A14: 5 | B14: "sha256": "ec6e5703b34827ba0974fda522a3c71b39cc18622ddcc5cc9907cbc4ae1e1ded"
A15: 6 | B15: },
A16: 7 | B16: "gameID": "treasure_dice",
A17: 8 | B17: "rtp": 96.0,
A18: 9 | B18: "betDenomination": 1000,
A19: 10 | B19: "minDenomination": 10,
A20: 11 | B20: "providerNumber": 1,
A21: 12 | B21: "standardForceFile": {
... A227: 218 | B227: }

Sheet FE_Config_JSON
A1: Frontend Config JSON Audit
A2: config_fe_treasure_dice.json
A3: JSON Overview
A4: Key | B4: Value
A5: Type | B5: dict
A6: Top-Level Keys | B6: providerName, gameName, gameID, rtp, numReels, numRows, betModes, symbols, paddingReels
A8: Serialized JSON
A9: Line | B9: Content
A10: 1 | B10: {
A11: 2 | B11: "providerName": "sample_provider",
A12: 3 | B12: "gameName": "sample_lines",
A13: 4 | B13: "gameID": "treasure_dice",
A14: 5 | B14: "rtp": 0.96,
A15: 6 | B15: "numReels": 0,
A16: 7 | B16: "numRows": [],
A17: 8 | B17: "betModes": {
A18: 9 | B18: "safe_shore": {
A19: 10 | B19: "cost": 1.0,
A20: 11 | B20: "feature": true,
A21: 12 | B21: "buyBonus": false,
... A77: 68 | B77: }

Sheet Mapping_JSON
A1: Event Mapping JSON Audit
A2: treasure_dice_mapping_spec.json
A3: JSON Overview
A4: Key | B4: Value
A5: Type | B5: dict
A6: Top-Level Keys | B6: spec_id, phase, date, source, determinism_rules, event_families, regular_modes, bonus_mode
A8: Serialized JSON
A9: Line | B9: Content
A10: 1 | B10: {
A11: 2 | B11: "spec_id": "treasure_dice_mapping_v1",
A12: 3 | B12: "phase": 3,
A13: 4 | B13: "date": "2026-06-03",
A14: 5 | B14: "source": "Game_Description.md",
A15: 6 | B15: "determinism_rules": [
A16: 7 | B16: "Settlement is fixed before presentation begins.",
A17: 8 | B17: "Each mode_id + outcome_id maps to exactly one payout and one ordered event sequence.",
A18: 9 | B18: "Replay must use stored mode_id and outcome_id only.",
A19: 10 | B19: "Presentation variants do not alter probability or payout."
A20: 11 | B20: ],
A21: 12 | B21: "event_families": {
... A692: 683 | B692: }

Sheet Validation_JSON
A1: Validation Summary JSON Audit
A2: treasure_dice_phase5_validation_summary.json
A3: JSON Overview
A4: Key | B4: Value
A5: Type | B5: dict
A6: Top-Level Keys | B6: phase, date, package_path, modes, checks, rounding, notes
A8: Serialized JSON
A9: Line | B9: Content
A10: 1 | B10: {
A11: 2 | B11: "phase": 5,
A12: 3 | B12: "date": "2026-06-08",
A13: 4 | B13: "package_path": "math-sdk/games/treasure_dice_final",
A14: 5 | B14: "modes": [
A15: 6 | B15: {
A16: 7 | B16: "mode_id": "safe_shore",
A17: 8 | B17: "cost": 1.0,
A18: 9 | B18: "rounds": 2000,
A19: 10 | B19: "theoretical_rtp": 0.96,
A20: 11 | B20: "simulated_rtp": 0.960000000000025,
A21: 12 | B21: "rtp_drift": 2.4980018054066022e-14,
... A354: 345 | B354: }

Sheet LUT_safe_shore
A1: Lookup Audit - safe_shore
A2: Source: lookUpTable_safe_shore_0.csv
A4: Key | B4: Value
A6: Cost | B6: =1 -> 1
A7: Total Weight | B7: =SUM(B23:B2022) -> 2000
A8: Weighted Mean Payout | B8: =SUM(F23:F2022) -> 0.96
A9: RTP | B9: =B8/B6 -> 0.96
A10: Hit Rate | B10: =SUMIF(D23:D2022,">0",E23:E2022) -> 0.8
A11: Zero Rate | B11: =SUMIF(D23:D2022,0,E23:E2022) -> 0.2
A12: Below-Cost Rate | B12: =SUMIFS(E23:E2022,D23:D2022,">0",D23:D2022,"<"&$B$6) -> 0
A13: Profit Rate | B13: =SUMIFS(E23:E2022,D23:D2022,">"&$B$6) -> 0.8
A14: Variance | B14: =SUMPRODUCT(E23:E2022,(D23:D2022-$B$8)*(D23:D2022-$B$8)) -> 0.2304
A15: Std Dev | B15: =SQRT(B14) -> 0.48
A16: Min Win | B16: =MIN(D23:D2022) -> 0
A17: Max Win | B17: =MAX(D23:D2022) -> 1.2
A18: Median | B18: =INDEX(D23:D2022,COUNTIF(H23:H2022,"<0.5")+1) -> 0
A19: P95 | B19: =INDEX(D23:D2022,COUNTIF(H23:H2022,"<0.95")+1) -> 1.2
A20: P99 | B20: =INDEX(D23:D2022,COUNTIF(H23:H2022,"<0.99")+1) -> 1.2
A22: ID | B22: Weight | C22: Payout Raw | D22: Payout Norm | E22: Probability | F22: Weighted Payout | G22: Cum Weight | H22: Cum Prob | I22: Payout vs Cost
A23: 0 | B23: 1 | C23: 120 | D23: =C23/100 -> 1.2 | E23: =B23/$B$7 -> 0.0005 | F23: =D23*E23 -> 0.0006 | G23: =SUM($B$23:B23) -> 1 | H23: =SUM($E$23:E23) -> 0.0005 | I23: =D23-$B$6 -> 0.2
A24: 1 | B24: 33 | C24: 0 | D24: =C24/100 -> 0 | E24: =B24/$B$7 -> 0.0165 | F24: =D24*E24 -> 0 | G24: =SUM($B$23:B24) -> 34 | H24: =SUM($E$23:E24) -> 0.017 | I24: =D24-$B$6 -> -1
A25: 2 | B25: 1 | C25: 120 | D25: =C25/100 -> 1.2 | E25: =B25/$B$7 -> 0.0005 | F25: =D25*E25 -> 0.0006 | G25: =SUM($B$23:B25) -> 35 | H25: =SUM($E$23:E25) -> 0.0175 | I25: =D25-$B$6 -> 0.2
A26: 3 | B26: 1 | C26: 120 | D26: =C26/100 -> 1.2 | E26: =B26/$B$7 -> 0.0005 | F26: =D26*E26 -> 0.0006 | G26: =SUM($B$23:B26) -> 36 | H26: =SUM($E$23:E26) -> 0.018 | I26: =D26-$B$6 -> 0.2
A27: 4 | B27: 1 | C27: 120 | D27: =C27/100 -> 1.2 | E27: =B27/$B$7 -> 0.0005 | F27: =D27*E27 -> 0.0006 | G27: =SUM($B$23:B27) -> 37 | H27: =SUM($E$23:E27) -> 0.0185 | I27: =D27-$B$6 -> 0.2
A28: 5 | B28: 1 | C28: 120 | D28: =C28/100 -> 1.2 | E28: =B28/$B$7 -> 0.0005 | F28: =D28*E28 -> 0.0006 | G28: =SUM($B$23:B28) -> 38 | H28: =SUM($E$23:E28) -> 0.019 | I28: =D28-$B$6 -> 0.2
A29: 6 | B29: 1 | C29: 120 | D29: =C29/100 -> 1.2 | E29: =B29/$B$7 -> 0.0005 | F29: =D29*E29 -> 0.0006 | G29: =SUM($B$23:B29) -> 39 | H29: =SUM($E$23:E29) -> 0.0195 | I29: =D29-$B$6 -> 0.2
A30: 7 | B30: 1 | C30: 120 | D30: =C30/100 -> 1.2 | E30: =B30/$B$7 -> 0.0005 | F30: =D30*E30 -> 0.0006 | G30: =SUM($B$23:B30) -> 40 | H30: =SUM($E$23:E30) -> 0.02 | I30: =D30-$B$6 -> 0.2
A31: 8 | B31: 1 | C31: 120 | D31: =C31/100 -> 1.2 | E31: =B31/$B$7 -> 0.0005 | F31: =D31*E31 -> 0.0006 | G31: =SUM($B$23:B31) -> 41 | H31: =SUM($E$23:E31) -> 0.0205 | I31: =D31-$B$6 -> 0.2
A32: 9 | B32: 1 | C32: 120 | D32: =C32/100 -> 1.2 | E32: =B32/$B$7 -> 0.0005 | F32: =D32*E32 -> 0.0006 | G32: =SUM($B$23:B32) -> 42 | H32: =SUM($E$23:E32) -> 0.021 | I32: =D32-$B$6 -> 0.2
A33: 10 | B33: 1 | C33: 120 | D33: =C33/100 -> 1.2 | E33: =B33/$B$7 -> 0.0005 | F33: =D33*E33 -> 0.0006 | G33: =SUM($B$23:B33) -> 43 | H33: =SUM($E$23:E33) -> 0.0215 | I33: =D33-$B$6 -> 0.2
A34: 11 | B34: 1 | C34: 120 | D34: =C34/100 -> 1.2 | E34: =B34/$B$7 -> 0.0005 | F34: =D34*E34 -> 0.0006 | G34: =SUM($B$23:B34) -> 44 | H34: =SUM($E$23:E34) -> 0.022 | I34: =D34-$B$6 -> 0.2
... A2022: 1999 | B2022: 1 | C2022: 120 | D2022: =C2022/100 -> 1.2 | E2022: =B2022/$B$7 -> 0.0005 | F2022: =D2022*E2022 -> 0.0006 | G2022: =SUM($B$23:B2022) -> 2000 | H2022: =SUM($E$23:E2022) -> 1 | I2022: =D2022-$B$6 -> 0.2

Sheet LUT_hidden_bay
A1: Lookup Audit - hidden_bay
A2: Source: lookUpTable_hidden_bay_0.csv
A4: Key | B4: Value
A6: Cost | B6: =1 -> 1
A7: Total Weight | B7: =SUM(B23:B1022) -> 1000
A8: Weighted Mean Payout | B8: =SUM(F23:F1022) -> 0.96
A9: RTP | B9: =B8/B6 -> 0.96
A10: Hit Rate | B10: =SUMIF(D23:D1022,">0",E23:E1022) -> 0.6
A11: Zero Rate | B11: =SUMIF(D23:D1022,0,E23:E1022) -> 0.4
A12: Below-Cost Rate | B12: =SUMIFS(E23:E1022,D23:D1022,">0",D23:D1022,"<"&$B$6) -> 0
A13: Profit Rate | B13: =SUMIFS(E23:E1022,D23:D1022,">"&$B$6) -> 0.6
A14: Variance | B14: =SUMPRODUCT(E23:E1022,(D23:D1022-$B$8)*(D23:D1022-$B$8)) -> 0.6144
A15: Std Dev | B15: =SQRT(B14) -> 0.78383672
A16: Min Win | B16: =MIN(D23:D1022) -> 0
A17: Max Win | B17: =MAX(D23:D1022) -> 1.6
A18: Median | B18: =INDEX(D23:D1022,COUNTIF(H23:H1022,"<0.5")+1) -> 1.6
A19: P95 | B19: =INDEX(D23:D1022,COUNTIF(H23:H1022,"<0.95")+1) -> 0
A20: P99 | B20: =INDEX(D23:D1022,COUNTIF(H23:H1022,"<0.99")+1) -> 0
A22: ID | B22: Weight | C22: Payout Raw | D22: Payout Norm | E22: Probability | F22: Weighted Payout | G22: Cum Weight | H22: Cum Prob | I22: Payout vs Cost
A23: 0 | B23: 1 | C23: 160 | D23: =C23/100 -> 1.6 | E23: =B23/$B$7 -> 0.001 | F23: =D23*E23 -> 0.0016 | G23: =SUM($B$23:B23) -> 1 | H23: =SUM($E$23:E23) -> 0.001 | I23: =D23-$B$6 -> 0.6
A24: 1 | B24: 28 | C24: 0 | D24: =C24/100 -> 0 | E24: =B24/$B$7 -> 0.028 | F24: =D24*E24 -> 0 | G24: =SUM($B$23:B24) -> 29 | H24: =SUM($E$23:E24) -> 0.029 | I24: =D24-$B$6 -> -1
A25: 2 | B25: 1 | C25: 160 | D25: =C25/100 -> 1.6 | E25: =B25/$B$7 -> 0.001 | F25: =D25*E25 -> 0.0016 | G25: =SUM($B$23:B25) -> 30 | H25: =SUM($E$23:E25) -> 0.03 | I25: =D25-$B$6 -> 0.6
A26: 3 | B26: 1 | C26: 160 | D26: =C26/100 -> 1.6 | E26: =B26/$B$7 -> 0.001 | F26: =D26*E26 -> 0.0016 | G26: =SUM($B$23:B26) -> 31 | H26: =SUM($E$23:E26) -> 0.031 | I26: =D26-$B$6 -> 0.6
A27: 4 | B27: 1 | C27: 0 | D27: =C27/100 -> 0 | E27: =B27/$B$7 -> 0.001 | F27: =D27*E27 -> 0 | G27: =SUM($B$23:B27) -> 32 | H27: =SUM($E$23:E27) -> 0.032 | I27: =D27-$B$6 -> -1
A28: 5 | B28: 1 | C28: 0 | D28: =C28/100 -> 0 | E28: =B28/$B$7 -> 0.001 | F28: =D28*E28 -> 0 | G28: =SUM($B$23:B28) -> 33 | H28: =SUM($E$23:E28) -> 0.033 | I28: =D28-$B$6 -> -1
A29: 6 | B29: 1 | C29: 160 | D29: =C29/100 -> 1.6 | E29: =B29/$B$7 -> 0.001 | F29: =D29*E29 -> 0.0016 | G29: =SUM($B$23:B29) -> 34 | H29: =SUM($E$23:E29) -> 0.034 | I29: =D29-$B$6 -> 0.6
A30: 7 | B30: 1 | C30: 160 | D30: =C30/100 -> 1.6 | E30: =B30/$B$7 -> 0.001 | F30: =D30*E30 -> 0.0016 | G30: =SUM($B$23:B30) -> 35 | H30: =SUM($E$23:E30) -> 0.035 | I30: =D30-$B$6 -> 0.6
A31: 8 | B31: 1 | C31: 160 | D31: =C31/100 -> 1.6 | E31: =B31/$B$7 -> 0.001 | F31: =D31*E31 -> 0.0016 | G31: =SUM($B$23:B31) -> 36 | H31: =SUM($E$23:E31) -> 0.036 | I31: =D31-$B$6 -> 0.6
A32: 9 | B32: 1 | C32: 160 | D32: =C32/100 -> 1.6 | E32: =B32/$B$7 -> 0.001 | F32: =D32*E32 -> 0.0016 | G32: =SUM($B$23:B32) -> 37 | H32: =SUM($E$23:E32) -> 0.037 | I32: =D32-$B$6 -> 0.6
A33: 10 | B33: 1 | C33: 160 | D33: =C33/100 -> 1.6 | E33: =B33/$B$7 -> 0.001 | F33: =D33*E33 -> 0.0016 | G33: =SUM($B$23:B33) -> 38 | H33: =SUM($E$23:E33) -> 0.038 | I33: =D33-$B$6 -> 0.6
A34: 11 | B34: 1 | C34: 160 | D34: =C34/100 -> 1.6 | E34: =B34/$B$7 -> 0.001 | F34: =D34*E34 -> 0.0016 | G34: =SUM($B$23:B34) -> 39 | H34: =SUM($E$23:E34) -> 0.039 | I34: =D34-$B$6 -> 0.6
... A1022: 999 | B1022: 1 | C1022: 0 | D1022: =C1022/100 -> 0 | E1022: =B1022/$B$7 -> 0.001 | F1022: =D1022*E1022 -> 0 | G1022: =SUM($B$23:B1022) -> 1000 | H1022: =SUM($E$23:E1022) -> 1 | I1022: =D1022-$B$6 -> -1

Sheet LUT_coral_reef
A1: Lookup Audit - coral_reef
A2: Source: lookUpTable_coral_reef_0.csv
A4: Key | B4: Value
A6: Cost | B6: =1 -> 1
A7: Total Weight | B7: =SUM(B23:B1022) -> 1000
A8: Weighted Mean Payout | B8: =SUM(F23:F1022) -> 0.96
A9: RTP | B9: =B8/B6 -> 0.96
A10: Hit Rate | B10: =SUMIF(D23:D1022,">0",E23:E1022) -> 0.4
A11: Zero Rate | B11: =SUMIF(D23:D1022,0,E23:E1022) -> 0.6
A12: Below-Cost Rate | B12: =SUMIFS(E23:E1022,D23:D1022,">0",D23:D1022,"<"&$B$6) -> 0
A13: Profit Rate | B13: =SUMIFS(E23:E1022,D23:D1022,">"&$B$6) -> 0.4
A14: Variance | B14: =SUMPRODUCT(E23:E1022,(D23:D1022-$B$8)*(D23:D1022-$B$8)) -> 1.3824
A15: Std Dev | B15: =SQRT(B14) -> 1.1757551
A16: Min Win | B16: =MIN(D23:D1022) -> 0
A17: Max Win | B17: =MAX(D23:D1022) -> 2.4
A18: Median | B18: =INDEX(D23:D1022,COUNTIF(H23:H1022,"<0.5")+1) -> 2.4
A19: P95 | B19: =INDEX(D23:D1022,COUNTIF(H23:H1022,"<0.95")+1) -> 2.4
A20: P99 | B20: =INDEX(D23:D1022,COUNTIF(H23:H1022,"<0.99")+1) -> 0
A22: ID | B22: Weight | C22: Payout Raw | D22: Payout Norm | E22: Probability | F22: Weighted Payout | G22: Cum Weight | H22: Cum Prob | I22: Payout vs Cost
A23: 0 | B23: 1 | C23: 240 | D23: =C23/100 -> 2.4 | E23: =B23/$B$7 -> 0.001 | F23: =D23*E23 -> 0.0024 | G23: =SUM($B$23:B23) -> 1 | H23: =SUM($E$23:E23) -> 0.001 | I23: =D23-$B$6 -> 1.4
A24: 1 | B24: 15 | C24: 0 | D24: =C24/100 -> 0 | E24: =B24/$B$7 -> 0.015 | F24: =D24*E24 -> 0 | G24: =SUM($B$23:B24) -> 16 | H24: =SUM($E$23:E24) -> 0.016 | I24: =D24-$B$6 -> -1
A25: 2 | B25: 1 | C25: 240 | D25: =C25/100 -> 2.4 | E25: =B25/$B$7 -> 0.001 | F25: =D25*E25 -> 0.0024 | G25: =SUM($B$23:B25) -> 17 | H25: =SUM($E$23:E25) -> 0.017 | I25: =D25-$B$6 -> 1.4
A26: 3 | B26: 1 | C26: 240 | D26: =C26/100 -> 2.4 | E26: =B26/$B$7 -> 0.001 | F26: =D26*E26 -> 0.0024 | G26: =SUM($B$23:B26) -> 18 | H26: =SUM($E$23:E26) -> 0.018 | I26: =D26-$B$6 -> 1.4
A27: 4 | B27: 1 | C27: 0 | D27: =C27/100 -> 0 | E27: =B27/$B$7 -> 0.001 | F27: =D27*E27 -> 0 | G27: =SUM($B$23:B27) -> 19 | H27: =SUM($E$23:E27) -> 0.019 | I27: =D27-$B$6 -> -1
A28: 5 | B28: 1 | C28: 0 | D28: =C28/100 -> 0 | E28: =B28/$B$7 -> 0.001 | F28: =D28*E28 -> 0 | G28: =SUM($B$23:B28) -> 20 | H28: =SUM($E$23:E28) -> 0.02 | I28: =D28-$B$6 -> -1
A29: 6 | B29: 1 | C29: 240 | D29: =C29/100 -> 2.4 | E29: =B29/$B$7 -> 0.001 | F29: =D29*E29 -> 0.0024 | G29: =SUM($B$23:B29) -> 21 | H29: =SUM($E$23:E29) -> 0.021 | I29: =D29-$B$6 -> 1.4
A30: 7 | B30: 1 | C30: 240 | D30: =C30/100 -> 2.4 | E30: =B30/$B$7 -> 0.001 | F30: =D30*E30 -> 0.0024 | G30: =SUM($B$23:B30) -> 22 | H30: =SUM($E$23:E30) -> 0.022 | I30: =D30-$B$6 -> 1.4
A31: 8 | B31: 1 | C31: 0 | D31: =C31/100 -> 0 | E31: =B31/$B$7 -> 0.001 | F31: =D31*E31 -> 0 | G31: =SUM($B$23:B31) -> 23 | H31: =SUM($E$23:E31) -> 0.023 | I31: =D31-$B$6 -> -1
A32: 9 | B32: 1 | C32: 0 | D32: =C32/100 -> 0 | E32: =B32/$B$7 -> 0.001 | F32: =D32*E32 -> 0 | G32: =SUM($B$23:B32) -> 24 | H32: =SUM($E$23:E32) -> 0.024 | I32: =D32-$B$6 -> -1
A33: 10 | B33: 1 | C33: 0 | D33: =C33/100 -> 0 | E33: =B33/$B$7 -> 0.001 | F33: =D33*E33 -> 0 | G33: =SUM($B$23:B33) -> 25 | H33: =SUM($E$23:E33) -> 0.025 | I33: =D33-$B$6 -> -1
A34: 11 | B34: 1 | C34: 0 | D34: =C34/100 -> 0 | E34: =B34/$B$7 -> 0.001 | F34: =D34*E34 -> 0 | G34: =SUM($B$23:B34) -> 26 | H34: =SUM($E$23:E34) -> 0.026 | I34: =D34-$B$6 -> -1
... A1022: 999 | B1022: 1 | C1022: 0 | D1022: =C1022/100 -> 0 | E1022: =B1022/$B$7 -> 0.001 | F1022: =D1022*E1022 -> 0 | G1022: =SUM($B$23:B1022) -> 1000 | H1022: =SUM($E$23:E1022) -> 1 | I1022: =D1022-$B$6 -> -1

Sheet LUT_storm_route
A1: Lookup Audit - storm_route
A2: Source: lookUpTable_storm_route_0.csv
A4: Key | B4: Value
A6: Cost | B6: =1 -> 1
A7: Total Weight | B7: =SUM(B23:B1022) -> 1000
A8: Weighted Mean Payout | B8: =SUM(F23:F1022) -> 0.96
A9: RTP | B9: =B8/B6 -> 0.96
A10: Hit Rate | B10: =SUMIF(D23:D1022,">0",E23:E1022) -> 0.25
A11: Zero Rate | B11: =SUMIF(D23:D1022,0,E23:E1022) -> 0.75
A12: Below-Cost Rate | B12: =SUMIFS(E23:E1022,D23:D1022,">0",D23:D1022,"<"&$B$6) -> 0
A13: Profit Rate | B13: =SUMIFS(E23:E1022,D23:D1022,">"&$B$6) -> 0.25
A14: Variance | B14: =SUMPRODUCT(E23:E1022,(D23:D1022-$B$8)*(D23:D1022-$B$8)) -> 2.7648
A15: Std Dev | B15: =SQRT(B14) -> 1.6627688
A16: Min Win | B16: =MIN(D23:D1022) -> 0
A17: Max Win | B17: =MAX(D23:D1022) -> 3.84
A18: Median | B18: =INDEX(D23:D1022,COUNTIF(H23:H1022,"<0.5")+1) -> 0
A19: P95 | B19: =INDEX(D23:D1022,COUNTIF(H23:H1022,"<0.95")+1) -> 3.84
A20: P99 | B20: =INDEX(D23:D1022,COUNTIF(H23:H1022,"<0.99")+1) -> 0
A22: ID | B22: Weight | C22: Payout Raw | D22: Payout Norm | E22: Probability | F22: Weighted Payout | G22: Cum Weight | H22: Cum Prob | I22: Payout vs Cost
A23: 0 | B23: 1 | C23: 384 | D23: =C23/100 -> 3.84 | E23: =B23/$B$7 -> 0.001 | F23: =D23*E23 -> 0.00384 | G23: =SUM($B$23:B23) -> 1 | H23: =SUM($E$23:E23) -> 0.001 | I23: =D23-$B$6 -> 2.84
A24: 1 | B24: 23 | C24: 0 | D24: =C24/100 -> 0 | E24: =B24/$B$7 -> 0.023 | F24: =D24*E24 -> 0 | G24: =SUM($B$23:B24) -> 24 | H24: =SUM($E$23:E24) -> 0.024 | I24: =D24-$B$6 -> -1
A25: 2 | B25: 1 | C25: 384 | D25: =C25/100 -> 3.84 | E25: =B25/$B$7 -> 0.001 | F25: =D25*E25 -> 0.00384 | G25: =SUM($B$23:B25) -> 25 | H25: =SUM($E$23:E25) -> 0.025 | I25: =D25-$B$6 -> 2.84
A26: 3 | B26: 1 | C26: 384 | D26: =C26/100 -> 3.84 | E26: =B26/$B$7 -> 0.001 | F26: =D26*E26 -> 0.00384 | G26: =SUM($B$23:B26) -> 26 | H26: =SUM($E$23:E26) -> 0.026 | I26: =D26-$B$6 -> 2.84
A27: 4 | B27: 1 | C27: 0 | D27: =C27/100 -> 0 | E27: =B27/$B$7 -> 0.001 | F27: =D27*E27 -> 0 | G27: =SUM($B$23:B27) -> 27 | H27: =SUM($E$23:E27) -> 0.027 | I27: =D27-$B$6 -> -1
A28: 5 | B28: 1 | C28: 0 | D28: =C28/100 -> 0 | E28: =B28/$B$7 -> 0.001 | F28: =D28*E28 -> 0 | G28: =SUM($B$23:B28) -> 28 | H28: =SUM($E$23:E28) -> 0.028 | I28: =D28-$B$6 -> -1
A29: 6 | B29: 1 | C29: 0 | D29: =C29/100 -> 0 | E29: =B29/$B$7 -> 0.001 | F29: =D29*E29 -> 0 | G29: =SUM($B$23:B29) -> 29 | H29: =SUM($E$23:E29) -> 0.029 | I29: =D29-$B$6 -> -1
A30: 7 | B30: 1 | C30: 384 | D30: =C30/100 -> 3.84 | E30: =B30/$B$7 -> 0.001 | F30: =D30*E30 -> 0.00384 | G30: =SUM($B$23:B30) -> 30 | H30: =SUM($E$23:E30) -> 0.03 | I30: =D30-$B$6 -> 2.84
A31: 8 | B31: 1 | C31: 0 | D31: =C31/100 -> 0 | E31: =B31/$B$7 -> 0.001 | F31: =D31*E31 -> 0 | G31: =SUM($B$23:B31) -> 31 | H31: =SUM($E$23:E31) -> 0.031 | I31: =D31-$B$6 -> -1
A32: 9 | B32: 1 | C32: 0 | D32: =C32/100 -> 0 | E32: =B32/$B$7 -> 0.001 | F32: =D32*E32 -> 0 | G32: =SUM($B$23:B32) -> 32 | H32: =SUM($E$23:E32) -> 0.032 | I32: =D32-$B$6 -> -1
A33: 10 | B33: 1 | C33: 0 | D33: =C33/100 -> 0 | E33: =B33/$B$7 -> 0.001 | F33: =D33*E33 -> 0 | G33: =SUM($B$23:B33) -> 33 | H33: =SUM($E$23:E33) -> 0.033 | I33: =D33-$B$6 -> -1
A34: 11 | B34: 1 | C34: 0 | D34: =C34/100 -> 0 | E34: =B34/$B$7 -> 0.001 | F34: =D34*E34 -> 0 | G34: =SUM($B$23:B34) -> 34 | H34: =SUM($E$23:E34) -> 0.034 | I34: =D34-$B$6 -> -1
... A1022: 999 | B1022: 1 | C1022: 0 | D1022: =C1022/100 -> 0 | E1022: =B1022/$B$7 -> 0.001 | F1022: =D1022*E1022 -> 0 | G1022: =SUM($B$23:B1022) -> 1000 | H1022: =SUM($E$23:E1022) -> 1 | I1022: =D1022-$B$6 -> -1

Sheet LUT_skull_island
A1: Lookup Audit - skull_island
A2: Source: lookUpTable_skull_island_0.csv
A4: Key | B4: Value
A6: Cost | B6: =1 -> 1
A7: Total Weight | B7: =SUM(B23:B1022) -> 1000
A8: Weighted Mean Payout | B8: =SUM(F23:F1022) -> 0.96
A9: RTP | B9: =B8/B6 -> 0.96
A10: Hit Rate | B10: =SUMIF(D23:D1022,">0",E23:E1022) -> 0.1
A11: Zero Rate | B11: =SUMIF(D23:D1022,0,E23:E1022) -> 0.9
A12: Below-Cost Rate | B12: =SUMIFS(E23:E1022,D23:D1022,">0",D23:D1022,"<"&$B$6) -> 0
A13: Profit Rate | B13: =SUMIFS(E23:E1022,D23:D1022,">"&$B$6) -> 0.1
A14: Variance | B14: =SUMPRODUCT(E23:E1022,(D23:D1022-$B$8)*(D23:D1022-$B$8)) -> 8.2944
A15: Std Dev | B15: =SQRT(B14) -> 2.88
A16: Min Win | B16: =MIN(D23:D1022) -> 0
A17: Max Win | B17: =MAX(D23:D1022) -> 9.6
A18: Median | B18: =INDEX(D23:D1022,COUNTIF(H23:H1022,"<0.5")+1) -> 0
A19: P95 | B19: =INDEX(D23:D1022,COUNTIF(H23:H1022,"<0.95")+1) -> 0
A20: P99 | B20: =INDEX(D23:D1022,COUNTIF(H23:H1022,"<0.99")+1) -> 0
A22: ID | B22: Weight | C22: Payout Raw | D22: Payout Norm | E22: Probability | F22: Weighted Payout | G22: Cum Weight | H22: Cum Prob | I22: Payout vs Cost
A23: 0 | B23: 11 | C23: 0 | D23: =C23/100 -> 0 | E23: =B23/$B$7 -> 0.011 | F23: =D23*E23 -> 0 | G23: =SUM($B$23:B23) -> 11 | H23: =SUM($E$23:E23) -> 0.011 | I23: =D23-$B$6 -> -1
A24: 1 | B24: 1 | C24: 0 | D24: =C24/100 -> 0 | E24: =B24/$B$7 -> 0.001 | F24: =D24*E24 -> 0 | G24: =SUM($B$23:B24) -> 12 | H24: =SUM($E$23:E24) -> 0.012 | I24: =D24-$B$6 -> -1
A25: 2 | B25: 1 | C25: 0 | D25: =C25/100 -> 0 | E25: =B25/$B$7 -> 0.001 | F25: =D25*E25 -> 0 | G25: =SUM($B$23:B25) -> 13 | H25: =SUM($E$23:E25) -> 0.013 | I25: =D25-$B$6 -> -1
A26: 3 | B26: 1 | C26: 0 | D26: =C26/100 -> 0 | E26: =B26/$B$7 -> 0.001 | F26: =D26*E26 -> 0 | G26: =SUM($B$23:B26) -> 14 | H26: =SUM($E$23:E26) -> 0.014 | I26: =D26-$B$6 -> -1
A27: 4 | B27: 1 | C27: 0 | D27: =C27/100 -> 0 | E27: =B27/$B$7 -> 0.001 | F27: =D27*E27 -> 0 | G27: =SUM($B$23:B27) -> 15 | H27: =SUM($E$23:E27) -> 0.015 | I27: =D27-$B$6 -> -1
A28: 5 | B28: 1 | C28: 0 | D28: =C28/100 -> 0 | E28: =B28/$B$7 -> 0.001 | F28: =D28*E28 -> 0 | G28: =SUM($B$23:B28) -> 16 | H28: =SUM($E$23:E28) -> 0.016 | I28: =D28-$B$6 -> -1
A29: 6 | B29: 1 | C29: 0 | D29: =C29/100 -> 0 | E29: =B29/$B$7 -> 0.001 | F29: =D29*E29 -> 0 | G29: =SUM($B$23:B29) -> 17 | H29: =SUM($E$23:E29) -> 0.017 | I29: =D29-$B$6 -> -1
A30: 7 | B30: 1 | C30: 0 | D30: =C30/100 -> 0 | E30: =B30/$B$7 -> 0.001 | F30: =D30*E30 -> 0 | G30: =SUM($B$23:B30) -> 18 | H30: =SUM($E$23:E30) -> 0.018 | I30: =D30-$B$6 -> -1
A31: 8 | B31: 1 | C31: 0 | D31: =C31/100 -> 0 | E31: =B31/$B$7 -> 0.001 | F31: =D31*E31 -> 0 | G31: =SUM($B$23:B31) -> 19 | H31: =SUM($E$23:E31) -> 0.019 | I31: =D31-$B$6 -> -1
A32: 9 | B32: 1 | C32: 0 | D32: =C32/100 -> 0 | E32: =B32/$B$7 -> 0.001 | F32: =D32*E32 -> 0 | G32: =SUM($B$23:B32) -> 20 | H32: =SUM($E$23:E32) -> 0.02 | I32: =D32-$B$6 -> -1
A33: 10 | B33: 1 | C33: 0 | D33: =C33/100 -> 0 | E33: =B33/$B$7 -> 0.001 | F33: =D33*E33 -> 0 | G33: =SUM($B$23:B33) -> 21 | H33: =SUM($E$23:E33) -> 0.021 | I33: =D33-$B$6 -> -1
A34: 11 | B34: 1 | C34: 0 | D34: =C34/100 -> 0 | E34: =B34/$B$7 -> 0.001 | F34: =D34*E34 -> 0 | G34: =SUM($B$23:B34) -> 22 | H34: =SUM($E$23:E34) -> 0.022 | I34: =D34-$B$6 -> -1
... A1022: 999 | B1022: 1 | C1022: 0 | D1022: =C1022/100 -> 0 | E1022: =B1022/$B$7 -> 0.001 | F1022: =D1022*E1022 -> 0 | G1022: =SUM($B$23:B1022) -> 1000 | H1022: =SUM($E$23:E1022) -> 1 | I1022: =D1022-$B$6 -> -1

Sheet LUT_kraken_waters
A1: Lookup Audit - kraken_waters
A2: Source: lookUpTable_kraken_waters_0.csv
A4: Key | B4: Value
A6: Cost | B6: =1 -> 1
A7: Total Weight | B7: =SUM(B23:B1022) -> 1000
A8: Weighted Mean Payout | B8: =SUM(F23:F1022) -> 0.96
A9: RTP | B9: =B8/B6 -> 0.96
A10: Hit Rate | B10: =SUMIF(D23:D1022,">0",E23:E1022) -> 0.05
A11: Zero Rate | B11: =SUMIF(D23:D1022,0,E23:E1022) -> 0.95
A12: Below-Cost Rate | B12: =SUMIFS(E23:E1022,D23:D1022,">0",D23:D1022,"<"&$B$6) -> 0
A13: Profit Rate | B13: =SUMIFS(E23:E1022,D23:D1022,">"&$B$6) -> 0.05
A14: Variance | B14: =SUMPRODUCT(E23:E1022,(D23:D1022-$B$8)*(D23:D1022-$B$8)) -> 17.5104
A15: Std Dev | B15: =SQRT(B14) -> 4.184543
A16: Min Win | B16: =MIN(D23:D1022) -> 0
A17: Max Win | B17: =MAX(D23:D1022) -> 19.2
A18: Median | B18: =INDEX(D23:D1022,COUNTIF(H23:H1022,"<0.5")+1) -> 0
A19: P95 | B19: =INDEX(D23:D1022,COUNTIF(H23:H1022,"<0.95")+1) -> 0
A20: P99 | B20: =INDEX(D23:D1022,COUNTIF(H23:H1022,"<0.99")+1) -> 0
A22: ID | B22: Weight | C22: Payout Raw | D22: Payout Norm | E22: Probability | F22: Weighted Payout | G22: Cum Weight | H22: Cum Prob | I22: Payout vs Cost
A23: 0 | B23: 9 | C23: 0 | D23: =C23/100 -> 0 | E23: =B23/$B$7 -> 0.009 | F23: =D23*E23 -> 0 | G23: =SUM($B$23:B23) -> 9 | H23: =SUM($E$23:E23) -> 0.009 | I23: =D23-$B$6 -> -1
A24: 1 | B24: 1 | C24: 0 | D24: =C24/100 -> 0 | E24: =B24/$B$7 -> 0.001 | F24: =D24*E24 -> 0 | G24: =SUM($B$23:B24) -> 10 | H24: =SUM($E$23:E24) -> 0.01 | I24: =D24-$B$6 -> -1
A25: 2 | B25: 1 | C25: 0 | D25: =C25/100 -> 0 | E25: =B25/$B$7 -> 0.001 | F25: =D25*E25 -> 0 | G25: =SUM($B$23:B25) -> 11 | H25: =SUM($E$23:E25) -> 0.011 | I25: =D25-$B$6 -> -1
A26: 3 | B26: 1 | C26: 0 | D26: =C26/100 -> 0 | E26: =B26/$B$7 -> 0.001 | F26: =D26*E26 -> 0 | G26: =SUM($B$23:B26) -> 12 | H26: =SUM($E$23:E26) -> 0.012 | I26: =D26-$B$6 -> -1
A27: 4 | B27: 1 | C27: 0 | D27: =C27/100 -> 0 | E27: =B27/$B$7 -> 0.001 | F27: =D27*E27 -> 0 | G27: =SUM($B$23:B27) -> 13 | H27: =SUM($E$23:E27) -> 0.013 | I27: =D27-$B$6 -> -1
A28: 5 | B28: 1 | C28: 0 | D28: =C28/100 -> 0 | E28: =B28/$B$7 -> 0.001 | F28: =D28*E28 -> 0 | G28: =SUM($B$23:B28) -> 14 | H28: =SUM($E$23:E28) -> 0.014 | I28: =D28-$B$6 -> -1
A29: 6 | B29: 1 | C29: 0 | D29: =C29/100 -> 0 | E29: =B29/$B$7 -> 0.001 | F29: =D29*E29 -> 0 | G29: =SUM($B$23:B29) -> 15 | H29: =SUM($E$23:E29) -> 0.015 | I29: =D29-$B$6 -> -1
A30: 7 | B30: 1 | C30: 0 | D30: =C30/100 -> 0 | E30: =B30/$B$7 -> 0.001 | F30: =D30*E30 -> 0 | G30: =SUM($B$23:B30) -> 16 | H30: =SUM($E$23:E30) -> 0.016 | I30: =D30-$B$6 -> -1
A31: 8 | B31: 1 | C31: 0 | D31: =C31/100 -> 0 | E31: =B31/$B$7 -> 0.001 | F31: =D31*E31 -> 0 | G31: =SUM($B$23:B31) -> 17 | H31: =SUM($E$23:E31) -> 0.017 | I31: =D31-$B$6 -> -1
A32: 9 | B32: 1 | C32: 0 | D32: =C32/100 -> 0 | E32: =B32/$B$7 -> 0.001 | F32: =D32*E32 -> 0 | G32: =SUM($B$23:B32) -> 18 | H32: =SUM($E$23:E32) -> 0.018 | I32: =D32-$B$6 -> -1
A33: 10 | B33: 1 | C33: 0 | D33: =C33/100 -> 0 | E33: =B33/$B$7 -> 0.001 | F33: =D33*E33 -> 0 | G33: =SUM($B$23:B33) -> 19 | H33: =SUM($E$23:E33) -> 0.019 | I33: =D33-$B$6 -> -1
A34: 11 | B34: 1 | C34: 0 | D34: =C34/100 -> 0 | E34: =B34/$B$7 -> 0.001 | F34: =D34*E34 -> 0 | G34: =SUM($B$23:B34) -> 20 | H34: =SUM($E$23:E34) -> 0.02 | I34: =D34-$B$6 -> -1
... A1022: 999 | B1022: 1 | C1022: 0 | D1022: =C1022/100 -> 0 | E1022: =B1022/$B$7 -> 0.001 | F1022: =D1022*E1022 -> 0 | G1022: =SUM($B$23:B1022) -> 1000 | H1022: =SUM($E$23:E1022) -> 1 | I1022: =D1022-$B$6 -> -1

Sheet LUT_lost_treasure
A1: Lookup Audit - lost_treasure
A2: Source: lookUpTable_lost_treasure_0.csv
A4: Key | B4: Value
A6: Cost | B6: =1 -> 1
A7: Total Weight | B7: =SUM(B23:B2022) -> 2000
A8: Weighted Mean Payout | B8: =SUM(F23:F2022) -> 0.96
A9: RTP | B9: =B8/B6 -> 0.96
A10: Hit Rate | B10: =SUMIF(D23:D2022,">0",E23:E2022) -> 0.01
A11: Zero Rate | B11: =SUMIF(D23:D2022,0,E23:E2022) -> 0.99
A12: Below-Cost Rate | B12: =SUMIFS(E23:E2022,D23:D2022,">0",D23:D2022,"<"&$B$6) -> 0
A13: Profit Rate | B13: =SUMIFS(E23:E2022,D23:D2022,">"&$B$6) -> 0.01
A14: Variance | B14: =SUMPRODUCT(E23:E2022,(D23:D2022-$B$8)*(D23:D2022-$B$8)) -> 91.2384
A15: Std Dev | B15: =SQRT(B14) -> 9.5518794
A16: Min Win | B16: =MIN(D23:D2022) -> 0
A17: Max Win | B17: =MAX(D23:D2022) -> 96
A18: Median | B18: =INDEX(D23:D2022,COUNTIF(H23:H2022,"<0.5")+1) -> 0
A19: P95 | B19: =INDEX(D23:D2022,COUNTIF(H23:H2022,"<0.95")+1) -> 0
A20: P99 | B20: =INDEX(D23:D2022,COUNTIF(H23:H2022,"<0.99")+1) -> 0
A22: ID | B22: Weight | C22: Payout Raw | D22: Payout Norm | E22: Probability | F22: Weighted Payout | G22: Cum Weight | H22: Cum Prob | I22: Payout vs Cost
A23: 0 | B23: 0 | C23: 0 | D23: =C23/100 -> 0 | E23: =B23/$B$7 -> 0 | F23: =D23*E23 -> 0 | G23: =SUM($B$23:B23) -> 0 | H23: =SUM($E$23:E23) -> 0 | I23: =D23-$B$6 -> -1
A24: 1 | B24: 0 | C24: 0 | D24: =C24/100 -> 0 | E24: =B24/$B$7 -> 0 | F24: =D24*E24 -> 0 | G24: =SUM($B$23:B24) -> 0 | H24: =SUM($E$23:E24) -> 0 | I24: =D24-$B$6 -> -1
A25: 2 | B25: 1 | C25: 0 | D25: =C25/100 -> 0 | E25: =B25/$B$7 -> 0.0005 | F25: =D25*E25 -> 0 | G25: =SUM($B$23:B25) -> 1 | H25: =SUM($E$23:E25) -> 0.0005 | I25: =D25-$B$6 -> -1
A26: 3 | B26: 1 | C26: 0 | D26: =C26/100 -> 0 | E26: =B26/$B$7 -> 0.0005 | F26: =D26*E26 -> 0 | G26: =SUM($B$23:B26) -> 2 | H26: =SUM($E$23:E26) -> 0.001 | I26: =D26-$B$6 -> -1
A27: 4 | B27: 1 | C27: 0 | D27: =C27/100 -> 0 | E27: =B27/$B$7 -> 0.0005 | F27: =D27*E27 -> 0 | G27: =SUM($B$23:B27) -> 3 | H27: =SUM($E$23:E27) -> 0.0015 | I27: =D27-$B$6 -> -1
A28: 5 | B28: 1 | C28: 0 | D28: =C28/100 -> 0 | E28: =B28/$B$7 -> 0.0005 | F28: =D28*E28 -> 0 | G28: =SUM($B$23:B28) -> 4 | H28: =SUM($E$23:E28) -> 0.002 | I28: =D28-$B$6 -> -1
A29: 6 | B29: 1 | C29: 0 | D29: =C29/100 -> 0 | E29: =B29/$B$7 -> 0.0005 | F29: =D29*E29 -> 0 | G29: =SUM($B$23:B29) -> 5 | H29: =SUM($E$23:E29) -> 0.0025 | I29: =D29-$B$6 -> -1
A30: 7 | B30: 1 | C30: 0 | D30: =C30/100 -> 0 | E30: =B30/$B$7 -> 0.0005 | F30: =D30*E30 -> 0 | G30: =SUM($B$23:B30) -> 6 | H30: =SUM($E$23:E30) -> 0.003 | I30: =D30-$B$6 -> -1
A31: 8 | B31: 1 | C31: 0 | D31: =C31/100 -> 0 | E31: =B31/$B$7 -> 0.0005 | F31: =D31*E31 -> 0 | G31: =SUM($B$23:B31) -> 7 | H31: =SUM($E$23:E31) -> 0.0035 | I31: =D31-$B$6 -> -1
A32: 9 | B32: 1 | C32: 0 | D32: =C32/100 -> 0 | E32: =B32/$B$7 -> 0.0005 | F32: =D32*E32 -> 0 | G32: =SUM($B$23:B32) -> 8 | H32: =SUM($E$23:E32) -> 0.004 | I32: =D32-$B$6 -> -1
A33: 10 | B33: 1 | C33: 0 | D33: =C33/100 -> 0 | E33: =B33/$B$7 -> 0.0005 | F33: =D33*E33 -> 0 | G33: =SUM($B$23:B33) -> 9 | H33: =SUM($E$23:E33) -> 0.0045 | I33: =D33-$B$6 -> -1
A34: 11 | B34: 1 | C34: 0 | D34: =C34/100 -> 0 | E34: =B34/$B$7 -> 0.0005 | F34: =D34*E34 -> 0 | G34: =SUM($B$23:B34) -> 10 | H34: =SUM($E$23:E34) -> 0.005 | I34: =D34-$B$6 -> -1
... A2022: 1999 | B2022: 1 | C2022: 0 | D2022: =C2022/100 -> 0 | E2022: =B2022/$B$7 -> 0.0005 | F2022: =D2022*E2022 -> 0 | G2022: =SUM($B$23:B2022) -> 2000 | H2022: =SUM($E$23:E2022) -> 1 | I2022: =D2022-$B$6 -> -1

Sheet LUT_treasure_hunt_buy
A1: Lookup Audit - treasure_hunt_buy
A2: Source: lookUpTable_treasure_hunt_buy_0.csv
A4: Key | B4: Value
A6: Cost | B6: =100 -> 100
A7: Total Weight | B7: =SUM(B23:B1022) -> 5000
A8: Weighted Mean Payout | B8: =SUM(F23:F1022) -> 95.995
A9: RTP | B9: =B8/B6 -> 0.95995
A10: Hit Rate | B10: =SUMIF(D23:D1022,">0",E23:E1022) -> 0.8134
A11: Zero Rate | B11: =SUMIF(D23:D1022,0,E23:E1022) -> 0.1866
A12: Below-Cost Rate | B12: =SUMIFS(E23:E1022,D23:D1022,">0",D23:D1022,"<"&$B$6) -> 0.447
A13: Profit Rate | B13: =SUMIFS(E23:E1022,D23:D1022,">"&$B$6) -> 0.3664
A14: Variance | B14: =SUMPRODUCT(E23:E1022,(D23:D1022-$B$8)*(D23:D1022-$B$8)) -> 5932.535
A15: Std Dev | B15: =SQRT(B14) -> 77.022951
A16: Min Win | B16: =MIN(D23:D1022) -> 0
A17: Max Win | B17: =MAX(D23:D1022) -> 275
A18: Median | B18: =INDEX(D23:D1022,COUNTIF(H23:H1022,"<0.5")+1) -> 120
A19: P95 | B19: =INDEX(D23:D1022,COUNTIF(H23:H1022,"<0.95")+1) -> 50
A20: P99 | B20: =INDEX(D23:D1022,COUNTIF(H23:H1022,"<0.99")+1) -> 180
A22: ID | B22: Weight | C22: Payout Raw | D22: Payout Norm | E22: Probability | F22: Weighted Payout | G22: Cum Weight | H22: Cum Prob | I22: Payout vs Cost
A23: 0 | B23: 0 | C23: 0 | D23: =C23/100 -> 0 | E23: =B23/$B$7 -> 0 | F23: =D23*E23 -> 0 | G23: =SUM($B$23:B23) -> 0 | H23: =SUM($E$23:E23) -> 0 | I23: =D23-$B$6 -> -100
A24: 1 | B24: 5 | C24: 27500 | D24: =C24/100 -> 275 | E24: =B24/$B$7 -> 0.001 | F24: =D24*E24 -> 0.275 | G24: =SUM($B$23:B24) -> 5 | H24: =SUM($E$23:E24) -> 0.001 | I24: =D24-$B$6 -> 175
A25: 2 | B25: 5 | C25: 5000 | D25: =C25/100 -> 50 | E25: =B25/$B$7 -> 0.001 | F25: =D25*E25 -> 0.05 | G25: =SUM($B$23:B25) -> 10 | H25: =SUM($E$23:E25) -> 0.002 | I25: =D25-$B$6 -> -50
A26: 3 | B26: 5 | C26: 5000 | D26: =C26/100 -> 50 | E26: =B26/$B$7 -> 0.001 | F26: =D26*E26 -> 0.05 | G26: =SUM($B$23:B26) -> 15 | H26: =SUM($E$23:E26) -> 0.003 | I26: =D26-$B$6 -> -50
A27: 4 | B27: 5 | C27: 12000 | D27: =C27/100 -> 120 | E27: =B27/$B$7 -> 0.001 | F27: =D27*E27 -> 0.12 | G27: =SUM($B$23:B27) -> 20 | H27: =SUM($E$23:E27) -> 0.004 | I27: =D27-$B$6 -> 20
A28: 5 | B28: 5 | C28: 12000 | D28: =C28/100 -> 120 | E28: =B28/$B$7 -> 0.001 | F28: =D28*E28 -> 0.12 | G28: =SUM($B$23:B28) -> 25 | H28: =SUM($E$23:E28) -> 0.005 | I28: =D28-$B$6 -> 20
A29: 6 | B29: 5 | C29: 5000 | D29: =C29/100 -> 50 | E29: =B29/$B$7 -> 0.001 | F29: =D29*E29 -> 0.05 | G29: =SUM($B$23:B29) -> 30 | H29: =SUM($E$23:E29) -> 0.006 | I29: =D29-$B$6 -> -50
A30: 7 | B30: 5 | C30: 5000 | D30: =C30/100 -> 50 | E30: =B30/$B$7 -> 0.001 | F30: =D30*E30 -> 0.05 | G30: =SUM($B$23:B30) -> 35 | H30: =SUM($E$23:E30) -> 0.007 | I30: =D30-$B$6 -> -50
A31: 8 | B31: 5 | C31: 9000 | D31: =C31/100 -> 90 | E31: =B31/$B$7 -> 0.001 | F31: =D31*E31 -> 0.09 | G31: =SUM($B$23:B31) -> 40 | H31: =SUM($E$23:E31) -> 0.008 | I31: =D31-$B$6 -> -10
A32: 9 | B32: 5 | C32: 9000 | D32: =C32/100 -> 90 | E32: =B32/$B$7 -> 0.001 | F32: =D32*E32 -> 0.09 | G32: =SUM($B$23:B32) -> 45 | H32: =SUM($E$23:E32) -> 0.009 | I32: =D32-$B$6 -> -10
A33: 10 | B33: 5 | C33: 9000 | D33: =C33/100 -> 90 | E33: =B33/$B$7 -> 0.001 | F33: =D33*E33 -> 0.09 | G33: =SUM($B$23:B33) -> 50 | H33: =SUM($E$23:E33) -> 0.01 | I33: =D33-$B$6 -> -10
A34: 11 | B34: 5 | C34: 9000 | D34: =C34/100 -> 90 | E34: =B34/$B$7 -> 0.001 | F34: =D34*E34 -> 0.09 | G34: =SUM($B$23:B34) -> 55 | H34: =SUM($E$23:E34) -> 0.011 | I34: =D34-$B$6 -> -10
... A1022: 999 | B1022: 5 | C1022: 12000 | D1022: =C1022/100 -> 120 | E1022: =B1022/$B$7 -> 0.001 | F1022: =D1022*E1022 -> 0.12 | G1022: =SUM($B$23:B1022) -> 5000 | H1022: =SUM($E$23:E1022) -> 1 | I1022: =D1022-$B$6 -> 20

Sheet Bonus_Outcome_Audit
A1: Bonus Outcome Audit - treasure_hunt_buy
A2: Unique payout distribution aggregated from the lookup table
A4: Key | B4: Value
A6: Cost | B6: =100 -> 100
A7: Total Weight | B7: =SUM(B23:B28) -> 5000
A8: Weighted Mean Payout | B8: =SUM(D23:D28) -> 95.995
A9: RTP | B9: =B8/B6 -> 0.95995
A10: Hit Rate | B10: =SUMIF(A23:A28,">0",C23:C28) -> 0.8134
A11: Zero Rate | B11: =SUMIF(A23:A28,0,C23:C28) -> 0.1866
A12: Below-Cost Rate | B12: =SUMIFS(C23:C28,A23:A28,">0",A23:A28,"<100") -> 0.447
A13: Profit Rate | B13: =SUMIFS(C23:C28,A23:A28,">100") -> 0.3664
A14: Variance | B14: =SUMPRODUCT(C23:C28,(A23:A28-$B$8)*(A23:A28-$B$8)) -> 5932.535
A15: Std Dev | B15: =SQRT(B14) -> 77.022951
A16: Min Win | B16: =MIN(A23:A28) -> 0
A17: Max Win | B17: =MAX(A23:A28) -> 275
A18: Median | B18: =INDEX(A23:A28,COUNTIF(E23:E28,"<0.5")+1) -> 90
A19: P95 | B19: =INDEX(A23:A28,COUNTIF(E23:E28,"<0.95")+1) -> 275
A20: P99 | B20: =INDEX(A23:A28,COUNTIF(E23:E28,"<0.99")+1) -> 275
A22: Payout Norm | B22: Weight | C22: Probability | D22: Expected Contribution | E22: Cumulative Probability | F22: Zero? | G22: Below Cost? | H22: Profit?
A23: 0 | B23: 933 | C23: =B23/$B$7 -> 0.1866 | D23: =A23*C23 -> 0 | E23: =SUM($C$23:C23) -> 0.1866 | F23: =IF(A23=0,"Yes","No") -> Yes | G23: =IF(AND(A23>0,A23<100),"Yes","No") -> No | H23: =IF(A23>100,"Yes","No") -> No
A24: 50 | B24: 1090 | C24: =B24/$B$7 -> 0.218 | D24: =A24*C24 -> 10.9 | E24: =SUM($C$23:C24) -> 0.4046 | F24: =IF(A24=0,"Yes","No") -> No | G24: =IF(AND(A24>0,A24<100),"Yes","No") -> Yes | H24: =IF(A24>100,"Yes","No") -> No
A25: 90 | B25: 1145 | C25: =B25/$B$7 -> 0.229 | D25: =A25*C25 -> 20.61 | E25: =SUM($C$23:C25) -> 0.6336 | F25: =IF(A25=0,"Yes","No") -> No | G25: =IF(AND(A25>0,A25<100),"Yes","No") -> Yes | H25: =IF(A25>100,"Yes","No") -> No
A26: 120 | B26: 830 | C26: =B26/$B$7 -> 0.166 | D26: =A26*C26 -> 19.92 | E26: =SUM($C$23:C26) -> 0.7996 | F26: =IF(A26=0,"Yes","No") -> No | G26: =IF(AND(A26>0,A26<100),"Yes","No") -> No | H26: =IF(A26>100,"Yes","No") -> Yes
A27: 180 | B27: 555 | C27: =B27/$B$7 -> 0.111 | D27: =A27*C27 -> 19.98 | E27: =SUM($C$23:C27) -> 0.9106 | F27: =IF(A27=0,"Yes","No") -> No | G27: =IF(AND(A27>0,A27<100),"Yes","No") -> No | H27: =IF(A27>100,"Yes","No") -> Yes
A28: 275 | B28: 447 | C28: =B28/$B$7 -> 0.0894 | D28: =A28*C28 -> 24.585 | E28: =SUM($C$23:C28) -> 1 | F28: =IF(A28=0,"Yes","No") -> No | G28: =IF(AND(A28>0,A28<100),"Yes","No") -> No | H28: =IF(A28>100,"Yes","No") -> Yes

Sheet Treasure_Dice_Final_Math_Report
A1: Treasure Dice Final Math Report
A2: Treasure_Dice_Final_Math_Report.md
A3: Audit Metrics
A4: Key | B4: Value
A5: Model Version | B5: treasure_dice_release_math_v1_2026_06_04
A6: Modes | B6: 8
A7: All RTP Pass | B7: TRUE
A9: Computed Final Mode Summary
A10: Mode | B10: Cost | C10: RTP | D10: Hit Rate | E10: Std Dev | F10: P95 | G10: P99 | H10: Max Win | I10: Status
A11: safe_shore | B11: 1 | C11: 0.96 | D11: 0.8 | E11: 0.48 | F11: 1.2 | G11: 1.2 | H11: 1.2 | I11: Pass
A12: hidden_bay | B12: 1 | C12: 0.96 | D12: 0.6 | E12: 0.78383672 | F12: 1.6 | G12: 1.6 | H12: 1.6 | I12: Pass
A13: coral_reef | B13: 1 | C13: 0.96 | D13: 0.4 | E13: 1.1757551 | F13: 2.4 | G13: 2.4 | H13: 2.4 | I13: Pass
A14: storm_route | B14: 1 | C14: 0.96 | D14: 0.25 | E14: 1.6627688 | F14: 3.84 | G14: 3.84 | H14: 3.84 | I14: Pass
A15: skull_island | B15: 1 | C15: 0.96 | D15: 0.1 | E15: 2.88 | F15: 9.6 | G15: 9.6 | H15: 9.6 | I15: Pass
A16: kraken_waters | B16: 1 | C16: 0.96 | D16: 0.05 | E16: 4.184543 | F16: 0 | G16: 19.2 | H16: 19.2 | I16: Pass
A17: lost_treasure | B17: 1 | C17: 0.96 | D17: 0.01 | E17: 9.5518794 | F17: 0 | G17: 0 | H17: 96 | I17: Pass
A18: treasure_hunt_buy | B18: 100 | C18: 0.95995 | D18: 0.8134 | E18: 77.022951 | F18: 275 | G18: 275 | H18: 275 | I18: Pass
A20: Source Text
A21: Line | B21: Content
A22: 1 | B22: # Treasure Dice Final Math Report
A23: 2
A24: 3 | B24: ## Document Status
A25: 4
A26: 5 | B26: - Model version: `treasure_dice_release_math_v1_2026_06_04`
A27: 6 | B27: - Scope: Final production math summary for Treasure Dice release package
A28: 7
A29: 8 | B29: ## Release Scope
A30: 9
A31: 10 | B31: Included in the release:
A32: 11
A33: 12 | B33: - seven regular route modes
A34: 13 | B34: - one Bonus Buy mode: `treasure_hunt_buy`
A35: 14 | B35: - deterministic replay-safe presentation mapping
A36: 15 | B36: - Stake Engine static outcome package for all eight modes
A37: 16
A38: 17 | B38: Excluded from the release:
A39: 18
A40: 19 | B40: - custom route slider
A41: 20 | B41: - organic bonus trigger from regular routes
A42: 21 | B42: - any frontend choice that changes settlement value
...

Sheet Treasure_Dice_Approved_Regular_
A1: Treasure Dice Approved Regular Routes Paytable
A2: Treasure_Dice_Approved_Regular_Routes_Paytable.md
A3: Audit Metrics
A4: Key | B4: Value
A5: Source | B5: Lookup tables + approved route math
A6: Regular Modes | B6: 7
A7: Target RTP | B7: 0.96
A8: Tolerance | B8: 0.01
A10: Computed Route Audit Table
A11: Mode | B11: Win Rate | C11: Multiplier | D11: Payout @ B=1 | E11: Net Profit | F11: RTP | G11: Variance | H11: Std Dev | I11: Max Win
A12: safe_shore | B12: 0.8 | C12: 1.2 | D12: 1.2 | E12: 0.2 | F12: 0.96 | G12: 0.2304 | H12: 0.48 | I12: 1.2
A13: hidden_bay | B13: 0.6 | C13: 1.6 | D13: 1.6 | E13: 0.6 | F13: 0.96 | G13: 0.6144 | H13: 0.78383672 | I13: 1.6
A14: coral_reef | B14: 0.4 | C14: 2.4 | D14: 2.4 | E14: 1.4 | F14: 0.96 | G14: 1.3824 | H14: 1.1757551 | I14: 2.4
A15: storm_route | B15: 0.25 | C15: 3.84 | D15: 3.84 | E15: 2.84 | F15: 0.96 | G15: 2.7648 | H15: 1.6627688 | I15: 3.84
A16: skull_island | B16: 0.1 | C16: 9.6 | D16: 9.6 | E16: 8.6 | F16: 0.96 | G16: 8.2944 | H16: 2.88 | I16: 9.6
A17: kraken_waters | B17: 0.05 | C17: 19.2 | D17: 19.2 | E17: 18.2 | F17: 0.96 | G17: 17.5104 | H17: 4.184543 | I17: 19.2
A18: lost_treasure | B18: 0.01 | C18: 96 | D18: 96 | E18: 95 | F18: 0.96 | G18: 91.2384 | H18: 9.5518794 | I18: 96
A20: Source Text
A21: Line | B21: Content
A22: 1 | B22: # Treasure Dice Approved Regular Routes Paytable
A23: 2
A24: 3 | B24: ## Document Status
A25: 4
A26: 5 | B26: - Date: 2026-06-04
A27: 6 | B27: - Source approval basis: [Treasure_Dice_Phase_1_Math_Report.md](Treasure_Dice_Phase_1_Math_Report.md)
A28: 7
A29: 8 | B29: ## Approved Paytable
A30: 9
A31: 10 | B31: | Mode ID | UI Name | Cost | Win Chance | Total Payout Multiplier | Payout at B=1 | Net Profit at B=1 | RTP | Max Win |
A32: 11 | B32: | --- | --- | --- | --- | --- | --- | --- | --- | --- |
A33: 12 | B33: | safe_shore | Safe Shore | 1 | 80.00% | 1.20x | 1.20 | 0.20 | 96.00% | 1.20x |
A34: 13 | B34: | hidden_bay | Hidden Bay | 1 | 60.00% | 1.60x | 1.60 | 0.60 | 96.00% | 1.60x |
A35: 14 | B35: | coral_reef | Coral Reef | 1 | 40.00% | 2.40x | 2.40 | 1.40 | 96.00% | 2.40x |
A36: 15 | B36: | storm_route | Storm Route | 1 | 25.00% | 3.84x | 3.84 | 2.84 | 96.00% | 3.84x |
A37: 16 | B37: | skull_island | Skull Island | 1 | 10.00% | 9.60x | 9.60 | 8.60 | 96.00% | 9.60x |
A38: 17 | B38: | kraken_waters | Kraken Waters | 1 | 5.00% | 19.20x | 19.20 | 18.20 | 96.00% | 19.20x |
A39: 18 | B39: | lost_treasure | Lost Treasure | 1 | 1.00% | 96.00x | 96.00 | 95.00 | 96.00% | 96.00x |
A40: 19
A41: 20 | B41: ## Approval Note
A42: 21
...

Sheet Treasure_Dice_Approved_Bonus_Bu
A1: Treasure Dice Approved Bonus Buy Paytable
A2: Treasure_Dice_Approved_Bonus_Buy_Paytable.md
A3: Audit Metrics
A4: Key | B4: Value
A5: Mode | B5: treasure_hunt_buy
A6: Cost | B6: 100
A7: Target RTP | B7: 0.96
A8: RTP | B8: 0.95995
A9: Hit Rate | B9: 0.8134
A10: Max Win | B10: 275
A12: Computed Bonus Outcome Distribution
A13: Payout Norm | B13: Weight | C13: Probability | D13: Expected Contribution | E13: Cumulative Probability | F13: Zero? | G13: Below Cost? | H13: Profit?
A14: 0 | B14: 933 | C14: 0.1866 | D14: 0 | E14: 0.1866 | F14: Yes | G14: No | H14: No
A15: 50 | B15: 1090 | C15: 0.218 | D15: 10.9 | E15: 0.4046 | F15: No | G15: Yes | H15: No
A16: 90 | B16: 1145 | C16: 0.229 | D16: 20.61 | E16: 0.6336 | F16: No | G16: Yes | H16: No
A17: 120 | B17: 830 | C17: 0.166 | D17: 19.92 | E17: 0.7996 | F17: No | G17: No | H17: Yes
A18: 180 | B18: 555 | C18: 0.111 | D18: 19.98 | E18: 0.9106 | F18: No | G18: No | H18: Yes
A19: 275 | B19: 447 | C19: 0.0894 | D19: 24.585 | E19: 1 | F19: No | G19: No | H19: Yes
A21: Source Text
A22: Line | B22: Content
A23: 1 | B23: # Treasure Dice Approved Bonus Buy Paytable And Treasure Hunt Description
A24: 2
A25: 3 | B25: ## Document Status
A26: 4
A27: 5 | B27: - Date: 2026-06-06
A28: 6 | B28: - Approved mode: `treasure_hunt_buy`
A29: 7 | B29: - Source approval basis: [Treasure_Dice_Phase_2_Bonus_Report.md](Treasure_Dice_Phase_2_Bonus_Report.md)
A30: 8
A31: 9 | B31: ## Approved Bonus Model
A32: 10
A33: 11 | B33: - Approved candidate: `A`
A34: 12 | B34: - Cost: `100 x` base bet
A35: 13 | B35: - RTP: `96.00%`
A36: 14 | B36: - Max win: `275x` base bet
A37: 15 | B37: - Presentation model: deterministic multi-step treasure hunt using `bonus_step ... bonus_complete`
A38: 16
A39: 17 | B39: ## Approved Paytable
A40: 18
A41: 19 | B41: | Outcome ID | Weight | Probability | Total Payout Multiplier vs B | Total Payout vs Cost | Event Count |
A42: 20 | B42: | --- | --- | --- | --- | --- | --- |
...

Sheet Treasure_Dice_Phase_3_Event_Map
A1: Treasure Dice Phase 3 Event Mapping Report
A2: Treasure_Dice_Phase_3_Event_Mapping_Report.md
A3: Audit Metrics
A4: Key | B4: Value
A5: Mapping File | B5: treasure_dice_phase3_mapping_spec.json
A6: Deterministic Replay | B6: TRUE
A7: Presentation Only | B7: TRUE
A9: Source Text
A10: Line | B10: Content
A11: 1 | B11: # Treasure Dice Phase 3 Event Mapping Report
A12: 2
A13: 3 | B13: ## Document Status
A14: 4
A15: 5 | B15: - Phase: 3 - Deterministic Event Mapping
A16: 6 | B16: - Review purpose: Formal event-mapping and replay-determinism review
A17: 7 | B17: - Source brief: [Game_Description.md](Game_Description.md)
A18: 8 | B18: - Upstream math approvals: [Treasure_Dice_Phase_1_Math_Report.md](Treasure_Dice_Phase_1_Math_Report.md), [Treasure_Dice_Phase_2_Bonus_Report.md](Treasure_Dice_Phase_2_Bonus_Report.md)
A19: 9
A20: 10 | B20: ## Scope
A21: 11
A22: 12 | B22: This report locks deterministic mapping between approved mathematical outcomes and presentation events.
A23: 13
A24: 14 | B24: Included:
A25: 15
A26: 16 | B26: - regular route event-family mapping
A27: 17 | B27: - Bonus Buy candidate A event-family mapping
A28: 18 | B28: - replay determinism constraints
A29: 19 | B29: - presentation-only variant constraints
A30: 20 | B30: - packaging handoff references
A31: 21
A32: 22 | B32: Not included:
A33: 23
A34: 24 | B34: - SDK package generation
A35: 25 | B35: - simulation/reconciliation runs
A36: 26 | B36: - final frontend naming sign-off
A37: 27
A38: 28 | B38: ## Summary Verdict
A39: 29
A40: 30 | B40: Phase 3 mapping is mathematically deterministic and replay-safe under the defined rules:
A41: 31
...

Sheet Treasure_Dice_Phase_5_Simulatio
A1: Treasure Dice Phase 5 Simulation Report
A2: Treasure_Dice_Phase_5_Simulation_Report.md
A3: Audit Metrics
A4: Key | B4: Value
A5: Purpose | B5: Simulation evidence
A6: Modes | B6: 8
A8: Source Text
A9: Line | B9: Content
A10: 1 | B10: # Treasure Dice Phase 5 Simulation Report
A11: 2
A12: 3 | B12: ## Document Status
A13: 4
A14: 5 | B14: - Phase: 5 - Validation and Reporting
A15: 6 | B15: - Source package: [math-sdk/games/treasure_dice](math-sdk/games/treasure_dice)
A16: 7 | B16: - Source summary: [treasure_dice_phase5_validation_summary.json](treasure_dice_phase5_validation_summary.json)
A17: 8
A18: 9 | B18: ## Scope
A19: 10
A20: 11 | B20: This report covers simulated-versus-theoretical RTP reconciliation for all eight published modes.
A21: 12
A22: 13 | B22: ## RTP Reconciliation Summary
A23: 14
A24: 15 | B24: | Mode | Rounds | Theoretical RTP | Simulated RTP | Drift | Drift Sigma |
A25: 16 | B25: | --- | ---: | ---: | ---: | ---: | ---: |
A26: 17 | B26: | safe_shore | 2000 | 0.9600 | 0.9792 | +0.0192 | +1.79 |
A27: 18 | B27: | hidden_bay | 1000 | 0.9600 | 1.0032 | +0.0432 | +1.74 |
A28: 19 | B28: | coral_reef | 1000 | 0.9600 | 0.9936 | +0.0336 | +0.90 |
A29: 20 | B29: | storm_route | 1000 | 0.9600 | 1.0445 | +0.0845 | +1.61 |
A30: 21 | B30: | skull_island | 1000 | 0.9600 | 1.0560 | +0.0960 | +1.05 |
A31: 22 | B31: | kraken_waters | 1000 | 0.9600 | 1.1136 | +0.1536 | +1.16 |
A32: 23 | B32: | lost_treasure | 2000 | 0.9600 | 0.8640 | -0.0960 | -0.45 |
A33: 24 | B33: | treasure_hunt_buy | 1000 | 0.9600 | 0.9341 | -0.0259 | -1.09 |
A34: 25
A35: 26 | B35: ## Interpretation
A36: 27
A37: 28 | B37: - All modes are directionally consistent with theoretical expectations for short package-generation run sizes.
A38: 29 | B38: - No mode exceeds an absolute drift of 2 sigma in this run.
A39: 30 | B39: - High-volatility and low-hit modes (`kraken_waters`, `lost_treasure`) show larger raw drift as expected at low simulation volumes.
A40: 31
A41: 32 | B41: ## Simulation Notes
...

Sheet Treasure_Dice_Phase_5_Volatilit
A1: Treasure Dice Phase 5 Volatility Report
A2: Treasure_Dice_Phase_5_Volatility_Report.md
A3: Audit Metrics
A4: Key | B4: Value
A5: Regular Std Range | B5: 0.480000 - 9.551879
A6: Bonus Std | B6: 77.022951
A7: Bonus Variance | B7: 5932.535
A9: Source Text
A10: Line | B10: Content
A11: 1 | B11: # Treasure Dice Phase 5 Volatility Report
A12: 2
A13: 3 | B13: ## Document Status
A14: 4
A15: 5 | B15: - Phase: 5 - Validation and Reporting
A16: 6 | B16: - Source summary: [treasure_dice_phase5_validation_summary.json](treasure_dice_phase5_validation_summary.json)
A17: 7
A18: 8 | B18: ## Scope
A19: 9
A20: 10 | B20: This report reconciles theoretical and simulated standard deviation (payout-multiplier space) for all eight modes.
A21: 11
A22: 12 | B22: ## Volatility Comparison
A23: 13
A24: 14 | B24: | Mode | Theoretical Std Dev | Simulated Std Dev | Delta |
A25: 15 | B25: | --- | ---: | ---: | ---: |
A26: 16 | B26: | safe_shore | 0.4800 | 0.4650 | -0.0150 |
A27: 17 | B27: | hidden_bay | 0.7838 | 0.7738 | -0.0101 |
A28: 18 | B28: | coral_reef | 1.1758 | 1.1821 | +0.0064 |
A29: 19 | B29: | storm_route | 1.6628 | 1.7088 | +0.0460 |
A30: 20 | B30: | skull_island | 2.8800 | 3.0037 | +0.1237 |
A31: 21 | B31: | kraken_waters | 4.1845 | 4.4879 | +0.3033 |
A32: 22 | B32: | lost_treasure | 9.5519 | 9.0663 | -0.4856 |
A33: 23 | B33: | treasure_hunt_buy | 75.1399 | 75.5730 | +0.4331 |
A34: 24
A35: 25 | B35: ## Interpretation
A36: 26
A37: 27 | B37: - Lower-volatility route modes (`safe_shore`, `hidden_bay`, `coral_reef`) align tightly between theory and simulation.
A38: 28 | B38: - Higher-volatility modes and bonus mode show broader spread, expected with current run lengths.
A39: 29 | B39: - No structural mismatch between mapped payout ladders and generated lookup distributions was detected.
A40: 30
A41: 31 | B41: ## Verdict
...

Sheet Treasure_Dice_Phase_5_Final_Val
A1: Treasure Dice Phase 5 Final Validation Summary
A2: Treasure_Dice_Phase_5_Final_Validation_Summary.md
A3: Audit Metrics
A4: Key | B4: Value
A5: All RTP Pass | B5: TRUE
A6: All Weight Pass | B6: TRUE
A7: All Lookup Pass | B7: TRUE
A8: All MaxWin Pass | B8: TRUE
A9: All Replay Pass | B9: TRUE
A11: Computed Validation Table
A12: Mode | B12: Cost | C12: Theoretical RTP | D12: Recalculated RTP | E12: Drift | F12: Pass
A13: safe_shore | B13: 1 | C13: 0.96 | D13: 0.96 | E13: 2.4980018e-14 | F13: Pass
A14: hidden_bay | B14: 1 | C14: 0.96 | D14: 0.96 | E14: 9.3258734e-15 | F14: Pass
A15: coral_reef | B15: 1 | C15: 0.96 | D15: 0.96 | E15: -6.2172489e-15 | F15: Pass
A16: storm_route | B16: 1 | C16: 0.96 | D16: 0.96 | E16: 2.3314684e-15 | F16: Pass
A17: skull_island | B17: 1 | C17: 0.96 | D17: 0.96 | E17: 1.6653345e-15 | F17: Pass
A18: kraken_waters | B18: 1 | C18: 0.96 | D18: 0.96 | E18: 9.9920072e-16 | F18: Pass
A19: lost_treasure | B19: 1 | C19: 0.96 | D19: 0.96 | E19: 0 | F19: Pass
A20: treasure_hunt_buy | B20: 100 | C20: 0.96 | D20: 0.95995 | E20: -5e-05 | F20: Pass
A22: Source Text
A23: Line | B23: Content
A24: 1 | B24: # Treasure Dice Phase 5 Final Validation Summary
A25: 2
A26: 3 | B26: ## Recalculated Package Validation
A27: 4
A28: 5 | B28: - Date: 2026-06-06
A29: 6 | B29: - Scope: treasure_dice_final/artifacts/publish_files
A30: 7 | B30: - Target RTP per mode: 96.00%
A31: 8 | B31: - RTP tolerance: +/-0.01
A32: 9
A33: 10 | B33: ## Consolidated Verdict
A34: 11
A35: 12 | B35: - RTP tolerance check: Pass.
A36: 13 | B36: - Weight integrity check: Pass.
A37: 14 | B37: - Max-win bound check: Pass.
A38: 15
A39: 16 | B39: ## Mode RTP Table
A40: 17
A41: 18 | B41: | Mode | Cost | Theoretical RTP | Recalculated RTP | Drift | Pass |
A42: 19 | B42: | --- | ---: | ---: | ---: | ---: | --- |
...

Sheet Treasure_Dice_Phase_6_Precision
A1: Treasure Dice Phase 6 Precision Rounding And Frontend Contract
A2: Treasure_Dice_Phase_6_Precision_Rounding_And_Frontend_Contract.md
A3: Audit Metrics
A4: Key | B4: Value
A5: Policy | B5: Stake Engine integer money with six decimal places
A6: Small Bets | B6: 0.01, 0.02, 0.05
A7: RTP Retention | B7: Exact under final settlement model
A9: Source Text
A10: Line | B10: Content
A11: 1 | B11: # Treasure Dice Phase 6 Precision, Rounding, and Frontend Contract
A12: 2
A13: 3 | B13: ## Document Status
A14: 4
A15: 5 | B15: - Phase: 6 - Publication Readiness
A16: 6 | B16: - Purpose: Final closure of Game_Description sections 11 and 12 for Treasure Dice publication
A17: 7
A18: 8 | B18: ## Governing Engine Rule
A19: 9
A20: 10 | B20: Stake Engine settlement uses integer monetary values with six decimal places of precision.
A21: 11
A22: 12 | B22: Source evidence:
A23: 13
A24: 14 | B24: - [math-sdk/docs/rgs_docs/RGS.md](math-sdk/docs/rgs_docs/RGS.md)
A25: 15
A26: 16 | B26: This supersedes the earlier provisional fiat-cent review assumption used in Phase 1 for sensitivity analysis. Currency formatting belongs to the display layer and does not alter gameplay logic or settlement.
A27: 17
A28: 18 | B28: ## Final Section 11 Policy
A29: 19
A30: 20 | B30: ### 1. Internal Precision
A31: 21
A32: 22 | B32: - Probabilities and normalized outcome weights are validated to an absolute tolerance of `1e-8`.
A33: 23 | B33: - Regular-route payout multipliers are fixed exactly as published in the brief: `1.20`, `1.60`, `2.40`, `3.84`, `9.60`, `19.20`, `96.00`.
A34: 24 | B34: - Bonus payout multipliers for the approved Candidate A package are fixed as exact whole-number multiples of base bet: `0`, `50`, `90`, `120`, `180`, `275`.
A35: 25 | B35: - Settlement amounts are represented in Stake Engine money units with six decimal places of precision.
A36: 26
A37: 27 | B37: ### 2. Currency Rounding Rules
A38: 28
A39: 29 | B39: - Settlement rule for all supported currencies: compute payout using Stake Engine six-decimal money precision, with no pre-settlement cent rounding.
A40: 30 | B40: - Display rule for fiat and crypto-like currencies: apply currency formatting only after authoritative settlement is determined.
A41: 31 | B41: - Display formatting must never be used to recalculate or alter payout.
...

Sheet Treasure_Dice_Exposure_Table_Pe
A1: Treasure Dice Exposure Table Pending Operator Cap
A2: Treasure_Dice_Exposure_Table_Pending_Operator_Cap.md
A3: Audit Metrics
A4: Key | B4: Value
A5: Status | B5: Pending operator payout cap
A6: Formula | B6: max allowed base bet = payout cap / max win multiplier
A7: Highest Regular Max Win | B7: 96
A8: Bonus Max Win | B8: 275
A10: Source Text
A11: Line | B11: Content
A12: 1 | B12: # Treasure Dice Exposure Table Pending Operator Cap
A13: 2
A14: 3 | B14: ## Document Status
A15: 4
A16: 5 | B16: - Date: 2026-06-04
A17: 6 | B17: - Purpose: Provide release-ready exposure formulas until an operator payout cap is supplied
A18: 7
A19: 8 | B19: ## Rule
A20: 9
A21: 10 | B21: If an operator provides an absolute payout cap, then:
A22: 11
A23: 12 | B23: `max allowed base bet = payout cap / max win multiplier`
A24: 13
A25: 14 | B25: ## Per-Mode Exposure Formula Table
A26: 15
A27: 16 | B27: | Mode ID | Max Win Multiplier | Max Allowed Base Bet Formula |
A28: 17 | B28: | --- | --- | --- |
A29: 18 | B29: | safe_shore | 1.20x | `cap / 1.20` |
A30: 19 | B30: | hidden_bay | 1.60x | `cap / 1.60` |
A31: 20 | B31: | coral_reef | 2.40x | `cap / 2.40` |
A32: 21 | B32: | storm_route | 3.84x | `cap / 3.84` |
A33: 22 | B33: | skull_island | 9.60x | `cap / 9.60` |
A34: 23 | B34: | kraken_waters | 19.20x | `cap / 19.20` |
A35: 24 | B35: | lost_treasure | 96.00x | `cap / 96.00` |
A36: 25 | B36: | treasure_hunt_buy | 275.00x | `cap / 275.00` |
A37: 26
A38: 27 | B38: ## Current Status
A39: 28
A40: 29 | B40: - No operator payout cap is assumed in the current publication package.
A41: 30 | B41: - This table is complete enough for release documentation and must be replaced with a cap-specific table only if an operator mandates an absolute payout cap.

Sheet Treasure_Dice_Phase_6_Risk_Asse
A1: Treasure Dice Phase 6 Risk Assessment
A2: Treasure_Dice_Phase_6_Risk_Assessment.md
A3: Audit Metrics
A4: Key | B4: Value
A5: Package Status | B5: Ready
A6: Acceptance Status | B6: Pass
A7: Key Risk | B7: Operator payout cap not yet supplied
A9: Source Text
A10: Line | B10: Content
A11: 1 | B11: # Treasure Dice Phase 6 Risk Assessment
A12: 2
A13: 3 | B13: ## Document Status
A14: 4
A15: 5 | B15: - Phase: 6 - Publication Readiness
A16: 6 | B16: - Date: 2026-06-08
A17: 7
A18: 8
A19: 9 | B19: ## Risk Scale
A20: 10
A21: 11 | B21: - Severity: High, Medium, Low
A22: 12 | B22: - Likelihood: High, Medium, Low
A23: 13
A24: 14 | B24: ## Active Risks
A25: 15
A26: 16 | B26: ### R2 - Short-run simulation drift for high-volatility modes
A27: 17
A28: 18 | B28: - Description: Current package-validation simulation lengths are suitable for integrity checks but can show notable RTP drift in volatile modes.
A29: 19 | B29: - Source evidence: [Treasure_Dice_Phase_5_Simulation_Report.md](Treasure_Dice_Phase_5_Simulation_Report.md)
A30: 20 | B30: - Severity: Medium
A31: 21 | B31: - Likelihood: Medium
A32: 22 | B32: - Impact: Potential misinterpretation of production RTP if short-run metrics are used as final statistical sign-off.
A33: 23 | B33: - Mitigation options:
A34: 24 | B34: 1. Run larger simulation volume for final statistical confidence.
A35: 25 | B35: 2. Use sigma-based interpretation in release notes.
A36: 26 | B36: - Owner: Math validation owner.
A37: 27 | B37: - Status: Open for final sign-off campaign, acceptable for package integrity gate.
A38: 28
A39: 29 | B39: ### R3 - Operator payout-cap dependency for exposure closure
A40: 30
A41: 31 | B41: - Description: Absolute payout-cap value is not confirmed; exposure table uses formulas only.
...

Sheet Treasure_Dice_Phase_6_Acceptanc
A1: Treasure Dice Phase 6 Acceptance Checklist
A2: Treasure_Dice_Phase_6_Acceptance_Checklist.md
A3: Audit Metrics
A4: Key | B4: Value
A5: RTP Checks | B5: Pass
A6: Replay Checks | B6: Pass
A7: Lookup Checks | B7: Pass
A8: Max Win Checks | B8: Pass
A10: Source Text
A11: Line | B11: Content
A12: 1 | B12: # Treasure Dice Phase 6 Acceptance Checklist
A13: 2
A14: 3 | B14: ## Document Status
A15: 4
A16: 5 | B16: - Phase: 6 - Publication Readiness
A17: 6 | B17: - Acceptance source: Section 17 in [Game_Description.md](Game_Description.md)
A18: 7
A19: 8 | B19: ## Acceptance Criteria Matrix
A20: 9
A21: 10 | B21: | # | Acceptance Criterion | Status | Evidence | Notes |
A22: 11 | B22: | --- | --- | --- | --- | --- |
A23: 12 | B23: | 1 | Seven regular routes published as separate static modes with cost 1 | Pass | [math-sdk/games/treasure_dice/library/publish_files/index.json](math-sdk/games/treasure_dice/library/publish_files/index.json), [math-sdk/games/treasure_dice/library/configs/config_fe_treasure_dice.json](math-sdk/games/treasure_dice/library/configs/config_fe_treasure_dice.json) | safe_shore through lost_treasure present |
A24: 13 | B24: | 2 | Bonus Buy published as separate treasure_hunt_buy mode with cost 100 | Pass | [math-sdk/games/treasure_dice/library/publish_files/index.json](math-sdk/games/treasure_dice/library/publish_files/index.json), [math-sdk/games/treasure_dice/library/configs/config_fe_treasure_dice.json](math-sdk/games/treasure_dice/library/configs/config_fe_treasure_dice.json) | Mode present with cost 100 |
A25: 14 | B25: | 3 | Theoretical RTP of each mode equals 96.00% before currency rounding | Pass | [Treasure_Dice_Phase_1_Math_Report.md](Treasure_Dice_Phase_1_Math_Report.md), [Treasure_Dice_Phase_2_Bonus_Report.md](Treasure_Dice_Phase_2_Bonus_Report.md) | All defined at 0.96 |
A26: 15 | B26: | 4 | Combined RTP remains 96.00% regardless of mode mix | Pass | [Game_Description.md](Game_Description.md), [Treasure_Dice_Phase_2_Bonus_Report.md](Treasure_Dice_Phase_2_Bonus_Report.md) | Same RTP target across regular and bonus modes |
