Workbook

Sheet Summary
A1: AzteckPlinkoBiased_audit_formulas Workbook
A2: Generated from F:\Gaming\Stakes\math-sdk\games\azteck_plinko_biased_binomial
A4: Package
A5: Key | B5: Value
A6: Root | B6: F:\Gaming\Stakes\math-sdk\games\azteck_plinko_biased_binomial
A7: Index | B7: F:\Gaming\Stakes\math-sdk\games\azteck_plinko_biased_binomial\artifacts\publish_files\index.json
A8: Lookup files | B8: 72
A9: Docs dir exists | B9: TRUE
A10: RTP tolerance | B10: 0.01
A11: Payout scale | B11: 100
A12: Max bet assumption | B12: 500
A14: Mode Metrics
A15: Mode | B15: Cost | C15: Rows Config | D15: Expected Buckets | E15: Rows | F15: Unique Multipliers | G15: Bucket Structure Pass | H15: RTP Target | I15: RTP Actual | J15: Abs Drift | K15: RTP Pass | L15: Hit Rate | M15: Zero Rate | N15: Profit Rate | O15: Weighted Mean | P15: Std | Q15: Max Win | R15: Max Win Probability | S15: Max Exposure
A16: buy100_expert_10 | B16: ='buy100_expert_10'!$B$3 | C16: 10 | D16: =IF(C16="","",C16+1) | E16: ='buy100_expert_10'!B24 | F16: ='buy100_expert_10'!B25 | G16: =IF(C16="","N/A",E16=D16) | H16: ='buy100_expert_10'!$D$3 | I16: ='buy100_expert_10'!I19 | J16: =ABS(I16-H16) | K16: ='buy100_expert_10'!J19 | L16: =SUMIFS('buy100_expert_10'!E7:E17,'buy100_expert_10'!D7:D17,">0") | M16: =SUMIFS('buy100_expert_10'!E7:E17,'buy100_expert_10'!D7:D17,"=0") | N16: =SUMIFS('buy100_expert_10'!E7:E17,'buy100_expert_10'!D7:D17,">"&B16) | O16: ='buy100_expert_10'!H19 | P16: =SQRT(SUMPRODUCT('buy100_expert_10'!E7:E17,('buy100_expert_10'!D7:D17-O16)^2)) | Q16: ='buy100_expert_10'!B22 | R16: ='buy100_expert_10'!B23 | S16: ='buy100_expert_10'!B26
A17: buy100_expert_11 | B17: ='buy100_expert_11'!$B$3 | C17: 11 | D17: =IF(C17="","",C17+1) | E17: ='buy100_expert_11'!B25 | F17: ='buy100_expert_11'!B26 | G17: =IF(C17="","N/A",E17=D17) | H17: ='buy100_expert_11'!$D$3 | I17: ='buy100_expert_11'!I20 | J17: =ABS(I17-H17) | K17: ='buy100_expert_11'!J20 | L17: =SUMIFS('buy100_expert_11'!E7:E18,'buy100_expert_11'!D7:D18,">0") | M17: =SUMIFS('buy100_expert_11'!E7:E18,'buy100_expert_11'!D7:D18,"=0") | N17: =SUMIFS('buy100_expert_11'!E7:E18,'buy100_expert_11'!D7:D18,">"&B17) | O17: ='buy100_expert_11'!H20 | P17: =SQRT(SUMPRODUCT('buy100_expert_11'!E7:E18,('buy100_expert_11'!D7:D18-O17)^2)) | Q17: ='buy100_expert_11'!B23 | R17: ='buy100_expert_11'!B24 | S17: ='buy100_expert_11'!B27
A18: buy100_expert_12 | B18: ='buy100_expert_12'!$B$3 | C18: 12 | D18: =IF(C18="","",C18+1) | E18: ='buy100_expert_12'!B26 | F18: ='buy100_expert_12'!B27 | G18: =IF(C18="","N/A",E18=D18) | H18: ='buy100_expert_12'!$D$3 | I18: ='buy100_expert_12'!I21 | J18: =ABS(I18-H18) | K18: ='buy100_expert_12'!J21 | L18: =SUMIFS('buy100_expert_12'!E7:E19,'buy100_expert_12'!D7:D19,">0") | M18: =SUMIFS('buy100_expert_12'!E7:E19,'buy100_expert_12'!D7:D19,"=0") | N18: =SUMIFS('buy100_expert_12'!E7:E19,'buy100_expert_12'!D7:D19,">"&B18) | O18: ='buy100_expert_12'!H21 | P18: =SQRT(SUMPRODUCT('buy100_expert_12'!E7:E19,('buy100_expert_12'!D7:D19-O18)^2)) | Q18: ='buy100_expert_12'!B24 | R18: ='buy100_expert_12'!B25 | S18: ='buy100_expert_12'!B28
A19: buy100_expert_13 | B19: ='buy100_expert_13'!$B$3 | C19: 13 | D19: =IF(C19="","",C19+1) | E19: ='buy100_expert_13'!B27 | F19: ='buy100_expert_13'!B28 | G19: =IF(C19="","N/A",E19=D19) | H19: ='buy100_expert_13'!$D$3 | I19: ='buy100_expert_13'!I22 | J19: =ABS(I19-H19) | K19: ='buy100_expert_13'!J22 | L19: =SUMIFS('buy100_expert_13'!E7:E20,'buy100_expert_13'!D7:D20,">0") | M19: =SUMIFS('buy100_expert_13'!E7:E20,'buy100_expert_13'!D7:D20,"=0") | N19: =SUMIFS('buy100_expert_13'!E7:E20,'buy100_expert_13'!D7:D20,">"&B19) | O19: ='buy100_expert_13'!H22 | P19: =SQRT(SUMPRODUCT('buy100_expert_13'!E7:E20,('buy100_expert_13'!D7:D20-O19)^2)) | Q19: ='buy100_expert_13'!B25 | R19: ='buy100_expert_13'!B26 | S19: ='buy100_expert_13'!B29
A20: buy100_expert_14 | B20: ='buy100_expert_14'!$B$3 | C20: 14 | D20: =IF(C20="","",C20+1) | E20: ='buy100_expert_14'!B28 | F20: ='buy100_expert_14'!B29 | G20: =IF(C20="","N/A",E20=D20) | H20: ='buy100_expert_14'!$D$3 | I20: ='buy100_expert_14'!I23 | J20: =ABS(I20-H20) | K20: ='buy100_expert_14'!J23 | L20: =SUMIFS('buy100_expert_14'!E7:E21,'buy100_expert_14'!D7:D21,">0") | M20: =SUMIFS('buy100_expert_14'!E7:E21,'buy100_expert_14'!D7:D21,"=0") | N20: =SUMIFS('buy100_expert_14'!E7:E21,'buy100_expert_14'!D7:D21,">"&B20) | O20: ='buy100_expert_14'!H23 | P20: =SQRT(SUMPRODUCT('buy100_expert_14'!E7:E21,('buy100_expert_14'!D7:D21-O20)^2)) | Q20: ='buy100_expert_14'!B26 | R20: ='buy100_expert_14'!B27 | S20: ='buy100_expert_14'!B30
A21: buy100_expert_15 | B21: ='buy100_expert_15'!$B$3 | C21: 15 | D21: =IF(C21="","",C21+1) | E21: ='buy100_expert_15'!B29 | F21: ='buy100_expert_15'!B30 | G21: =IF(C21="","N/A",E21=D21) | H21: ='buy100_expert_15'!$D$3 | I21: ='buy100_expert_15'!I24 | J21: =ABS(I21-H21) | K21: ='buy100_expert_15'!J24 | L21: =SUMIFS('buy100_expert_15'!E7:E22,'buy100_expert_15'!D7:D22,">0") | M21: =SUMIFS('buy100_expert_15'!E7:E22,'buy100_expert_15'!D7:D22,"=0") | N21: =SUMIFS('buy100_expert_15'!E7:E22,'buy100_expert_15'!D7:D22,">"&B21) | O21: ='buy100_expert_15'!H24 | P21: =SQRT(SUMPRODUCT('buy100_expert_15'!E7:E22,('buy100_expert_15'!D7:D22-O21)^2)) | Q21: ='buy100_expert_15'!B27 | R21: ='buy100_expert_15'!B28 | S21: ='buy100_expert_15'!B31
A22: buy100_expert_16 | B22: ='buy100_expert_16'!$B$3 | C22: 16 | D22: =IF(C22="","",C22+1) | E22: ='buy100_expert_16'!B30 | F22: ='buy100_expert_16'!B31 | G22: =IF(C22="","N/A",E22=D22) | H22: ='buy100_expert_16'!$D$3 | I22: ='buy100_expert_16'!I25 | J22: =ABS(I22-H22) | K22: ='buy100_expert_16'!J25 | L22: =SUMIFS('buy100_expert_16'!E7:E23,'buy100_expert_16'!D7:D23,">0") | M22: =SUMIFS('buy100_expert_16'!E7:E23,'buy100_expert_16'!D7:D23,"=0") | N22: =SUMIFS('buy100_expert_16'!E7:E23,'buy100_expert_16'!D7:D23,">"&B22) | O22: ='buy100_expert_16'!H25 | P22: =SQRT(SUMPRODUCT('buy100_expert_16'!E7:E23,('buy100_expert_16'!D7:D23-O22)^2)) | Q22: ='buy100_expert_16'!B28 | R22: ='buy100_expert_16'!B29 | S22: ='buy100_expert_16'!B32
A23: buy100_expert_8 | B23: ='buy100_expert_8'!$B$3 | C23: 8 | D23: =IF(C23="","",C23+1) | E23: ='buy100_expert_8'!B22 | F23: ='buy100_expert_8'!B23 | G23: =IF(C23="","N/A",E23=D23) | H23: ='buy100_expert_8'!$D$3 | I23: ='buy100_expert_8'!I17 | J23: =ABS(I23-H23) | K23: ='buy100_expert_8'!J17 | L23: =SUMIFS('buy100_expert_8'!E7:E15,'buy100_expert_8'!D7:D15,">0") | M23: =SUMIFS('buy100_expert_8'!E7:E15,'buy100_expert_8'!D7:D15,"=0") | N23: =SUMIFS('buy100_expert_8'!E7:E15,'buy100_expert_8'!D7:D15,">"&B23) | O23: ='buy100_expert_8'!H17 | P23: =SQRT(SUMPRODUCT('buy100_expert_8'!E7:E15,('buy100_expert_8'!D7:D15-O23)^2)) | Q23: ='buy100_expert_8'!B20 | R23: ='buy100_expert_8'!B21 | S23: ='buy100_expert_8'!B24
A24: buy100_expert_9 | B24: ='buy100_expert_9'!$B$3 | C24: 9 | D24: =IF(C24="","",C24+1) | E24: ='buy100_expert_9'!B23 | F24: ='buy100_expert_9'!B24 | G24: =IF(C24="","N/A",E24=D24) | H24: ='buy100_expert_9'!$D$3 | I24: ='buy100_expert_9'!I18 | J24: =ABS(I24-H24) | K24: ='buy100_expert_9'!J18 | L24: =SUMIFS('buy100_expert_9'!E7:E16,'buy100_expert_9'!D7:D16,">0") | M24: =SUMIFS('buy100_expert_9'!E7:E16,'buy100_expert_9'!D7:D16,"=0") | N24: =SUMIFS('buy100_expert_9'!E7:E16,'buy100_expert_9'!D7:D16,">"&B24) | O24: ='buy100_expert_9'!H18 | P24: =SQRT(SUMPRODUCT('buy100_expert_9'!E7:E16,('buy100_expert_9'!D7:D16-O24)^2)) | Q24: ='buy100_expert_9'!B21 | R24: ='buy100_expert_9'!B22 | S24: ='buy100_expert_9'!B25
A25: buy100_high_10 | B25: ='buy100_high_10'!$B$3 | C25: 10 | D25: =IF(C25="","",C25+1) | E25: ='buy100_high_10'!B24 | F25: ='buy100_high_10'!B25 | G25: =IF(C25="","N/A",E25=D25) | H25: ='buy100_high_10'!$D$3 | I25: ='buy100_high_10'!I19 | J25: =ABS(I25-H25) | K25: ='buy100_high_10'!J19 | L25: =SUMIFS('buy100_high_10'!E7:E17,'buy100_high_10'!D7:D17,">0") | M25: =SUMIFS('buy100_high_10'!E7:E17,'buy100_high_10'!D7:D17,"=0") | N25: =SUMIFS('buy100_high_10'!E7:E17,'buy100_high_10'!D7:D17,">"&B25) | O25: ='buy100_high_10'!H19 | P25: =SQRT(SUMPRODUCT('buy100_high_10'!E7:E17,('buy100_high_10'!D7:D17-O25)^2)) | Q25: ='buy100_high_10'!B22 | R25: ='buy100_high_10'!B23 | S25: ='buy100_high_10'!B26
A26: buy100_high_11 | B26: ='buy100_high_11'!$B$3 | C26: 11 | D26: =IF(C26="","",C26+1) | E26: ='buy100_high_11'!B25 | F26: ='buy100_high_11'!B26 | G26: =IF(C26="","N/A",E26=D26) | H26: ='buy100_high_11'!$D$3 | I26: ='buy100_high_11'!I20 | J26: =ABS(I26-H26) | K26: ='buy100_high_11'!J20 | L26: =SUMIFS('buy100_high_11'!E7:E18,'buy100_high_11'!D7:D18,">0") | M26: =SUMIFS('buy100_high_11'!E7:E18,'buy100_high_11'!D7:D18,"=0") | N26: =SUMIFS('buy100_high_11'!E7:E18,'buy100_high_11'!D7:D18,">"&B26) | O26: ='buy100_high_11'!H20 | P26: =SQRT(SUMPRODUCT('buy100_high_11'!E7:E18,('buy100_high_11'!D7:D18-O26)^2)) | Q26: ='buy100_high_11'!B23 | R26: ='buy100_high_11'!B24 | S26: ='buy100_high_11'!B27
A27: buy100_high_12 | B27: ='buy100_high_12'!$B$3 | C27: 12 | D27: =IF(C27="","",C27+1) | E27: ='buy100_high_12'!B26 | F27: ='buy100_high_12'!B27 | G27: =IF(C27="","N/A",E27=D27) | H27: ='buy100_high_12'!$D$3 | I27: ='buy100_high_12'!I21 | J27: =ABS(I27-H27) | K27: ='buy100_high_12'!J21 | L27: =SUMIFS('buy100_high_12'!E7:E19,'buy100_high_12'!D7:D19,">0") | M27: =SUMIFS('buy100_high_12'!E7:E19,'buy100_high_12'!D7:D19,"=0") | N27: =SUMIFS('buy100_high_12'!E7:E19,'buy100_high_12'!D7:D19,">"&B27) | O27: ='buy100_high_12'!H21 | P27: =SQRT(SUMPRODUCT('buy100_high_12'!E7:E19,('buy100_high_12'!D7:D19-O27)^2)) | Q27: ='buy100_high_12'!B24 | R27: ='buy100_high_12'!B25 | S27: ='buy100_high_12'!B28
A28: buy100_high_13 | B28: ='buy100_high_13'!$B$3 | C28: 13 | D28: =IF(C28="","",C28+1) | E28: ='buy100_high_13'!B27 | F28: ='buy100_high_13'!B28 | G28: =IF(C28="","N/A",E28=D28) | H28: ='buy100_high_13'!$D$3 | I28: ='buy100_high_13'!I22 | J28: =ABS(I28-H28) | K28: ='buy100_high_13'!J22 | L28: =SUMIFS('buy100_high_13'!E7:E20,'buy100_high_13'!D7:D20,">0") | M28: =SUMIFS('buy100_high_13'!E7:E20,'buy100_high_13'!D7:D20,"=0") | N28: =SUMIFS('buy100_high_13'!E7:E20,'buy100_high_13'!D7:D20,">"&B28) | O28: ='buy100_high_13'!H22 | P28: =SQRT(SUMPRODUCT('buy100_high_13'!E7:E20,('buy100_high_13'!D7:D20-O28)^2)) | Q28: ='buy100_high_13'!B25 | R28: ='buy100_high_13'!B26 | S28: ='buy100_high_13'!B29
A29: buy100_high_14 | B29: ='buy100_high_14'!$B$3 | C29: 14 | D29: =IF(C29="","",C29+1) | E29: ='buy100_high_14'!B28 | F29: ='buy100_high_14'!B29 | G29: =IF(C29="","N/A",E29=D29) | H29: ='buy100_high_14'!$D$3 | I29: ='buy100_high_14'!I23 | J29: =ABS(I29-H29) | K29: ='buy100_high_14'!J23 | L29: =SUMIFS('buy100_high_14'!E7:E21,'buy100_high_14'!D7:D21,">0") | M29: =SUMIFS('buy100_high_14'!E7:E21,'buy100_high_14'!D7:D21,"=0") | N29: =SUMIFS('buy100_high_14'!E7:E21,'buy100_high_14'!D7:D21,">"&B29) | O29: ='buy100_high_14'!H23 | P29: =SQRT(SUMPRODUCT('buy100_high_14'!E7:E21,('buy100_high_14'!D7:D21-O29)^2)) | Q29: ='buy100_high_14'!B26 | R29: ='buy100_high_14'!B27 | S29: ='buy100_high_14'!B30
A30: buy100_high_15 | B30: ='buy100_high_15'!$B$3 | C30: 15 | D30: =IF(C30="","",C30+1) | E30: ='buy100_high_15'!B29 | F30: ='buy100_high_15'!B30 | G30: =IF(C30="","N/A",E30=D30) | H30: ='buy100_high_15'!$D$3 | I30: ='buy100_high_15'!I24 | J30: =ABS(I30-H30) | K30: ='buy100_high_15'!J24 | L30: =SUMIFS('buy100_high_15'!E7:E22,'buy100_high_15'!D7:D22,">0") | M30: =SUMIFS('buy100_high_15'!E7:E22,'buy100_high_15'!D7:D22,"=0") | N30: =SUMIFS('buy100_high_15'!E7:E22,'buy100_high_15'!D7:D22,">"&B30) | O30: ='buy100_high_15'!H24 | P30: =SQRT(SUMPRODUCT('buy100_high_15'!E7:E22,('buy100_high_15'!D7:D22-O30)^2)) | Q30: ='buy100_high_15'!B27 | R30: ='buy100_high_15'!B28 | S30: ='buy100_high_15'!B31
A31: buy100_high_16 | B31: ='buy100_high_16'!$B$3 | C31: 16 | D31: =IF(C31="","",C31+1) | E31: ='buy100_high_16'!B30 | F31: ='buy100_high_16'!B31 | G31: =IF(C31="","N/A",E31=D31) | H31: ='buy100_high_16'!$D$3 | I31: ='buy100_high_16'!I25 | J31: =ABS(I31-H31) | K31: ='buy100_high_16'!J25 | L31: =SUMIFS('buy100_high_16'!E7:E23,'buy100_high_16'!D7:D23,">0") | M31: =SUMIFS('buy100_high_16'!E7:E23,'buy100_high_16'!D7:D23,"=0") | N31: =SUMIFS('buy100_high_16'!E7:E23,'buy100_high_16'!D7:D23,">"&B31) | O31: ='buy100_high_16'!H25 | P31: =SQRT(SUMPRODUCT('buy100_high_16'!E7:E23,('buy100_high_16'!D7:D23-O31)^2)) | Q31: ='buy100_high_16'!B28 | R31: ='buy100_high_16'!B29 | S31: ='buy100_high_16'!B32
A32: buy100_high_8 | B32: ='buy100_high_8'!$B$3 | C32: 8 | D32: =IF(C32="","",C32+1) | E32: ='buy100_high_8'!B22 | F32: ='buy100_high_8'!B23 | G32: =IF(C32="","N/A",E32=D32) | H32: ='buy100_high_8'!$D$3 | I32: ='buy100_high_8'!I17 | J32: =ABS(I32-H32) | K32: ='buy100_high_8'!J17 | L32: =SUMIFS('buy100_high_8'!E7:E15,'buy100_high_8'!D7:D15,">0") | M32: =SUMIFS('buy100_high_8'!E7:E15,'buy100_high_8'!D7:D15,"=0") | N32: =SUMIFS('buy100_high_8'!E7:E15,'buy100_high_8'!D7:D15,">"&B32) | O32: ='buy100_high_8'!H17 | P32: =SQRT(SUMPRODUCT('buy100_high_8'!E7:E15,('buy100_high_8'!D7:D15-O32)^2)) | Q32: ='buy100_high_8'!B20 | R32: ='buy100_high_8'!B21 | S32: ='buy100_high_8'!B24
A33: buy100_high_9 | B33: ='buy100_high_9'!$B$3 | C33: 9 | D33: =IF(C33="","",C33+1) | E33: ='buy100_high_9'!B23 | F33: ='buy100_high_9'!B24 | G33: =IF(C33="","N/A",E33=D33) | H33: ='buy100_high_9'!$D$3 | I33: ='buy100_high_9'!I18 | J33: =ABS(I33-H33) | K33: ='buy100_high_9'!J18 | L33: =SUMIFS('buy100_high_9'!E7:E16,'buy100_high_9'!D7:D16,">0") | M33: =SUMIFS('buy100_high_9'!E7:E16,'buy100_high_9'!D7:D16,"=0") | N33: =SUMIFS('buy100_high_9'!E7:E16,'buy100_high_9'!D7:D16,">"&B33) | O33: ='buy100_high_9'!H18 | P33: =SQRT(SUMPRODUCT('buy100_high_9'!E7:E16,('buy100_high_9'!D7:D16-O33)^2)) | Q33: ='buy100_high_9'!B21 | R33: ='buy100_high_9'!B22 | S33: ='buy100_high_9'!B25
A34: buy100_low_10 | B34: ='buy100_low_10'!$B$3 | C34: 10 | D34: =IF(C34="","",C34+1) | E34: ='buy100_low_10'!B24 | F34: ='buy100_low_10'!B25 | G34: =IF(C34="","N/A",E34=D34) | H34: ='buy100_low_10'!$D$3 | I34: ='buy100_low_10'!I19 | J34: =ABS(I34-H34) | K34: ='buy100_low_10'!J19 | L34: =SUMIFS('buy100_low_10'!E7:E17,'buy100_low_10'!D7:D17,">0") | M34: =SUMIFS('buy100_low_10'!E7:E17,'buy100_low_10'!D7:D17,"=0") | N34: =SUMIFS('buy100_low_10'!E7:E17,'buy100_low_10'!D7:D17,">"&B34) | O34: ='buy100_low_10'!H19 | P34: =SQRT(SUMPRODUCT('buy100_low_10'!E7:E17,('buy100_low_10'!D7:D17-O34)^2)) | Q34: ='buy100_low_10'!B22 | R34: ='buy100_low_10'!B23 | S34: ='buy100_low_10'!B26
A35: buy100_low_11 | B35: ='buy100_low_11'!$B$3 | C35: 11 | D35: =IF(C35="","",C35+1) | E35: ='buy100_low_11'!B25 | F35: ='buy100_low_11'!B26 | G35: =IF(C35="","N/A",E35=D35) | H35: ='buy100_low_11'!$D$3 | I35: ='buy100_low_11'!I20 | J35: =ABS(I35-H35) | K35: ='buy100_low_11'!J20 | L35: =SUMIFS('buy100_low_11'!E7:E18,'buy100_low_11'!D7:D18,">0") | M35: =SUMIFS('buy100_low_11'!E7:E18,'buy100_low_11'!D7:D18,"=0") | N35: =SUMIFS('buy100_low_11'!E7:E18,'buy100_low_11'!D7:D18,">"&B35) | O35: ='buy100_low_11'!H20 | P35: =SQRT(SUMPRODUCT('buy100_low_11'!E7:E18,('buy100_low_11'!D7:D18-O35)^2)) | Q35: ='buy100_low_11'!B23 | R35: ='buy100_low_11'!B24 | S35: ='buy100_low_11'!B27
A36: buy100_low_12 | B36: ='buy100_low_12'!$B$3 | C36: 12 | D36: =IF(C36="","",C36+1) | E36: ='buy100_low_12'!B26 | F36: ='buy100_low_12'!B27 | G36: =IF(C36="","N/A",E36=D36) | H36: ='buy100_low_12'!$D$3 | I36: ='buy100_low_12'!I21 | J36: =ABS(I36-H36) | K36: ='buy100_low_12'!J21 | L36: =SUMIFS('buy100_low_12'!E7:E19,'buy100_low_12'!D7:D19,">0") | M36: =SUMIFS('buy100_low_12'!E7:E19,'buy100_low_12'!D7:D19,"=0") | N36: =SUMIFS('buy100_low_12'!E7:E19,'buy100_low_12'!D7:D19,">"&B36) | O36: ='buy100_low_12'!H21 | P36: =SQRT(SUMPRODUCT('buy100_low_12'!E7:E19,('buy100_low_12'!D7:D19-O36)^2)) | Q36: ='buy100_low_12'!B24 | R36: ='buy100_low_12'!B25 | S36: ='buy100_low_12'!B28
A37: buy100_low_13 | B37: ='buy100_low_13'!$B$3 | C37: 13 | D37: =IF(C37="","",C37+1) | E37: ='buy100_low_13'!B27 | F37: ='buy100_low_13'!B28 | G37: =IF(C37="","N/A",E37=D37) | H37: ='buy100_low_13'!$D$3 | I37: ='buy100_low_13'!I22 | J37: =ABS(I37-H37) | K37: ='buy100_low_13'!J22 | L37: =SUMIFS('buy100_low_13'!E7:E20,'buy100_low_13'!D7:D20,">0") | M37: =SUMIFS('buy100_low_13'!E7:E20,'buy100_low_13'!D7:D20,"=0") | N37: =SUMIFS('buy100_low_13'!E7:E20,'buy100_low_13'!D7:D20,">"&B37) | O37: ='buy100_low_13'!H22 | P37: =SQRT(SUMPRODUCT('buy100_low_13'!E7:E20,('buy100_low_13'!D7:D20-O37)^2)) | Q37: ='buy100_low_13'!B25 | R37: ='buy100_low_13'!B26 | S37: ='buy100_low_13'!B29
A38: buy100_low_14 | B38: ='buy100_low_14'!$B$3 | C38: 14 | D38: =IF(C38="","",C38+1) | E38: ='buy100_low_14'!B28 | F38: ='buy100_low_14'!B29 | G38: =IF(C38="","N/A",E38=D38) | H38: ='buy100_low_14'!$D$3 | I38: ='buy100_low_14'!I23 | J38: =ABS(I38-H38) | K38: ='buy100_low_14'!J23 | L38: =SUMIFS('buy100_low_14'!E7:E21,'buy100_low_14'!D7:D21,">0") | M38: =SUMIFS('buy100_low_14'!E7:E21,'buy100_low_14'!D7:D21,"=0") | N38: =SUMIFS('buy100_low_14'!E7:E21,'buy100_low_14'!D7:D21,">"&B38) | O38: ='buy100_low_14'!H23 | P38: =SQRT(SUMPRODUCT('buy100_low_14'!E7:E21,('buy100_low_14'!D7:D21-O38)^2)) | Q38: ='buy100_low_14'!B26 | R38: ='buy100_low_14'!B27 | S38: ='buy100_low_14'!B30
A39: buy100_low_15 | B39: ='buy100_low_15'!$B$3 | C39: 15 | D39: =IF(C39="","",C39+1) | E39: ='buy100_low_15'!B29 | F39: ='buy100_low_15'!B30 | G39: =IF(C39="","N/A",E39=D39) | H39: ='buy100_low_15'!$D$3 | I39: ='buy100_low_15'!I24 | J39: =ABS(I39-H39) | K39: ='buy100_low_15'!J24 | L39: =SUMIFS('buy100_low_15'!E7:E22,'buy100_low_15'!D7:D22,">0") | M39: =SUMIFS('buy100_low_15'!E7:E22,'buy100_low_15'!D7:D22,"=0") | N39: =SUMIFS('buy100_low_15'!E7:E22,'buy100_low_15'!D7:D22,">"&B39) | O39: ='buy100_low_15'!H24 | P39: =SQRT(SUMPRODUCT('buy100_low_15'!E7:E22,('buy100_low_15'!D7:D22-O39)^2)) | Q39: ='buy100_low_15'!B27 | R39: ='buy100_low_15'!B28 | S39: ='buy100_low_15'!B31
A40: buy100_low_16 | B40: ='buy100_low_16'!$B$3 | C40: 16 | D40: =IF(C40="","",C40+1) | E40: ='buy100_low_16'!B30 | F40: ='buy100_low_16'!B31 | G40: =IF(C40="","N/A",E40=D40) | H40: ='buy100_low_16'!$D$3 | I40: ='buy100_low_16'!I25 | J40: =ABS(I40-H40) | K40: ='buy100_low_16'!J25 | L40: =SUMIFS('buy100_low_16'!E7:E23,'buy100_low_16'!D7:D23,">0") | M40: =SUMIFS('buy100_low_16'!E7:E23,'buy100_low_16'!D7:D23,"=0") | N40: =SUMIFS('buy100_low_16'!E7:E23,'buy100_low_16'!D7:D23,">"&B40) | O40: ='buy100_low_16'!H25 | P40: =SQRT(SUMPRODUCT('buy100_low_16'!E7:E23,('buy100_low_16'!D7:D23-O40)^2)) | Q40: ='buy100_low_16'!B28 | R40: ='buy100_low_16'!B29 | S40: ='buy100_low_16'!B32
A41: buy100_low_8 | B41: ='buy100_low_8'!$B$3 | C41: 8 | D41: =IF(C41="","",C41+1) | E41: ='buy100_low_8'!B22 | F41: ='buy100_low_8'!B23 | G41: =IF(C41="","N/A",E41=D41) | H41: ='buy100_low_8'!$D$3 | I41: ='buy100_low_8'!I17 | J41: =ABS(I41-H41) | K41: ='buy100_low_8'!J17 | L41: =SUMIFS('buy100_low_8'!E7:E15,'buy100_low_8'!D7:D15,">0") | M41: =SUMIFS('buy100_low_8'!E7:E15,'buy100_low_8'!D7:D15,"=0") | N41: =SUMIFS('buy100_low_8'!E7:E15,'buy100_low_8'!D7:D15,">"&B41) | O41: ='buy100_low_8'!H17 | P41: =SQRT(SUMPRODUCT('buy100_low_8'!E7:E15,('buy100_low_8'!D7:D15-O41)^2)) | Q41: ='buy100_low_8'!B20 | R41: ='buy100_low_8'!B21 | S41: ='buy100_low_8'!B24
A42: buy100_low_9 | B42: ='buy100_low_9'!$B$3 | C42: 9 | D42: =IF(C42="","",C42+1) | E42: ='buy100_low_9'!B23 | F42: ='buy100_low_9'!B24 | G42: =IF(C42="","N/A",E42=D42) | H42: ='buy100_low_9'!$D$3 | I42: ='buy100_low_9'!I18 | J42: =ABS(I42-H42) | K42: ='buy100_low_9'!J18 | L42: =SUMIFS('buy100_low_9'!E7:E16,'buy100_low_9'!D7:D16,">0") | M42: =SUMIFS('buy100_low_9'!E7:E16,'buy100_low_9'!D7:D16,"=0") | N42: =SUMIFS('buy100_low_9'!E7:E16,'buy100_low_9'!D7:D16,">"&B42) | O42: ='buy100_low_9'!H18 | P42: =SQRT(SUMPRODUCT('buy100_low_9'!E7:E16,('buy100_low_9'!D7:D16-O42)^2)) | Q42: ='buy100_low_9'!B21 | R42: ='buy100_low_9'!B22 | S42: ='buy100_low_9'!B25
...

Sheet buy100_expert_10
A1: buy100_expert_10 Lookup Detail
A2: Derived from lookup rows
A3: Cost | B3: 99 | C3: Target RTP | D3: 0.9605 | E3: RTP Tol | F3: 0.01 | G3: Payout Scale | H3: 100 | I3: Rows (N) | J3: 10 | K3: p_right | L3: 0.49353346 | M3: p_left | N3: =IF(L3="","",1-L3)
A5: Rows
A6: sim_id | B6: weight | C6: payout_raw | D6: payout_scaled | E6: probability_binomial_exact | F6: probability_from_weight | G6: probability_diff | H6: weighted_payout | I6: cumulative_probability
A7: 0 | B7: 1110472 | C7: 0 | D7: =C7/$H$3 | E7: =IF($J$3="",IF($B$19>0,B7/$B$19,0),COMBIN($J$3,A7)*$L$3^A7*(1-$L$3)^($J$3-A7)) | F7: =IF($B$19>0,B7/$B$19,0) | G7: =E7-F7 | H7: =D7*E7 | I7: =E7
A8: 1 | B8: 10821151 | C8: 0 | D8: =C8/$H$3 | E8: =IF($J$3="",IF($B$19>0,B8/$B$19,0),COMBIN($J$3,A8)*$L$3^A8*(1-$L$3)^($J$3-A8)) | F8: =IF($B$19>0,B8/$B$19,0) | G8: =E8-F8 | H8: =D8*E8 | I8: =I7+E8
A9: 2 | B9: 47451703 | C9: 0 | D9: =C9/$H$3 | E9: =IF($J$3="",IF($B$19>0,B9/$B$19,0),COMBIN($J$3,A9)*$L$3^A9*(1-$L$3)^($J$3-A9)) | F9: =IF($B$19>0,B9/$B$19,0) | G9: =E9-F9 | H9: =D9*E9 | I9: =I8+E9
A10: 3 | B10: 123306614 | C10: 0 | D10: =C10/$H$3 | E10: =IF($J$3="",IF($B$19>0,B10/$B$19,0),COMBIN($J$3,A10)*$L$3^A10*(1-$L$3)^($J$3-A10)) | F10: =IF($B$19>0,B10/$B$19,0) | G10: =E10-F10 | H10: =D10*E10 | I10: =I9+E10
A11: 4 | B11: 210276267 | C11: 0 | D11: =C11/$H$3 | E11: =IF($J$3="",IF($B$19>0,B11/$B$19,0),COMBIN($J$3,A11)*$L$3^A11*(1-$L$3)^($J$3-A11)) | F11: =IF($B$19>0,B11/$B$19,0) | G11: =E11-F11 | H11: =D11*E11 | I11: =I10+E11
A12: 5 | B12: 245888005 | C12: 0 | D12: =C12/$H$3 | E12: =IF($J$3="",IF($B$19>0,B12/$B$19,0),COMBIN($J$3,A12)*$L$3^A12*(1-$L$3)^($J$3-A12)) | F12: =IF($B$19>0,B12/$B$19,0) | G12: =E12-F12 | H12: =D12*E12 | I12: =I11+E12
A13: 6 | B13: 199674192 | C13: 0 | D13: =C13/$H$3 | E13: =IF($J$3="",IF($B$19>0,B13/$B$19,0),COMBIN($J$3,A13)*$L$3^A13*(1-$L$3)^($J$3-A13)) | F13: =IF($B$19>0,B13/$B$19,0) | G13: =E13-F13 | H13: =D13*E13 | I13: =I12+E13
A14: 7 | B14: 111185902 | C14: 10 | D14: =C14/$H$3 | E14: =IF($J$3="",IF($B$19>0,B14/$B$19,0),COMBIN($J$3,A14)*$L$3^A14*(1-$L$3)^($J$3-A14)) | F14: =IF($B$19>0,B14/$B$19,0) | G14: =E14-F14 | H14: =D14*E14 | I14: =I13+E14
A15: 8 | B15: 40630001 | C15: 1029 | D15: =C15/$H$3 | E15: =IF($J$3="",IF($B$19>0,B15/$B$19,0),COMBIN($J$3,A15)*$L$3^A15*(1-$L$3)^($J$3-A15)) | F15: =IF($B$19>0,B15/$B$19,0) | G15: =E15-F15 | H15: =D15*E15 | I15: =I14+E15
A16: 9 | B16: 8798328 | C16: 101420 | D16: =C16/$H$3 | E16: =IF($J$3="",IF($B$19>0,B16/$B$19,0),COMBIN($J$3,A16)*$L$3^A16*(1-$L$3)^($J$3-A16)) | F16: =IF($B$19>0,B16/$B$19,0) | G16: =E16-F16 | H16: =D16*E16 | I16: =I15+E16
A17: 10 | B17: 857370 | C17: 10000000 | D17: =C17/$H$3 | E17: =IF($J$3="",IF($B$19>0,B17/$B$19,0),COMBIN($J$3,A17)*$L$3^A17*(1-$L$3)^($J$3-A17)) | F17: =IF($B$19>0,B17/$B$19,0) | G17: =E17-F17 | H17: =D17*E17 | I17: =I16+E17
A19: CHECK_SUMS | B19: =SUM(B7:B17) | C19: payout_raw_sum | D19: =SUM(D7:D17) | E19: =SUM(E7:E17) | F19: =SUM(F7:F17) | G19: =MAX(ABS(G7:G17)) | H19: =SUM(H7:H17) | I19: =IF($B$3>0,H19/$B$3,0) | J19: =IF($D$3="","N/A",ABS(I19-$D$3)<=$F$3)
A20: rtp_drift | B20: =IF($D$3="","",I19-$D$3)
A21: prob_sum_check | B21: =ABS(E19-1)<=1E-9
A22: max_win_value | B22: =MAX(D7:D17)
A23: max_win_probability | B23: =SUMIFS(E7:E17,D7:D17,B22)
A24: outcome_rows | B24: =ROWS(A7:A17)
A25: unique_multipliers | B25: =SUMPRODUCT(1/COUNTIF(D7:D17,D7:D17))
A26: max_exposure_with_max_bet | B26: =B22*500.0

Sheet buy100_expert_11
A1: buy100_expert_11 Lookup Detail
A2: Derived from lookup rows
A3: Cost | B3: 99 | C3: Target RTP | D3: 0.9605 | E3: RTP Tol | F3: 0.01 | G3: Payout Scale | H3: 100 | I3: Rows (N) | J3: 11 | K3: p_right | L3: 0.52625399 | M3: p_left | N3: =IF(L3="","",1-L3)
A5: Rows
A6: sim_id | B6: weight | C6: payout_raw | D6: payout_scaled | E6: probability_binomial_exact | F6: probability_from_weight | G6: probability_diff | H6: weighted_payout | I6: cumulative_probability
A7: 0 | B7: 269775 | C7: 0 | D7: =C7/$H$3 | E7: =IF($J$3="",IF($B$20>0,B7/$B$20,0),COMBIN($J$3,A7)*$L$3^A7*(1-$L$3)^($J$3-A7)) | F7: =IF($B$20>0,B7/$B$20,0) | G7: =E7-F7 | H7: =D7*E7 | I7: =E7
A8: 1 | B8: 3296429 | C8: 0 | D8: =C8/$H$3 | E8: =IF($J$3="",IF($B$20>0,B8/$B$20,0),COMBIN($J$3,A8)*$L$3^A8*(1-$L$3)^($J$3-A8)) | F8: =IF($B$20>0,B8/$B$20,0) | G8: =E8-F8 | H8: =D8*E8 | I8: =I7+E8
A9: 2 | B9: 18308955 | C9: 0 | D9: =C9/$H$3 | E9: =IF($J$3="",IF($B$20>0,B9/$B$20,0),COMBIN($J$3,A9)*$L$3^A9*(1-$L$3)^($J$3-A9)) | F9: =IF($B$20>0,B9/$B$20,0) | G9: =E9-F9 | H9: =D9*E9 | I9: =I8+E9
A10: 3 | B10: 61014725 | C10: 0 | D10: =C10/$H$3 | E10: =IF($J$3="",IF($B$20>0,B10/$B$20,0),COMBIN($J$3,A10)*$L$3^A10*(1-$L$3)^($J$3-A10)) | F10: =IF($B$20>0,B10/$B$20,0) | G10: =E10-F10 | H10: =D10*E10 | I10: =I9+E10
A11: 4 | B11: 135554673 | C11: 0 | D11: =C11/$H$3 | E11: =IF($J$3="",IF($B$20>0,B11/$B$20,0),COMBIN($J$3,A11)*$L$3^A11*(1-$L$3)^($J$3-A11)) | F11: =IF($B$20>0,B11/$B$20,0) | G11: =E11-F11 | H11: =D11*E11 | I11: =I10+E11
A12: 5 | B12: 210810565 | C12: 0 | D12: =C12/$H$3 | E12: =IF($J$3="",IF($B$20>0,B12/$B$20,0),COMBIN($J$3,A12)*$L$3^A12*(1-$L$3)^($J$3-A12)) | F12: =IF($B$20>0,B12/$B$20,0) | G12: =E12-F12 | H12: =D12*E12 | I12: =I11+E12
A13: 6 | B13: 234175908 | C13: 0 | D13: =C13/$H$3 | E13: =IF($J$3="",IF($B$20>0,B13/$B$20,0),COMBIN($J$3,A13)*$L$3^A13*(1-$L$3)^($J$3-A13)) | F13: =IF($B$20>0,B13/$B$20,0) | G13: =E13-F13 | H13: =D13*E13 | I13: =I12+E13
A14: 7 | B14: 185807833 | C14: 0 | D14: =C14/$H$3 | E14: =IF($J$3="",IF($B$20>0,B14/$B$20,0),COMBIN($J$3,A14)*$L$3^A14*(1-$L$3)^($J$3-A14)) | F14: =IF($B$20>0,B14/$B$20,0) | G14: =E14-F14 | H14: =D14*E14 | I14: =I13+E14
A15: 8 | B15: 103200990 | C15: 12 | D15: =C15/$H$3 | E15: =IF($J$3="",IF($B$20>0,B15/$B$20,0),COMBIN($J$3,A15)*$L$3^A15*(1-$L$3)^($J$3-A15)) | F15: =IF($B$20>0,B15/$B$20,0) | G15: =E15-F15 | H15: =D15*E15 | I15: =I14+E15
A16: 9 | B16: 38213116 | C16: 1104 | D16: =C16/$H$3 | E16: =IF($J$3="",IF($B$20>0,B16/$B$20,0),COMBIN($J$3,A16)*$L$3^A16*(1-$L$3)^($J$3-A16)) | F16: =IF($B$20>0,B16/$B$20,0) | G16: =E16-F16 | H16: =D16*E16 | I16: =I15+E16
A17: 10 | B17: 8489699 | C17: 105092 | D17: =C17/$H$3 | E17: =IF($J$3="",IF($B$20>0,B17/$B$20,0),COMBIN($J$3,A17)*$L$3^A17*(1-$L$3)^($J$3-A17)) | F17: =IF($B$20>0,B17/$B$20,0) | G17: =E17-F17 | H17: =D17*E17 | I17: =I16+E17
A18: 11 | B18: 857332 | C18: 10000000 | D18: =C18/$H$3 | E18: =IF($J$3="",IF($B$20>0,B18/$B$20,0),COMBIN($J$3,A18)*$L$3^A18*(1-$L$3)^($J$3-A18)) | F18: =IF($B$20>0,B18/$B$20,0) | G18: =E18-F18 | H18: =D18*E18 | I18: =I17+E18
A20: CHECK_SUMS | B20: =SUM(B7:B18) | C20: payout_raw_sum | D20: =SUM(D7:D18) | E20: =SUM(E7:E18) | F20: =SUM(F7:F18) | G20: =MAX(ABS(G7:G18)) | H20: =SUM(H7:H18) | I20: =IF($B$3>0,H20/$B$3,0) | J20: =IF($D$3="","N/A",ABS(I20-$D$3)<=$F$3)
A21: rtp_drift | B21: =IF($D$3="","",I20-$D$3)
A22: prob_sum_check | B22: =ABS(E20-1)<=1E-9
A23: max_win_value | B23: =MAX(D7:D18)
A24: max_win_probability | B24: =SUMIFS(E7:E18,D7:D18,B23)
A25: outcome_rows | B25: =ROWS(A7:A18)
A26: unique_multipliers | B26: =SUMPRODUCT(1/COUNTIF(D7:D18,D7:D18))
A27: max_exposure_with_max_bet | B27: =B23*500.0

Sheet buy100_expert_12
A1: buy100_expert_12 Lookup Detail
A2: Derived from lookup rows
A3: Cost | B3: 99 | C3: Target RTP | D3: 0.9605 | E3: RTP Tol | F3: 0.01 | G3: Payout Scale | H3: 100 | I3: Rows (N) | J3: 12 | K3: p_right | L3: 0.5551725 | M3: p_left | N3: =IF(L3="","",1-L3)
A5: Rows
A6: sim_id | B6: weight | C6: payout_raw | D6: payout_scaled | E6: probability_binomial_exact | F6: probability_from_weight | G6: probability_diff | H6: weighted_payout | I6: cumulative_probability
A7: 0 | B7: 60020 | C7: 0 | D7: =C7/$H$3 | E7: =IF($J$3="",IF($B$21>0,B7/$B$21,0),COMBIN($J$3,A7)*$L$3^A7*(1-$L$3)^($J$3-A7)) | F7: =IF($B$21>0,B7/$B$21,0) | G7: =E7-F7 | H7: =D7*E7 | I7: =E7
A8: 1 | B8: 898912 | C8: 0 | D8: =C8/$H$3 | E8: =IF($J$3="",IF($B$21>0,B8/$B$21,0),COMBIN($J$3,A8)*$L$3^A8*(1-$L$3)^($J$3-A8)) | F8: =IF($B$21>0,B8/$B$21,0) | G8: =E8-F8 | H8: =D8*E8 | I8: =I7+E8
A9: 2 | B9: 6170440 | C9: 0 | D9: =C9/$H$3 | E9: =IF($J$3="",IF($B$21>0,B9/$B$21,0),COMBIN($J$3,A9)*$L$3^A9*(1-$L$3)^($J$3-A9)) | F9: =IF($B$21>0,B9/$B$21,0) | G9: =E9-F9 | H9: =D9*E9 | I9: =I8+E9
A10: 3 | B10: 25670315 | C10: 0 | D10: =C10/$H$3 | E10: =IF($J$3="",IF($B$21>0,B10/$B$21,0),COMBIN($J$3,A10)*$L$3^A10*(1-$L$3)^($J$3-A10)) | F10: =IF($B$21>0,B10/$B$21,0) | G10: =E10-F10 | H10: =D10*E10 | I10: =I9+E10
A11: 4 | B11: 72085850 | C11: 0 | D11: =C11/$H$3 | E11: =IF($J$3="",IF($B$21>0,B11/$B$21,0),COMBIN($J$3,A11)*$L$3^A11*(1-$L$3)^($J$3-A11)) | F11: =IF($B$21>0,B11/$B$21,0) | G11: =E11-F11 | H11: =D11*E11 | I11: =I10+E11
A12: 5 | B12: 143948226 | C12: 0 | D12: =C12/$H$3 | E12: =IF($J$3="",IF($B$21>0,B12/$B$21,0),COMBIN($J$3,A12)*$L$3^A12*(1-$L$3)^($J$3-A12)) | F12: =IF($B$21>0,B12/$B$21,0) | G12: =E12-F12 | H12: =D12*E12 | I12: =I11+E12
A13: 6 | B13: 209599102 | C13: 0 | D13: =C13/$H$3 | E13: =IF($J$3="",IF($B$21>0,B13/$B$21,0),COMBIN($J$3,A13)*$L$3^A13*(1-$L$3)^($J$3-A13)) | F13: =IF($B$21>0,B13/$B$21,0) | G13: =E13-F13 | H13: =D13*E13 | I13: =I12+E13
A14: 7 | B14: 224222370 | C14: 0 | D14: =C14/$H$3 | E14: =IF($J$3="",IF($B$21>0,B14/$B$21,0),COMBIN($J$3,A14)*$L$3^A14*(1-$L$3)^($J$3-A14)) | F14: =IF($B$21>0,B14/$B$21,0) | G14: =E14-F14 | H14: =D14*E14 | I14: =I13+E14
A15: 8 | B15: 174902198 | C15: 0 | D15: =C15/$H$3 | E15: =IF($J$3="",IF($B$21>0,B15/$B$21,0),COMBIN($J$3,A15)*$L$3^A15*(1-$L$3)^($J$3-A15)) | F15: =IF($B$21>0,B15/$B$21,0) | G15: =E15-F15 | H15: =D15*E15 | I15: =I14+E15
A16: 9 | B16: 97017272 | C16: 13 | D16: =C16/$H$3 | E16: =IF($J$3="",IF($B$21>0,B16/$B$21,0),COMBIN($J$3,A16)*$L$3^A16*(1-$L$3)^($J$3-A16)) | F16: =IF($B$21>0,B16/$B$21,0) | G16: =E16-F16 | H16: =D16*E16 | I16: =I15+E16
A17: 10 | B17: 36325084 | C17: 1171 | D17: =C17/$H$3 | E17: =IF($J$3="",IF($B$21>0,B17/$B$21,0),COMBIN($J$3,A17)*$L$3^A17*(1-$L$3)^($J$3-A17)) | F17: =IF($B$21>0,B17/$B$21,0) | G17: =E17-F17 | H17: =D17*E17 | I17: =I16+E17
A18: 11 | B18: 8242904 | C18: 108226 | D18: =C18/$H$3 | E18: =IF($J$3="",IF($B$21>0,B18/$B$21,0),COMBIN($J$3,A18)*$L$3^A18*(1-$L$3)^($J$3-A18)) | F18: =IF($B$21>0,B18/$B$21,0) | G18: =E18-F18 | H18: =D18*E18 | I18: =I17+E18
A19: 12 | B19: 857306 | C19: 10000000 | D19: =C19/$H$3 | E19: =IF($J$3="",IF($B$21>0,B19/$B$21,0),COMBIN($J$3,A19)*$L$3^A19*(1-$L$3)^($J$3-A19)) | F19: =IF($B$21>0,B19/$B$21,0) | G19: =E19-F19 | H19: =D19*E19 | I19: =I18+E19
A21: CHECK_SUMS | B21: =SUM(B7:B19) | C21: payout_raw_sum | D21: =SUM(D7:D19) | E21: =SUM(E7:E19) | F21: =SUM(F7:F19) | G21: =MAX(ABS(G7:G19)) | H21: =SUM(H7:H19) | I21: =IF($B$3>0,H21/$B$3,0) | J21: =IF($D$3="","N/A",ABS(I21-$D$3)<=$F$3)
A22: rtp_drift | B22: =IF($D$3="","",I21-$D$3)
A23: prob_sum_check | B23: =ABS(E21-1)<=1E-9
A24: max_win_value | B24: =MAX(D7:D19)
A25: max_win_probability | B25: =SUMIFS(E7:E19,D7:D19,B24)
A26: outcome_rows | B26: =ROWS(A7:A19)
A27: unique_multipliers | B27: =SUMPRODUCT(1/COUNTIF(D7:D19,D7:D19))
A28: max_exposure_with_max_bet | B28: =B24*500.0

Sheet buy100_expert_13
A1: buy100_expert_13 Lookup Detail
A2: Derived from lookup rows
A3: Cost | B3: 99 | C3: Target RTP | D3: 0.9605 | E3: RTP Tol | F3: 0.01 | G3: Payout Scale | H3: 100 | I3: Rows (N) | J3: 13 | K3: p_right | L3: 0.58087996 | M3: p_left | N3: =IF(L3="","",1-L3)
A5: Rows
A6: sim_id | B6: weight | C6: payout_raw | D6: payout_scaled | E6: probability_binomial_exact | F6: probability_from_weight | G6: probability_diff | H6: weighted_payout | I6: cumulative_probability
A7: 0 | B7: 12314 | C7: 0 | D7: =C7/$H$3 | E7: =IF($J$3="",IF($B$22>0,B7/$B$22,0),COMBIN($J$3,A7)*$L$3^A7*(1-$L$3)^($J$3-A7)) | F7: =IF($B$22>0,B7/$B$22,0) | G7: =E7-F7 | H7: =D7*E7 | I7: =E7
A8: 1 | B8: 221866 | C8: 0 | D8: =C8/$H$3 | E8: =IF($J$3="",IF($B$22>0,B8/$B$22,0),COMBIN($J$3,A8)*$L$3^A8*(1-$L$3)^($J$3-A8)) | F8: =IF($B$22>0,B8/$B$22,0) | G8: =E8-F8 | H8: =D8*E8 | I8: =I7+E8
A9: 2 | B9: 1844973 | C9: 0 | D9: =C9/$H$3 | E9: =IF($J$3="",IF($B$22>0,B9/$B$22,0),COMBIN($J$3,A9)*$L$3^A9*(1-$L$3)^($J$3-A9)) | F9: =IF($B$22>0,B9/$B$22,0) | G9: =E9-F9 | H9: =D9*E9 | I9: =I8+E9
A10: 3 | B10: 9375825 | C10: 0 | D10: =C10/$H$3 | E10: =IF($J$3="",IF($B$22>0,B10/$B$22,0),COMBIN($J$3,A10)*$L$3^A10*(1-$L$3)^($J$3-A10)) | F10: =IF($B$22>0,B10/$B$22,0) | G10: =E10-F10 | H10: =D10*E10 | I10: =I9+E10
A11: 4 | B11: 32486091 | C11: 0 | D11: =C11/$H$3 | E11: =IF($J$3="",IF($B$22>0,B11/$B$22,0),COMBIN($J$3,A11)*$L$3^A11*(1-$L$3)^($J$3-A11)) | F11: =IF($B$22>0,B11/$B$22,0) | G11: =E11-F11 | H11: =D11*E11 | I11: =I10+E11
A12: 5 | B12: 81043452 | C12: 0 | D12: =C12/$H$3 | E12: =IF($J$3="",IF($B$22>0,B12/$B$22,0),COMBIN($J$3,A12)*$L$3^A12*(1-$L$3)^($J$3-A12)) | F12: =IF($B$22>0,B12/$B$22,0) | G12: =E12-F12 | H12: =D12*E12 | I12: =I11+E12
A13: 6 | B13: 149763036 | C13: 0 | D13: =C13/$H$3 | E13: =IF($J$3="",IF($B$22>0,B13/$B$22,0),COMBIN($J$3,A13)*$L$3^A13*(1-$L$3)^($J$3-A13)) | F13: =IF($B$22>0,B13/$B$22,0) | G13: =E13-F13 | H13: =D13*E13 | I13: =I12+E13
A14: 7 | B14: 207564273 | C14: 0 | D14: =C14/$H$3 | E14: =IF($J$3="",IF($B$22>0,B14/$B$22,0),COMBIN($J$3,A14)*$L$3^A14*(1-$L$3)^($J$3-A14)) | F14: =IF($B$22>0,B14/$B$22,0) | G14: =E14-F14 | H14: =D14*E14 | I14: =I13+E14
A15: 8 | B15: 215755478 | C15: 0 | D15: =C15/$H$3 | E15: =IF($J$3="",IF($B$22>0,B15/$B$22,0),COMBIN($J$3,A15)*$L$3^A15*(1-$L$3)^($J$3-A15)) | F15: =IF($B$22>0,B15/$B$22,0) | G15: =E15-F15 | H15: =D15*E15 | I15: =I14+E15
A16: 9 | B16: 166125879 | C16: 0 | D16: =C16/$H$3 | E16: =IF($J$3="",IF($B$22>0,B16/$B$22,0),COMBIN($J$3,A16)*$L$3^A16*(1-$L$3)^($J$3-A16)) | F16: =IF($B$22>0,B16/$B$22,0) | G16: =E16-F16 | H16: =D16*E16 | I16: =I15+E16
A17: 10 | B17: 92096950 | C17: 14 | D17: =C17/$H$3 | E17: =IF($J$3="",IF($B$22>0,B17/$B$22,0),COMBIN($J$3,A17)*$L$3^A17*(1-$L$3)^($J$3-A17)) | F17: =IF($B$22>0,B17/$B$22,0) | G17: =E17-F17 | H17: =D17*E17 | I17: =I16+E17
A18: 11 | B18: 34811424 | C18: 1231 | D18: =C18/$H$3 | E18: =IF($J$3="",IF($B$22>0,B18/$B$22,0),COMBIN($J$3,A18)*$L$3^A18*(1-$L$3)^($J$3-A18)) | F18: =IF($B$22>0,B18/$B$22,0) | G18: =E18-F18 | H18: =D18*E18 | I18: =I17+E18
A19: 12 | B19: 8041156 | C19: 110932 | D19: =C19/$H$3 | E19: =IF($J$3="",IF($B$22>0,B19/$B$22,0),COMBIN($J$3,A19)*$L$3^A19*(1-$L$3)^($J$3-A19)) | F19: =IF($B$22>0,B19/$B$22,0) | G19: =E19-F19 | H19: =D19*E19 | I19: =I18+E19
A20: 13 | B20: 857279 | C20: 10000000 | D20: =C20/$H$3 | E20: =IF($J$3="",IF($B$22>0,B20/$B$22,0),COMBIN($J$3,A20)*$L$3^A20*(1-$L$3)^($J$3-A20)) | F20: =IF($B$22>0,B20/$B$22,0) | G20: =E20-F20 | H20: =D20*E20 | I20: =I19+E20
A22: CHECK_SUMS | B22: =SUM(B7:B20) | C22: payout_raw_sum | D22: =SUM(D7:D20) | E22: =SUM(E7:E20) | F22: =SUM(F7:F20) | G22: =MAX(ABS(G7:G20)) | H22: =SUM(H7:H20) | I22: =IF($B$3>0,H22/$B$3,0) | J22: =IF($D$3="","N/A",ABS(I22-$D$3)<=$F$3)
A23: rtp_drift | B23: =IF($D$3="","",I22-$D$3)
A24: prob_sum_check | B24: =ABS(E22-1)<=1E-9
A25: max_win_value | B25: =MAX(D7:D20)
A26: max_win_probability | B26: =SUMIFS(E7:E20,D7:D20,B25)
A27: outcome_rows | B27: =ROWS(A7:A20)
A28: unique_multipliers | B28: =SUMPRODUCT(1/COUNTIF(D7:D20,D7:D20))
A29: max_exposure_with_max_bet | B29: =B25*500.0

Sheet buy100_expert_14
A1: buy100_expert_14 Lookup Detail
A2: Derived from lookup rows
A3: Cost | B3: 99 | C3: Target RTP | D3: 0.9605 | E3: RTP Tol | F3: 0.01 | G3: Payout Scale | H3: 100 | I3: Rows (N) | J3: 14 | K3: p_right | L3: 0.60386048 | M3: p_left | N3: =IF(L3="","",1-L3)
A5: Rows
A6: sim_id | B6: weight | C6: payout_raw | D6: payout_scaled | E6: probability_binomial_exact | F6: probability_from_weight | G6: probability_diff | H6: weighted_payout | I6: cumulative_probability
A7: 0 | B7: 2344 | C7: 0 | D7: =C7/$H$3 | E7: =IF($J$3="",IF($B$23>0,B7/$B$23,0),COMBIN($J$3,A7)*$L$3^A7*(1-$L$3)^($J$3-A7)) | F7: =IF($B$23>0,B7/$B$23,0) | G7: =E7-F7 | H7: =D7*E7 | I7: =E7
A8: 1 | B8: 50014 | C8: 0 | D8: =C8/$H$3 | E8: =IF($J$3="",IF($B$23>0,B8/$B$23,0),COMBIN($J$3,A8)*$L$3^A8*(1-$L$3)^($J$3-A8)) | F8: =IF($B$23>0,B8/$B$23,0) | G8: =E8-F8 | H8: =D8*E8 | I8: =I7+E8
A9: 2 | B9: 495556 | C9: 0 | D9: =C9/$H$3 | E9: =IF($J$3="",IF($B$23>0,B9/$B$23,0),COMBIN($J$3,A9)*$L$3^A9*(1-$L$3)^($J$3-A9)) | F9: =IF($B$23>0,B9/$B$23,0) | G9: =E9-F9 | H9: =D9*E9 | I9: =I8+E9
A10: 3 | B10: 3021629 | C10: 0 | D10: =C10/$H$3 | E10: =IF($J$3="",IF($B$23>0,B10/$B$23,0),COMBIN($J$3,A10)*$L$3^A10*(1-$L$3)^($J$3-A10)) | F10: =IF($B$23>0,B10/$B$23,0) | G10: =E10-F10 | H10: =D10*E10 | I10: =I9+E10
A11: 4 | B11: 12666664 | C11: 0 | D11: =C11/$H$3 | E11: =IF($J$3="",IF($B$23>0,B11/$B$23,0),COMBIN($J$3,A11)*$L$3^A11*(1-$L$3)^($J$3-A11)) | F11: =IF($B$23>0,B11/$B$23,0) | G11: =E11-F11 | H11: =D11*E11 | I11: =I10+E11
A12: 5 | B12: 38617190 | C12: 0 | D12: =C12/$H$3 | E12: =IF($J$3="",IF($B$23>0,B12/$B$23,0),COMBIN($J$3,A12)*$L$3^A12*(1-$L$3)^($J$3-A12)) | F12: =IF($B$23>0,B12/$B$23,0) | G12: =E12-F12 | H12: =D12*E12 | I12: =I11+E12
A13: 6 | B13: 88299930 | C13: 0 | D13: =C13/$H$3 | E13: =IF($J$3="",IF($B$23>0,B13/$B$23,0),COMBIN($J$3,A13)*$L$3^A13*(1-$L$3)^($J$3-A13)) | F13: =IF($B$23>0,B13/$B$23,0) | G13: =E13-F13 | H13: =D13*E13 | I13: =I12+E13
A14: 7 | B14: 153829893 | C14: 0 | D14: =C14/$H$3 | E14: =IF($J$3="",IF($B$23>0,B14/$B$23,0),COMBIN($J$3,A14)*$L$3^A14*(1-$L$3)^($J$3-A14)) | F14: =IF($B$23>0,B14/$B$23,0) | G14: =E14-F14 | H14: =D14*E14 | I14: =I13+E14
A15: 8 | B15: 205181038 | C15: 0 | D15: =C15/$H$3 | E15: =IF($J$3="",IF($B$23>0,B15/$B$23,0),COMBIN($J$3,A15)*$L$3^A15*(1-$L$3)^($J$3-A15)) | F15: =IF($B$23>0,B15/$B$23,0) | G15: =E15-F15 | H15: =D15*E15 | I15: =I14+E15
A16: 9 | B16: 208513605 | C16: 0 | D16: =C16/$H$3 | E16: =IF($J$3="",IF($B$23>0,B16/$B$23,0),COMBIN($J$3,A16)*$L$3^A16*(1-$L$3)^($J$3-A16)) | F16: =IF($B$23>0,B16/$B$23,0) | G16: =E16-F16 | H16: =D16*E16 | I16: =I15+E16
A17: 10 | B17: 158925224 | C17: 0 | D17: =C17/$H$3 | E17: =IF($J$3="",IF($B$23>0,B17/$B$23,0),COMBIN($J$3,A17)*$L$3^A17*(1-$L$3)^($J$3-A17)) | F17: =IF($B$23>0,B17/$B$23,0) | G17: =E17-F17 | H17: =D17*E17 | I17: =I16+E17
A18: 11 | B18: 88094455 | C18: 15 | D18: =C18/$H$3 | E18: =IF($J$3="",IF($B$23>0,B18/$B$23,0),COMBIN($J$3,A18)*$L$3^A18*(1-$L$3)^($J$3-A18)) | F18: =IF($B$23>0,B18/$B$23,0) | G18: =E18-F18 | H18: =D18*E18 | I18: =I17+E18
A19: 12 | B19: 33571984 | C19: 1283 | D19: =C19/$H$3 | E19: =IF($J$3="",IF($B$23>0,B19/$B$23,0),COMBIN($J$3,A19)*$L$3^A19*(1-$L$3)^($J$3-A19)) | F19: =IF($B$23>0,B19/$B$23,0) | G19: =E19-F19 | H19: =D19*E19 | I19: =I18+E19
... A21: 14 | B21: 857260 | C21: 10000000 | D21: =C21/$H$3 | E21: =IF($J$3="",IF($B$23>0,B21/$B$23,0),COMBIN($J$3,A21)*$L$3^A21*(1-$L$3)^($J$3-A21)) | F21: =IF($B$23>0,B21/$B$23,0) | G21: =E21-F21 | H21: =D21*E21 | I21: =I20+E21
A23: CHECK_SUMS | B23: =SUM(B7:B21) | C23: payout_raw_sum | D23: =SUM(D7:D21) | E23: =SUM(E7:E21) | F23: =SUM(F7:F21) | G23: =MAX(ABS(G7:G21)) | H23: =SUM(H7:H21) | I23: =IF($B$3>0,H23/$B$3,0) | J23: =IF($D$3="","N/A",ABS(I23-$D$3)<=$F$3)
A24: rtp_drift | B24: =IF($D$3="","",I23-$D$3)
A25: prob_sum_check | B25: =ABS(E23-1)<=1E-9
A26: max_win_value | B26: =MAX(D7:D21)
A27: max_win_probability | B27: =SUMIFS(E7:E21,D7:D21,B26)
A28: outcome_rows | B28: =ROWS(A7:A21)
A29: unique_multipliers | B29: =SUMPRODUCT(1/COUNTIF(D7:D21,D7:D21))
A30: max_exposure_with_max_bet | B30: =B26*500.0

Sheet buy100_expert_15
A1: buy100_expert_15 Lookup Detail
A2: Derived from lookup rows
A3: Cost | B3: 99 | C3: Target RTP | D3: 0.9605 | E3: RTP Tol | F3: 0.01 | G3: Payout Scale | H3: 100 | I3: Rows (N) | J3: 15 | K3: p_right | L3: 0.62451117 | M3: p_left | N3: =IF(L3="","",1-L3)
A5: Rows
A6: sim_id | B6: weight | C6: payout_raw | D6: payout_scaled | E6: probability_binomial_exact | F6: probability_from_weight | G6: probability_diff | H6: weighted_payout | I6: cumulative_probability
A7: 0 | B7: 416 | C7: 0 | D7: =C7/$H$3 | E7: =IF($J$3="",IF($B$24>0,B7/$B$24,0),COMBIN($J$3,A7)*$L$3^A7*(1-$L$3)^($J$3-A7)) | F7: =IF($B$24>0,B7/$B$24,0) | G7: =E7-F7 | H7: =D7*E7 | I7: =E7
A8: 1 | B8: 10375 | C8: 0 | D8: =C8/$H$3 | E8: =IF($J$3="",IF($B$24>0,B8/$B$24,0),COMBIN($J$3,A8)*$L$3^A8*(1-$L$3)^($J$3-A8)) | F8: =IF($B$24>0,B8/$B$24,0) | G8: =E8-F8 | H8: =D8*E8 | I8: =I7+E8
A9: 2 | B9: 120790 | C9: 0 | D9: =C9/$H$3 | E9: =IF($J$3="",IF($B$24>0,B9/$B$24,0),COMBIN($J$3,A9)*$L$3^A9*(1-$L$3)^($J$3-A9)) | F9: =IF($B$24>0,B9/$B$24,0) | G9: =E9-F9 | H9: =D9*E9 | I9: =I8+E9
A10: 3 | B10: 870555 | C10: 0 | D10: =C10/$H$3 | E10: =IF($J$3="",IF($B$24>0,B10/$B$24,0),COMBIN($J$3,A10)*$L$3^A10*(1-$L$3)^($J$3-A10)) | F10: =IF($B$24>0,B10/$B$24,0) | G10: =E10-F10 | H10: =D10*E10 | I10: =I9+E10
A11: 4 | B11: 4343709 | C11: 0 | D11: =C11/$H$3 | E11: =IF($J$3="",IF($B$24>0,B11/$B$24,0),COMBIN($J$3,A11)*$L$3^A11*(1-$L$3)^($J$3-A11)) | F11: =IF($B$24>0,B11/$B$24,0) | G11: =E11-F11 | H11: =D11*E11 | I11: =I10+E11
A12: 5 | B12: 15893759 | C12: 0 | D12: =C12/$H$3 | E12: =IF($J$3="",IF($B$24>0,B12/$B$24,0),COMBIN($J$3,A12)*$L$3^A12*(1-$L$3)^($J$3-A12)) | F12: =IF($B$24>0,B12/$B$24,0) | G12: =E12-F12 | H12: =D12*E12 | I12: =I11+E12
A13: 6 | B13: 44057369 | C13: 0 | D13: =C13/$H$3 | E13: =IF($J$3="",IF($B$24>0,B13/$B$24,0),COMBIN($J$3,A13)*$L$3^A13*(1-$L$3)^($J$3-A13)) | F13: =IF($B$24>0,B13/$B$24,0) | G13: =E13-F13 | H13: =D13*E13 | I13: =I12+E13
A14: 7 | B14: 94211998 | C14: 0 | D14: =C14/$H$3 | E14: =IF($J$3="",IF($B$24>0,B14/$B$24,0),COMBIN($J$3,A14)*$L$3^A14*(1-$L$3)^($J$3-A14)) | F14: =IF($B$24>0,B14/$B$24,0) | G14: =E14-F14 | H14: =D14*E14 | I14: =I13+E14
A15: 8 | B15: 156692928 | C15: 0 | D15: =C15/$H$3 | E15: =IF($J$3="",IF($B$24>0,B15/$B$24,0),COMBIN($J$3,A15)*$L$3^A15*(1-$L$3)^($J$3-A15)) | F15: =IF($B$24>0,B15/$B$24,0) | G15: =E15-F15 | H15: =D15*E15 | I15: =I14+E15
A16: 9 | B16: 202697369 | C16: 0 | D16: =C16/$H$3 | E16: =IF($J$3="",IF($B$24>0,B16/$B$24,0),COMBIN($J$3,A16)*$L$3^A16*(1-$L$3)^($J$3-A16)) | F16: =IF($B$24>0,B16/$B$24,0) | G16: =E16-F16 | H16: =D16*E16 | I16: =I15+E16
A17: 10 | B17: 202275157 | C17: 0 | D17: =C17/$H$3 | E17: =IF($J$3="",IF($B$24>0,B17/$B$24,0),COMBIN($J$3,A17)*$L$3^A17*(1-$L$3)^($J$3-A17)) | F17: =IF($B$24>0,B17/$B$24,0) | G17: =E17-F17 | H17: =D17*E17 | I17: =I16+E17
A18: 11 | B18: 152919564 | C18: 0 | D18: =C18/$H$3 | E18: =IF($J$3="",IF($B$24>0,B18/$B$24,0),COMBIN($J$3,A18)*$L$3^A18*(1-$L$3)^($J$3-A18)) | F18: =IF($B$24>0,B18/$B$24,0) | G18: =E18-F18 | H18: =D18*E18 | I18: =I17+E18
A19: 12 | B19: 84778354 | C19: 15 | D19: =C19/$H$3 | E19: =IF($J$3="",IF($B$24>0,B19/$B$24,0),COMBIN($J$3,A19)*$L$3^A19*(1-$L$3)^($J$3-A19)) | F19: =IF($B$24>0,B19/$B$24,0) | G19: =E19-F19 | H19: =D19*E19 | I19: =I18+E19
... A22: 15 | B22: 857247 | C22: 10000000 | D22: =C22/$H$3 | E22: =IF($J$3="",IF($B$24>0,B22/$B$24,0),COMBIN($J$3,A22)*$L$3^A22*(1-$L$3)^($J$3-A22)) | F22: =IF($B$24>0,B22/$B$24,0) | G22: =E22-F22 | H22: =D22*E22 | I22: =I21+E22
A24: CHECK_SUMS | B24: =SUM(B7:B22) | C24: payout_raw_sum | D24: =SUM(D7:D22) | E24: =SUM(E7:E22) | F24: =SUM(F7:F22) | G24: =MAX(ABS(G7:G22)) | H24: =SUM(H7:H22) | I24: =IF($B$3>0,H24/$B$3,0) | J24: =IF($D$3="","N/A",ABS(I24-$D$3)<=$F$3)
A25: rtp_drift | B25: =IF($D$3="","",I24-$D$3)
A26: prob_sum_check | B26: =ABS(E24-1)<=1E-9
A27: max_win_value | B27: =MAX(D7:D22)
A28: max_win_probability | B28: =SUMIFS(E7:E22,D7:D22,B27)
A29: outcome_rows | B29: =ROWS(A7:A22)
A30: unique_multipliers | B30: =SUMPRODUCT(1/COUNTIF(D7:D22,D7:D22))
A31: max_exposure_with_max_bet | B31: =B27*500.0

Sheet buy100_expert_16
A1: buy100_expert_16 Lookup Detail
A2: Derived from lookup rows
A3: Cost | B3: 99 | C3: Target RTP | D3: 0.9605 | E3: RTP Tol | F3: 0.01 | G3: Payout Scale | H3: 100 | I3: Rows (N) | J3: 16 | K3: p_right | L3: 0.64315911 | M3: p_left | N3: =IF(L3="","",1-L3)
A5: Rows
A6: sim_id | B6: weight | C6: payout_raw | D6: payout_scaled | E6: probability_binomial_exact | F6: probability_from_weight | G6: probability_diff | H6: weighted_payout | I6: cumulative_probability
A7: 0 | B7: 69 | C7: 0 | D7: =C7/$H$3 | E7: =IF($J$3="",IF($B$25>0,B7/$B$25,0),COMBIN($J$3,A7)*$L$3^A7*(1-$L$3)^($J$3-A7)) | F7: =IF($B$25>0,B7/$B$25,0) | G7: =E7-F7 | H7: =D7*E7 | I7: =E7
A8: 1 | B8: 1993 | C8: 0 | D8: =C8/$H$3 | E8: =IF($J$3="",IF($B$25>0,B8/$B$25,0),COMBIN($J$3,A8)*$L$3^A8*(1-$L$3)^($J$3-A8)) | F8: =IF($B$25>0,B8/$B$25,0) | G8: =E8-F8 | H8: =D8*E8 | I8: =I7+E8
A9: 2 | B9: 26944 | C9: 0 | D9: =C9/$H$3 | E9: =IF($J$3="",IF($B$25>0,B9/$B$25,0),COMBIN($J$3,A9)*$L$3^A9*(1-$L$3)^($J$3-A9)) | F9: =IF($B$25>0,B9/$B$25,0) | G9: =E9-F9 | H9: =D9*E9 | I9: =I8+E9
A10: 3 | B10: 226628 | C10: 0 | D10: =C10/$H$3 | E10: =IF($J$3="",IF($B$25>0,B10/$B$25,0),COMBIN($J$3,A10)*$L$3^A10*(1-$L$3)^($J$3-A10)) | F10: =IF($B$25>0,B10/$B$25,0) | G10: =E10-F10 | H10: =D10*E10 | I10: =I9+E10
A11: 4 | B11: 1327518 | C11: 0 | D11: =C11/$H$3 | E11: =IF($J$3="",IF($B$25>0,B11/$B$25,0),COMBIN($J$3,A11)*$L$3^A11*(1-$L$3)^($J$3-A11)) | F11: =IF($B$25>0,B11/$B$25,0) | G11: =E11-F11 | H11: =D11*E11 | I11: =I10+E11
A12: 5 | B12: 5742427 | C12: 0 | D12: =C12/$H$3 | E12: =IF($J$3="",IF($B$25>0,B12/$B$25,0),COMBIN($J$3,A12)*$L$3^A12*(1-$L$3)^($J$3-A12)) | F12: =IF($B$25>0,B12/$B$25,0) | G12: =E12-F12 | H12: =D12*E12 | I12: =I11+E12
A13: 6 | B13: 18974954 | C13: 0 | D13: =C13/$H$3 | E13: =IF($J$3="",IF($B$25>0,B13/$B$25,0),COMBIN($J$3,A13)*$L$3^A13*(1-$L$3)^($J$3-A13)) | F13: =IF($B$25>0,B13/$B$25,0) | G13: =E13-F13 | H13: =D13*E13 | I13: =I12+E13
A14: 7 | B14: 48856967 | C14: 0 | D14: =C14/$H$3 | E14: =IF($J$3="",IF($B$25>0,B14/$B$25,0),COMBIN($J$3,A14)*$L$3^A14*(1-$L$3)^($J$3-A14)) | F14: =IF($B$25>0,B14/$B$25,0) | G14: =E14-F14 | H14: =D14*E14 | I14: =I13+E14
A15: 8 | B15: 99065593 | C15: 0 | D15: =C15/$H$3 | E15: =IF($J$3="",IF($B$25>0,B15/$B$25,0),COMBIN($J$3,A15)*$L$3^A15*(1-$L$3)^($J$3-A15)) | F15: =IF($B$25>0,B15/$B$25,0) | G15: =E15-F15 | H15: =D15*E15 | I15: =I14+E15
A16: 9 | B16: 158713600 | C16: 0 | D16: =C16/$H$3 | E16: =IF($J$3="",IF($B$25>0,B16/$B$25,0),COMBIN($J$3,A16)*$L$3^A16*(1-$L$3)^($J$3-A16)) | F16: =IF($B$25>0,B16/$B$25,0) | G16: =E16-F16 | H16: =D16*E16 | I16: =I15+E16
A17: 10 | B17: 200242381 | C17: 0 | D17: =C17/$H$3 | E17: =IF($J$3="",IF($B$25>0,B17/$B$25,0),COMBIN($J$3,A17)*$L$3^A17*(1-$L$3)^($J$3-A17)) | F17: =IF($B$25>0,B17/$B$25,0) | G17: =E17-F17 | H17: =D17*E17 | I17: =I16+E17
A18: 11 | B18: 196860410 | C18: 0 | D18: =C18/$H$3 | E18: =IF($J$3="",IF($B$25>0,B18/$B$25,0),COMBIN($J$3,A18)*$L$3^A18*(1-$L$3)^($J$3-A18)) | F18: =IF($B$25>0,B18/$B$25,0) | G18: =E18-F18 | H18: =D18*E18 | I18: =I17+E18
A19: 12 | B19: 147839663 | C19: 0 | D19: =C19/$H$3 | E19: =IF($J$3="",IF($B$25>0,B19/$B$25,0),COMBIN($J$3,A19)*$L$3^A19*(1-$L$3)^($J$3-A19)) | F19: =IF($B$25>0,B19/$B$25,0) | G19: =E19-F19 | H19: =D19*E19 | I19: =I18+E19
... A23: 16 | B23: 857227 | C23: 10000000 | D23: =C23/$H$3 | E23: =IF($J$3="",IF($B$25>0,B23/$B$25,0),COMBIN($J$3,A23)*$L$3^A23*(1-$L$3)^($J$3-A23)) | F23: =IF($B$25>0,B23/$B$25,0) | G23: =E23-F23 | H23: =D23*E23 | I23: =I22+E23
A25: CHECK_SUMS | B25: =SUM(B7:B23) | C25: payout_raw_sum | D25: =SUM(D7:D23) | E25: =SUM(E7:E23) | F25: =SUM(F7:F23) | G25: =MAX(ABS(G7:G23)) | H25: =SUM(H7:H23) | I25: =IF($B$3>0,H25/$B$3,0) | J25: =IF($D$3="","N/A",ABS(I25-$D$3)<=$F$3)
A26: rtp_drift | B26: =IF($D$3="","",I25-$D$3)
A27: prob_sum_check | B27: =ABS(E25-1)<=1E-9
A28: max_win_value | B28: =MAX(D7:D23)
A29: max_win_probability | B29: =SUMIFS(E7:E23,D7:D23,B28)
A30: outcome_rows | B30: =ROWS(A7:A23)
A31: unique_multipliers | B31: =SUMPRODUCT(1/COUNTIF(D7:D23,D7:D23))
A32: max_exposure_with_max_bet | B32: =B28*500.0

Sheet buy100_expert_8
A1: buy100_expert_8 Lookup Detail
A2: Derived from lookup rows
A3: Cost | B3: 99 | C3: Target RTP | D3: 0.9605 | E3: RTP Tol | F3: 0.01 | G3: Payout Scale | H3: 100 | I3: Rows (N) | J3: 8 | K3: p_right | L3: 0.45167124 | M3: p_left | N3: =IF(L3="","",1-L3)
A5: Rows
A6: sim_id | B6: weight | C6: payout_raw | D6: payout_scaled | E6: probability_binomial_exact | F6: probability_from_weight | G6: probability_diff | H6: weighted_payout | I6: cumulative_probability
A7: 0 | B7: 8171997 | C7: 0 | D7: =C7/$H$3 | E7: =IF($J$3="",IF($B$17>0,B7/$B$17,0),COMBIN($J$3,A7)*$L$3^A7*(1-$L$3)^($J$3-A7)) | F7: =IF($B$17>0,B7/$B$17,0) | G7: =E7-F7 | H7: =D7*E7 | I7: =E7
A8: 1 | B8: 53851723 | C8: 0 | D8: =C8/$H$3 | E8: =IF($J$3="",IF($B$17>0,B8/$B$17,0),COMBIN($J$3,A8)*$L$3^A8*(1-$L$3)^($J$3-A8)) | F8: =IF($B$17>0,B8/$B$17,0) | G8: =E8-F8 | H8: =D8*E8 | I8: =I7+E8
A9: 2 | B9: 155256239 | C9: 0 | D9: =C9/$H$3 | E9: =IF($J$3="",IF($B$17>0,B9/$B$17,0),COMBIN($J$3,A9)*$L$3^A9*(1-$L$3)^($J$3-A9)) | F9: =IF($B$17>0,B9/$B$17,0) | G9: =E9-F9 | H9: =D9*E9 | I9: =I8+E9
A10: 3 | B10: 255776399 | C10: 0 | D10: =C10/$H$3 | E10: =IF($J$3="",IF($B$17>0,B10/$B$17,0),COMBIN($J$3,A10)*$L$3^A10*(1-$L$3)^($J$3-A10)) | F10: =IF($B$17>0,B10/$B$17,0) | G10: =E10-F10 | H10: =D10*E10 | I10: =I9+E10
A11: 4 | B11: 263361261 | C11: 0 | D11: =C11/$H$3 | E11: =IF($J$3="",IF($B$17>0,B11/$B$17,0),COMBIN($J$3,A11)*$L$3^A11*(1-$L$3)^($J$3-A11)) | F11: =IF($B$17>0,B11/$B$17,0) | G11: =E11-F11 | H11: =D11*E11 | I11: =I10+E11
A12: 5 | B12: 173549470 | C12: 6 | D12: =C12/$H$3 | E12: =IF($J$3="",IF($B$17>0,B12/$B$17,0),COMBIN($J$3,A12)*$L$3^A12*(1-$L$3)^($J$3-A12)) | F12: =IF($B$17>0,B12/$B$17,0) | G12: =E12-F12 | H12: =D12*E12 | I12: =I11+E12
A13: 6 | B13: 71478381 | C13: 569 | D13: =C13/$H$3 | E13: =IF($J$3="",IF($B$17>0,B13/$B$17,0),COMBIN($J$3,A13)*$L$3^A13*(1-$L$3)^($J$3-A13)) | F13: =IF($B$17>0,B13/$B$17,0) | G13: =E13-F13 | H13: =D13*E13 | I13: =I12+E13
A14: 7 | B14: 16822405 | C14: 53093 | D14: =C14/$H$3 | E14: =IF($J$3="",IF($B$17>0,B14/$B$17,0),COMBIN($J$3,A14)*$L$3^A14*(1-$L$3)^($J$3-A14)) | F14: =IF($B$17>0,B14/$B$17,0) | G14: =E14-F14 | H14: =D14*E14 | I14: =I13+E14
A15: 8 | B15: 1732139 | C15: 4950000 | D15: =C15/$H$3 | E15: =IF($J$3="",IF($B$17>0,B15/$B$17,0),COMBIN($J$3,A15)*$L$3^A15*(1-$L$3)^($J$3-A15)) | F15: =IF($B$17>0,B15/$B$17,0) | G15: =E15-F15 | H15: =D15*E15 | I15: =I14+E15
A17: CHECK_SUMS | B17: =SUM(B7:B15) | C17: payout_raw_sum | D17: =SUM(D7:D15) | E17: =SUM(E7:E15) | F17: =SUM(F7:F15) | G17: =MAX(ABS(G7:G15)) | H17: =SUM(H7:H15) | I17: =IF($B$3>0,H17/$B$3,0) | J17: =IF($D$3="","N/A",ABS(I17-$D$3)<=$F$3)
A18: rtp_drift | B18: =IF($D$3="","",I17-$D$3)
A19: prob_sum_check | B19: =ABS(E17-1)<=1E-9
A20: max_win_value | B20: =MAX(D7:D15)
A21: max_win_probability | B21: =SUMIFS(E7:E15,D7:D15,B20)
A22: outcome_rows | B22: =ROWS(A7:A15)
A23: unique_multipliers | B23: =SUMPRODUCT(1/COUNTIF(D7:D15,D7:D15))
A24: max_exposure_with_max_bet | B24: =B20*500.0

Sheet buy100_expert_9
A1: buy100_expert_9 Lookup Detail
A2: Derived from lookup rows
A3: Cost | B3: 99 | C3: Target RTP | D3: 0.9605 | E3: RTP Tol | F3: 0.01 | G3: Payout Scale | H3: 100 | I3: Rows (N) | J3: 9 | K3: p_right | L3: 0.45680177 | M3: p_left | N3: =IF(L3="","",1-L3)
A5: Rows
A6: sim_id | B6: weight | C6: payout_raw | D6: payout_scaled | E6: probability_binomial_exact | F6: probability_from_weight | G6: probability_diff | H6: weighted_payout | I6: cumulative_probability
A7: 0 | B7: 4117420 | C7: 0 | D7: =C7/$H$3 | E7: =IF($J$3="",IF($B$18>0,B7/$B$18,0),COMBIN($J$3,A7)*$L$3^A7*(1-$L$3)^($J$3-A7)) | F7: =IF($B$18>0,B7/$B$18,0) | G7: =E7-F7 | H7: =D7*E7 | I7: =E7
A8: 1 | B8: 31162843 | C8: 0 | D8: =C8/$H$3 | E8: =IF($J$3="",IF($B$18>0,B8/$B$18,0),COMBIN($J$3,A8)*$L$3^A8*(1-$L$3)^($J$3-A8)) | F8: =IF($B$18>0,B8/$B$18,0) | G8: =E8-F8 | H8: =D8*E8 | I8: =I7+E8
A9: 2 | B9: 104825391 | C9: 0 | D9: =C9/$H$3 | E9: =IF($J$3="",IF($B$18>0,B9/$B$18,0),COMBIN($J$3,A9)*$L$3^A9*(1-$L$3)^($J$3-A9)) | F9: =IF($B$18>0,B9/$B$18,0) | G9: =E9-F9 | H9: =D9*E9 | I9: =I8+E9
A10: 3 | B10: 205689775 | C10: 0 | D10: =C10/$H$3 | E10: =IF($J$3="",IF($B$18>0,B10/$B$18,0),COMBIN($J$3,A10)*$L$3^A10*(1-$L$3)^($J$3-A10)) | F10: =IF($B$18>0,B10/$B$18,0) | G10: =E10-F10 | H10: =D10*E10 | I10: =I9+E10
A11: 4 | B11: 259461777 | C11: 0 | D11: =C11/$H$3 | E11: =IF($J$3="",IF($B$18>0,B11/$B$18,0),COMBIN($J$3,A11)*$L$3^A11*(1-$L$3)^($J$3-A11)) | F11: =IF($B$18>0,B11/$B$18,0) | G11: =E11-F11 | H11: =D11*E11 | I11: =I10+E11
A12: 5 | B12: 218194005 | C12: 0 | D12: =C12/$H$3 | E12: =IF($J$3="",IF($B$18>0,B12/$B$18,0),COMBIN($J$3,A12)*$L$3^A12*(1-$L$3)^($J$3-A12)) | F12: =IF($B$18>0,B12/$B$18,0) | G12: =E12-F12 | H12: =D12*E12 | I12: =I11+E12
A13: 6 | B13: 122326622 | C13: 9 | D13: =C13/$H$3 | E13: =IF($J$3="",IF($B$18>0,B13/$B$18,0),COMBIN($J$3,A13)*$L$3^A13*(1-$L$3)^($J$3-A13)) | F13: =IF($B$18>0,B13/$B$18,0) | G13: =E13-F13 | H13: =D13*E13 | I13: =I12+E13
A14: 7 | B14: 44087312 | C14: 937 | D14: =C14/$H$3 | E14: =IF($J$3="",IF($B$18>0,B14/$B$18,0),COMBIN($J$3,A14)*$L$3^A14*(1-$L$3)^($J$3-A14)) | F14: =IF($B$18>0,B14/$B$18,0) | G14: =E14-F14 | H14: =D14*E14 | I14: =I13+E14
A15: 8 | B15: 9268790 | C15: 96290 | D15: =C15/$H$3 | E15: =IF($J$3="",IF($B$18>0,B15/$B$18,0),COMBIN($J$3,A15)*$L$3^A15*(1-$L$3)^($J$3-A15)) | F15: =IF($B$18>0,B15/$B$18,0) | G15: =E15-F15 | H15: =D15*E15 | I15: =I14+E15
A16: 9 | B16: 866065 | C16: 9900000 | D16: =C16/$H$3 | E16: =IF($J$3="",IF($B$18>0,B16/$B$18,0),COMBIN($J$3,A16)*$L$3^A16*(1-$L$3)^($J$3-A16)) | F16: =IF($B$18>0,B16/$B$18,0) | G16: =E16-F16 | H16: =D16*E16 | I16: =I15+E16
A18: CHECK_SUMS | B18: =SUM(B7:B16) | C18: payout_raw_sum | D18: =SUM(D7:D16) | E18: =SUM(E7:E16) | F18: =SUM(F7:F16) | G18: =MAX(ABS(G7:G16)) | H18: =SUM(H7:H16) | I18: =IF($B$3>0,H18/$B$3,0) | J18: =IF($D$3="","N/A",ABS(I18-$D$3)<=$F$3)
A19: rtp_drift | B19: =IF($D$3="","",I18-$D$3)
A20: prob_sum_check | B20: =ABS(E18-1)<=1E-9
A21: max_win_value | B21: =MAX(D7:D16)
A22: max_win_probability | B22: =SUMIFS(E7:E16,D7:D16,B21)
A23: outcome_rows | B23: =ROWS(A7:A16)
A24: unique_multipliers | B24: =SUMPRODUCT(1/COUNTIF(D7:D16,D7:D16))
A25: max_exposure_with_max_bet | B25: =B21*500.0

Sheet buy100_high_10
A1: buy100_high_10 Lookup Detail
A2: Derived from lookup rows
A3: Cost | B3: 99 | C3: Target RTP | D3: 0.9605 | E3: RTP Tol | F3: 0.01 | G3: Payout Scale | H3: 100 | I3: Rows (N) | J3: 10 | K3: p_right | L3: 0.63032353 | M3: p_left | N3: =IF(L3="","",1-L3)
A5: Rows
A6: sim_id | B6: weight | C6: payout_raw | D6: payout_scaled | E6: probability_binomial_exact | F6: probability_from_weight | G6: probability_diff | H6: weighted_payout | I6: cumulative_probability
A7: 0 | B7: 47667 | C7: 0 | D7: =C7/$H$3 | E7: =IF($J$3="",IF($B$19>0,B7/$B$19,0),COMBIN($J$3,A7)*$L$3^A7*(1-$L$3)^($J$3-A7)) | F7: =IF($B$19>0,B7/$B$19,0) | G7: =E7-F7 | H7: =D7*E7 | I7: =E7
A8: 1 | B8: 812755 | C8: 0 | D8: =C8/$H$3 | E8: =IF($J$3="",IF($B$19>0,B8/$B$19,0),COMBIN($J$3,A8)*$L$3^A8*(1-$L$3)^($J$3-A8)) | F8: =IF($B$19>0,B8/$B$19,0) | G8: =E8-F8 | H8: =D8*E8 | I8: =I7+E8
A9: 2 | B9: 6236114 | C9: 0 | D9: =C9/$H$3 | E9: =IF($J$3="",IF($B$19>0,B9/$B$19,0),COMBIN($J$3,A9)*$L$3^A9*(1-$L$3)^($J$3-A9)) | F9: =IF($B$19>0,B9/$B$19,0) | G9: =E9-F9 | H9: =D9*E9 | I9: =I8+E9
A10: 3 | B10: 28354661 | C10: 0 | D10: =C10/$H$3 | E10: =IF($J$3="",IF($B$19>0,B10/$B$19,0),COMBIN($J$3,A10)*$L$3^A10*(1-$L$3)^($J$3-A10)) | F10: =IF($B$19>0,B10/$B$19,0) | G10: =E10-F10 | H10: =D10*E10 | I10: =I9+E10
A11: 4 | B11: 84606597 | C11: 0 | D11: =C11/$H$3 | E11: =IF($J$3="",IF($B$19>0,B11/$B$19,0),COMBIN($J$3,A11)*$L$3^A11*(1-$L$3)^($J$3-A11)) | F11: =IF($B$19>0,B11/$B$19,0) | G11: =E11-F11 | H11: =D11*E11 | I11: =I10+E11
A12: 5 | B12: 173112003 | C12: 0 | D12: =C12/$H$3 | E12: =IF($J$3="",IF($B$19>0,B12/$B$19,0),COMBIN($J$3,A12)*$L$3^A12*(1-$L$3)^($J$3-A12)) | F12: =IF($B$19>0,B12/$B$19,0) | G12: =E12-F12 | H12: =D12*E12 | I12: =I11+E12
A13: 6 | B13: 245973118 | C13: 2 | D13: =C13/$H$3 | E13: =IF($J$3="",IF($B$19>0,B13/$B$19,0),COMBIN($J$3,A13)*$L$3^A13*(1-$L$3)^($J$3-A13)) | F13: =IF($B$19>0,B13/$B$19,0) | G13: =E13-F13 | H13: =D13*E13 | I13: =I12+E13
A14: 7 | B14: 239657657 | C14: 56 | D14: =C14/$H$3 | E14: =IF($J$3="",IF($B$19>0,B14/$B$19,0),COMBIN($J$3,A14)*$L$3^A14*(1-$L$3)^($J$3-A14)) | F14: =IF($B$19>0,B14/$B$19,0) | G14: =E14-F14 | H14: =D14*E14 | I14: =I13+E14
A15: 8 | B15: 153237228 | C15: 1337 | D15: =C15/$H$3 | E15: =IF($J$3="",IF($B$19>0,B15/$B$19,0),COMBIN($J$3,A15)*$L$3^A15*(1-$L$3)^($J$3-A15)) | F15: =IF($B$19>0,B15/$B$19,0) | G15: =E15-F15 | H15: =D15*E15 | I15: =I14+E15
A16: 9 | B16: 58062200 | C16: 31712 | D16: =C16/$H$3 | E16: =IF($J$3="",IF($B$19>0,B16/$B$19,0),COMBIN($J$3,A16)*$L$3^A16*(1-$L$3)^($J$3-A16)) | F16: =IF($B$19>0,B16/$B$19,0) | G16: =E16-F16 | H16: =D16*E16 | I16: =I15+E16
A17: 10 | B17: 9900176 | C17: 752400 | D17: =C17/$H$3 | E17: =IF($J$3="",IF($B$19>0,B17/$B$19,0),COMBIN($J$3,A17)*$L$3^A17*(1-$L$3)^($J$3-A17)) | F17: =IF($B$19>0,B17/$B$19,0) | G17: =E17-F17 | H17: =D17*E17 | I17: =I16+E17
A19: CHECK_SUMS | B19: =SUM(B7:B17) | C19: payout_raw_sum | D19: =SUM(D7:D17) | E19: =SUM(E7:E17) | F19: =SUM(F7:F17) | G19: =MAX(ABS(G7:G17)) | H19: =SUM(H7:H17) | I19: =IF($B$3>0,H19/$B$3,0) | J19: =IF($D$3="","N/A",ABS(I19-$D$3)<=$F$3)
A20: rtp_drift | B20: =IF($D$3="","",I19-$D$3)
A21: prob_sum_check | B21: =ABS(E19-1)<=1E-9
A22: max_win_value | B22: =MAX(D7:D17)
A23: max_win_probability | B23: =SUMIFS(E7:E17,D7:D17,B22)
A24: outcome_rows | B24: =ROWS(A7:A17)
A25: unique_multipliers | B25: =SUMPRODUCT(1/COUNTIF(D7:D17,D7:D17))
A26: max_exposure_with_max_bet | B26: =B22*500.0

Sheet buy100_high_11
A1: buy100_high_11 Lookup Detail
A2: Derived from lookup rows
A3: Cost | B3: 99 | C3: Target RTP | D3: 0.9605 | E3: RTP Tol | F3: 0.01 | G3: Payout Scale | H3: 100 | I3: Rows (N) | J3: 11 | K3: p_right | L3: 0.63871585 | M3: p_left | N3: =IF(L3="","",1-L3)
A5: Rows
A6: sim_id | B6: weight | C6: payout_raw | D6: payout_scaled | E6: probability_binomial_exact | F6: probability_from_weight | G6: probability_diff | H6: weighted_payout | I6: cumulative_probability
A7: 0 | B7: 13688 | C7: 0 | D7: =C7/$H$3 | E7: =IF($J$3="",IF($B$20>0,B7/$B$20,0),COMBIN($J$3,A7)*$L$3^A7*(1-$L$3)^($J$3-A7)) | F7: =IF($B$20>0,B7/$B$20,0) | G7: =E7-F7 | H7: =D7*E7 | I7: =E7
A8: 1 | B8: 266189 | C8: 0 | D8: =C8/$H$3 | E8: =IF($J$3="",IF($B$20>0,B8/$B$20,0),COMBIN($J$3,A8)*$L$3^A8*(1-$L$3)^($J$3-A8)) | F8: =IF($B$20>0,B8/$B$20,0) | G8: =E8-F8 | H8: =D8*E8 | I8: =I7+E8
A9: 2 | B9: 2352980 | C9: 0 | D9: =C9/$H$3 | E9: =IF($J$3="",IF($B$20>0,B9/$B$20,0),COMBIN($J$3,A9)*$L$3^A9*(1-$L$3)^($J$3-A9)) | F9: =IF($B$20>0,B9/$B$20,0) | G9: =E9-F9 | H9: =D9*E9 | I9: =I8+E9
A10: 3 | B10: 12479533 | C10: 0 | D10: =C10/$H$3 | E10: =IF($J$3="",IF($B$20>0,B10/$B$20,0),COMBIN($J$3,A10)*$L$3^A10*(1-$L$3)^($J$3-A10)) | F10: =IF($B$20>0,B10/$B$20,0) | G10: =E10-F10 | H10: =D10*E10 | I10: =I9+E10
A11: 4 | B11: 44125242 | C11: 0 | D11: =C11/$H$3 | E11: =IF($J$3="",IF($B$20>0,B11/$B$20,0),COMBIN($J$3,A11)*$L$3^A11*(1-$L$3)^($J$3-A11)) | F11: =IF($B$20>0,B11/$B$20,0) | G11: =E11-F11 | H11: =D11*E11 | I11: =I10+E11
A12: 5 | B12: 109212893 | C12: 0 | D12: =C12/$H$3 | E12: =IF($J$3="",IF($B$20>0,B12/$B$20,0),COMBIN($J$3,A12)*$L$3^A12*(1-$L$3)^($J$3-A12)) | F12: =IF($B$20>0,B12/$B$20,0) | G12: =E12-F12 | H12: =D12*E12 | I12: =I11+E12
A13: 6 | B13: 193077954 | C13: 0 | D13: =C13/$H$3 | E13: =IF($J$3="",IF($B$20>0,B13/$B$20,0),COMBIN($J$3,A13)*$L$3^A13*(1-$L$3)^($J$3-A13)) | F13: =IF($B$20>0,B13/$B$20,0) | G13: =E13-F13 | H13: =D13*E13 | I13: =I12+E13
A14: 7 | B14: 243816690 | C14: 0 | D14: =C14/$H$3 | E14: =IF($J$3="",IF($B$20>0,B14/$B$20,0),COMBIN($J$3,A14)*$L$3^A14*(1-$L$3)^($J$3-A14)) | F14: =IF($B$20>0,B14/$B$20,0) | G14: =E14-F14 | H14: =D14*E14 | I14: =I13+E14
A15: 8 | B15: 215522299 | C15: 6 | D15: =C15/$H$3 | E15: =IF($J$3="",IF($B$20>0,B15/$B$20,0),COMBIN($J$3,A15)*$L$3^A15*(1-$L$3)^($J$3-A15)) | F15: =IF($B$20>0,B15/$B$20,0) | G15: =E15-F15 | H15: =D15*E15 | I15: =I14+E15
A16: 9 | B16: 127007607 | C16: 332 | D16: =C16/$H$3 | E16: =IF($J$3="",IF($B$20>0,B16/$B$20,0),COMBIN($J$3,A16)*$L$3^A16*(1-$L$3)^($J$3-A16)) | F16: =IF($B$20>0,B16/$B$20,0) | G16: =E16-F16 | H16: =D16*E16 | I16: =I15+E16
A17: 10 | B17: 44907461 | C17: 19847 | D17: =C17/$H$3 | E17: =IF($J$3="",IF($B$20>0,B17/$B$20,0),COMBIN($J$3,A17)*$L$3^A17*(1-$L$3)^($J$3-A17)) | F17: =IF($B$20>0,B17/$B$20,0) | G17: =E17-F17 | H17: =D17*E17 | I17: =I16+E17
A18: 11 | B18: 7217349 | C18: 1188000 | D18: =C18/$H$3 | E18: =IF($J$3="",IF($B$20>0,B18/$B$20,0),COMBIN($J$3,A18)*$L$3^A18*(1-$L$3)^($J$3-A18)) | F18: =IF($B$20>0,B18/$B$20,0) | G18: =E18-F18 | H18: =D18*E18 | I18: =I17+E18
A20: CHECK_SUMS | B20: =SUM(B7:B18) | C20: payout_raw_sum | D20: =SUM(D7:D18) | E20: =SUM(E7:E18) | F20: =SUM(F7:F18) | G20: =MAX(ABS(G7:G18)) | H20: =SUM(H7:H18) | I20: =IF($B$3>0,H20/$B$3,0) | J20: =IF($D$3="","N/A",ABS(I20-$D$3)<=$F$3)
A21: rtp_drift | B21: =IF($D$3="","",I20-$D$3)
